Workbook

Sheet MP1
B1: Employer ID No. | C1: 2027-4107-0002
B2: Employer/Business Name | C2: AGRICULTURAL TRAINING INSTITUTE
B3: Employer/Business Address | C3: ATI Bldg. Elliptical Rd. Diliman, Quezon City
B4: Contact Number | C4: 929-85(234)/09989741223
B5: Email Address | C5: hrmo.co@ati.da.gov.ph
B6: Total Remittance | C6: =K99+L99 -> 45000
B7: Pag-IBIG IDENTIFICATION NO. | D7: MEMBERSHIP PROGRAM | E7: LAST NAME | F7: FIRST NAME | G7: NAME EXTENSION | H7: MIDDLE NAME | I7: PERCOV | J7: For PAG-IBIG I only | L7: EE SHARE | M7: REMARKS
B8: MID NO. | C8: MP2 ACCOUNT NO. | J8: MONTHLY COMPENSATION | K8: ER SHARE
A9: 1 | B9: 121222125544 | D9: F1-Pag-IBIG 1 | E9: ABCEDE | F9: DIANNE | H9: PALAYA | I9: MAR 2026 | J9: =SUMIF(PAYOUT!$A:$A,'MP1'!$A9,PAYOUT!$L:$L) -> 31705 | K9: 200 | L9: =SUMIF(PAYOUT!$A:$A,'MP1'!$A9,PAYOUT!$AE:$AE) -> 200
A10: 2 | B10: 121294057717 | D10: F1-Pag-IBIG 1 | E10: AGUILAR | F10: ROXETTE GELYN | H10: ROÑO | I10: MAR 2026 | J10: =SUMIF(PAYOUT!$A:$A,'MP1'!$A10,PAYOUT!$L:$L) -> 31705 | K10: 200 | L10: =SUMIF(PAYOUT!$A:$A,'MP1'!$A10,PAYOUT!$AE:$AE) -> 200
A11: 3 | B11: 107002369490 | D11: F1-Pag-IBIG 1 | E11: ALBERTO | F11: CAMILO | H11: MALIT | I11: MAR 2026 | J11: =SUMIF(PAYOUT!$A:$A,'MP1'!$A11,PAYOUT!$L:$L) -> 32401 | K11: 200 | L11: =SUMIF(PAYOUT!$A:$A,'MP1'!$A11,PAYOUT!$AE:$AE) -> 200
A12: 4 | B12: 121313175684 | D12: F1-Pag-IBIG 1 | E12: ALCANTARA | F12: JUSTINE ANN | H12: CASTRO | I12: MAR 2026 | J12: =SUMIF(PAYOUT!$A:$A,'MP1'!$A12,PAYOUT!$L:$L) -> 31705 | K12: 200 | L12: =SUMIF(PAYOUT!$A:$A,'MP1'!$A12,PAYOUT!$AE:$AE) -> 200
A13: 5 | B13: 121052246752 | D13: F1-Pag-IBIG 1 | E13: ALFONSO | F13: CINDY | H13: CORCELLES | I13: MAR 2026 | J13: =SUMIF(PAYOUT!$A:$A,'MP1'!$A13,PAYOUT!$L:$L) -> 53818 | K13: 200 | L13: =SUMIF(PAYOUT!$A:$A,'MP1'!$A13,PAYOUT!$AE:$AE) -> 200
A14: 6 | B14: 121019967335 | D14: F1-Pag-IBIG 1 | E14: ALFORQUE | F14: G. MARK ANTHONY | H14: CORDERO | I14: MAR 2026 | J14: =SUMIF(PAYOUT!$A:$A,'MP1'!$A14,PAYOUT!$L:$L) -> 42594 | K14: 200 | L14: =SUMIF(PAYOUT!$A:$A,'MP1'!$A14,PAYOUT!$AE:$AE) -> 1000
A15: 7 | B15: 121143838658 | D15: F1-Pag-IBIG 1 | E15: ALVAREZ | F15: MARIA CLARISSA | H15: MENDEZ | I15: MAR 2026 | J15: =SUMIF(PAYOUT!$A:$A,'MP1'!$A15,PAYOUT!$L:$L) -> 24329 | K15: 200 | L15: =SUMIF(PAYOUT!$A:$A,'MP1'!$A15,PAYOUT!$AE:$AE) -> 200
A16: 8 | B16: 121156058706 | D16: F1-Pag-IBIG 1 | E16: ALVAREZ | F16: MARK NELLO | H16: BOLA | I16: MAR 2026 | J16: =SUMIF(PAYOUT!$A:$A,'MP1'!$A16,PAYOUT!$L:$L) -> 42178 | K16: 200 | L16: =SUMIF(PAYOUT!$A:$A,'MP1'!$A16,PAYOUT!$AE:$AE) -> 500
A17: 9 | B17: 121146103671 | D17: F1-Pag-IBIG 1 | E17: ANINACION | F17: JOSHUA | H17: GERPACIO | I17: MAR 2026 | J17: =SUMIF(PAYOUT!$A:$A,'MP1'!$A17,PAYOUT!$L:$L) -> 42594 | K17: 200 | L17: =SUMIF(PAYOUT!$A:$A,'MP1'!$A17,PAYOUT!$AE:$AE) -> 200
A18: 10 | B18: 121257804768 | D18: F1-Pag-IBIG 1 | E18: ANTIPAS | F18: ANDREA JANE | H18: MURING | I18: MAR 2026 | J18: =SUMIF(PAYOUT!$A:$A,'MP1'!$A18,PAYOUT!$L:$L) -> 20914 | K18: 200 | L18: =SUMIF(PAYOUT!$A:$A,'MP1'!$A18,PAYOUT!$AE:$AE) -> 200
A19: 11 | B19: 107002368645 | D19: F1-Pag-IBIG 1 | E19: ARCEO | F19: ANTONIETA | H19: JAMON | I19: MAR 2026 | J19: =SUMIF(PAYOUT!$A:$A,'MP1'!$A19,PAYOUT!$L:$L) -> 148940 | K19: 200 | L19: =SUMIF(PAYOUT!$A:$A,'MP1'!$A19,PAYOUT!$AE:$AE) -> 200
A20: 12 | B20: 107002369567 | D20: F1-Pag-IBIG 1 | E20: BALANGATAN | F20: JUN | H20: GARCIA | I20: MAR 2026 | J20: =SUMIF(PAYOUT!$A:$A,'MP1'!$A20,PAYOUT!$L:$L) -> 23668 | K20: 200 | L20: =SUMIF(PAYOUT!$A:$A,'MP1'!$A20,PAYOUT!$AE:$AE) -> 200
... A98: 90 | B98: 121080071170 | D98: F1-Pag-IBIG 1 | E98: YAGO | F98: EMERSON | H98: SOLANO | I98: MAR 2026 | J98: =SUMIF(PAYOUT!$A:$A,'MP1'!$A98,PAYOUT!$L:$L) -> 82963 | K98: 200 | L98: =SUMIF(PAYOUT!$A:$A,'MP1'!$A98,PAYOUT!$AE:$AE) -> 200
K99: =SUM(K9:K98) -> 18000 | L99: =SUM(L9:L98) -> 27000

Sheet MP2
B1: Employer ID No. | C1: 2027-4107-0002
B2: Employer/Business Name | C2: AGRICULTURAL TRAINING INSTITUTE
B3: Employer/Business Address | C3: ATI Bldg. Elliptical Rd. Diliman, Quezon City
B4: Contact Number | C4: 929-85(234)/09989741223
B5: Email Address | C5: hrmo.co@ati.da.gov.ph
B6: Total Remittance | C6: =L100 -> 33700
B7: Pag-IBIG IDENTIFICATION NO. | D7: MEMBERSHIP PROGRAM | E7: LAST NAME | F7: FIRST NAME | G7: NAME EXTENSION | H7: MIDDLE NAME | I7: PERCOV | J7: For PAG-IBIG II only | L7: EE SHARE | M7: REMARKS
B8: MID NO. | C8: MP2 ACCOUNT NO. | J8: MONTHLY COMPENSATION | K8: ER SHARE
A9: 1 | B9: 121222125544 | C9: 521037005993 | D9: M2-Modified Pag-IBIG 2 | E9: ABCEDE | F9: DIANNE | H9: PALAYA | I9: MAR 2026 | J9: =SUMIF(PAYOUT!$A:$A,'MP2'!$A9,PAYOUT!$L:$L) -> 31705 | L9: =SUMIF(PAYOUT!$A:$A,'MP2'!$A9,PAYOUT!$AD:$AD) -> 1000
A10: 2 | B10: 121294057717 | D10: M2-Modified Pag-IBIG 2 | E10: AGUILAR | F10: ROXETTE GELYN | H10: ROÑO | I10: MAR 2026 | J10: =SUMIF(PAYOUT!$A:$A,'MP2'!$A10,PAYOUT!$L:$L) -> 31705 | L10: =SUMIF(PAYOUT!$A:$A,'MP2'!$A10,PAYOUT!$AD:$AD) -> 0
A11: 3 | B11: 107002369490 | C11: 521186014249 | D11: M2-Modified Pag-IBIG 2 | E11: ALBERTO | F11: CAMILO | H11: MALIT | I11: MAR 2026 | J11: =SUMIF(PAYOUT!$A:$A,'MP2'!$A11,PAYOUT!$L:$L) -> 32401 | L11: =SUMIF(PAYOUT!$A:$A,'MP2'!$A11,PAYOUT!$AD:$AD) -> 500
A12: 4 | B12: 121313175684 | D12: M2-Modified Pag-IBIG 2 | E12: ALCANTARA | F12: JUSTINE ANN | H12: CASTRO | I12: MAR 2026 | J12: =SUMIF(PAYOUT!$A:$A,'MP2'!$A12,PAYOUT!$L:$L) -> 31705 | L12: =SUMIF(PAYOUT!$A:$A,'MP2'!$A12,PAYOUT!$AD:$AD) -> 0
A13: 5 | B13: 121052246752 | D13: M2-Modified Pag-IBIG 2 | E13: ALFONSO | F13: CINDY | H13: CORCELLES | I13: MAR 2026 | J13: =SUMIF(PAYOUT!$A:$A,'MP2'!$A13,PAYOUT!$L:$L) -> 53818 | L13: =SUMIF(PAYOUT!$A:$A,'MP2'!$A13,PAYOUT!$AD:$AD) -> 0
A14: 6 | B14: 121019967335 | C14: 524026014423 | D14: M2-Modified Pag-IBIG 2 | E14: ALFORQUE | F14: G. MARK ANTHONY | H14: CORDERO | I14: MAR 2026 | J14: =SUMIF(PAYOUT!$A:$A,'MP2'!$A14,PAYOUT!$L:$L) -> 42594 | L14: =SUMIF(PAYOUT!$A:$A,'MP2'!$A14,PAYOUT!$AD:$AD) -> 3000
A15: 7 | B15: 121143838658 | D15: M2-Modified Pag-IBIG 2 | E15: ALVAREZ | F15: MARIA CLARISSA | H15: MENDEZ | I15: MAR 2026 | J15: =SUMIF(PAYOUT!$A:$A,'MP2'!$A15,PAYOUT!$L:$L) -> 24329 | L15: =SUMIF(PAYOUT!$A:$A,'MP2'!$A15,PAYOUT!$AD:$AD) -> 0
A16: 8 | B16: 121156058706 | C16: 523031016397 | D16: M2-Modified Pag-IBIG 2 | E16: ALVAREZ | F16: MARK NELLO | H16: BOLA | I16: MAR 2026 | J16: =SUMIF(PAYOUT!$A:$A,'MP2'!$A16,PAYOUT!$L:$L) -> 42178 | L16: =SUMIF(PAYOUT!$A:$A,'MP2'!$A16,PAYOUT!$AD:$AD) -> 2000
A17: 9 | B17: 121146103671 | D17: M2-Modified Pag-IBIG 2 | E17: ANINACION | F17: JOSHUA | H17: GERPACIO | I17: MAR 2026 | J17: =SUMIF(PAYOUT!$A:$A,'MP2'!$A17,PAYOUT!$L:$L) -> 42594 | L17: =SUMIF(PAYOUT!$A:$A,'MP2'!$A17,PAYOUT!$AD:$AD) -> 0
A18: 10 | B18: 121257804768 | C18: 525058628227 | D18: M2-Modified Pag-IBIG 2 | E18: ANTIPAS | F18: ANDREA JANE | H18: MURING | I18: MAR 2026 | J18: =SUMIF(PAYOUT!$A:$A,'MP2'!$A18,PAYOUT!$L:$L) -> 20914 | L18: =SUMIF(PAYOUT!$A:$A,'MP2'!$A18,PAYOUT!$AD:$AD) -> 1000
A19: 11 | B19: 107002368645 | D19: M2-Modified Pag-IBIG 2 | E19: ARCEO | F19: ANTONIETA | H19: JAMON | I19: MAR 2026 | J19: =SUMIF(PAYOUT!$A:$A,'MP2'!$A19,PAYOUT!$L:$L) -> 148940 | L19: =SUMIF(PAYOUT!$A:$A,'MP2'!$A19,PAYOUT!$AD:$AD) -> 0
A20: 12 | B20: 107002369567 | D20: M2-Modified Pag-IBIG 2 | E20: BALANGATAN | F20: JUN | H20: GARCIA | I20: MAR 2026 | J20: =SUMIF(PAYOUT!$A:$A,'MP2'!$A20,PAYOUT!$L:$L) -> 23668 | L20: =SUMIF(PAYOUT!$A:$A,'MP2'!$A20,PAYOUT!$AD:$AD) -> 0
A21: 13 | B21: 121310118441 | D21: M2-Modified Pag-IBIG 2 | E21: BALUYUT | F21: JULIA MARIE | H21: MEDES | I21: MAR 2026 | J21: =SUMIF(PAYOUT!$A:$A,'MP2'!$A21,PAYOUT!$L:$L) -> 31705 | L21: =SUMIF(PAYOUT!$A:$A,'MP2'!$A21,PAYOUT!$AD:$AD) -> 0
A22: 14 | B22: 107002369611 | D22: M2-Modified Pag-IBIG 2 | E22: BAUTISTA | F22: MARILYN | H22: JOSEF | I22: MAR 2026 | J22: =SUMIF(PAYOUT!$A:$A,'MP2'!$A22,PAYOUT!$L:$L) -> 17360 | L22: =SUMIF(PAYOUT!$A:$A,'MP2'!$A22,PAYOUT!$AD:$AD) -> 0
A23: 16 | B23: 107002369655 | D23: M2-Modified Pag-IBIG 2 | E23: BIBIT | F23: DARWIN | H23: DELA CRUZ | I23: MAR 2026 | J23: =SUMIF(PAYOUT!$A:$A,'MP2'!$A23,PAYOUT!$L:$L) -> 23883 | L23: =SUMIF(PAYOUT!$A:$A,'MP2'!$A23,PAYOUT!$AD:$AD) -> 0
A24: 17 | B24: 107002405368 | D24: M2-Modified Pag-IBIG 2 | E24: BOLON | F24: RICHARD | H24: ENOT | I24: MAR 2026 | J24: =SUMIF(PAYOUT!$A:$A,'MP2'!$A24,PAYOUT!$L:$L) -> 19565 | L24: =SUMIF(PAYOUT!$A:$A,'MP2'!$A24,PAYOUT!$AD:$AD) -> 0
A25: 18 | B25: 121280890824 | D25: M2-Modified Pag-IBIG 2 | E25: BOMBON | F25: MARY ANGELYN | H25: PANIS | I25: MAR 2026 | J25: =SUMIF(PAYOUT!$A:$A,'MP2'!$A25,PAYOUT!$L:$L) -> 42178 | L25: =SUMIF(PAYOUT!$A:$A,'MP2'!$A25,PAYOUT!$AD:$AD) -> 0
A26: 19 | B26: 121090329684 | C26: 522003016377 | D26: M2-Modified Pag-IBIG 2 | E26: BORLAGDAN | F26: FRANCO GABRIEL | H26: PACAO | I26: MAR 2026 | J26: =SUMIF(PAYOUT!$A:$A,'MP2'!$A26,PAYOUT!$L:$L) -> 50066 | L26: =SUMIF(PAYOUT!$A:$A,'MP2'!$A26,PAYOUT!$AD:$AD) -> 1000
A27: 20 | B27: 121084370919 | D27: M2-Modified Pag-IBIG 2 | E27: BORROMEO | F27: KEMUEL | H27: MORAO | I27: MAR 2026 | J27: =SUMIF(PAYOUT!$A:$A,'MP2'!$A27,PAYOUT!$L:$L) -> 53818 | L27: =SUMIF(PAYOUT!$A:$A,'MP2'!$A27,PAYOUT!$AD:$AD) -> 0
A28: 21 | B28: 121155793878 | D28: M2-Modified Pag-IBIG 2 | E28: BUNDA | F28: ARNEL | H28: RAFAEL | I28: MAR 2026 | J28: =SUMIF(PAYOUT!$A:$A,'MP2'!$A28,PAYOUT!$L:$L) -> 32401 | L28: =SUMIF(PAYOUT!$A:$A,'MP2'!$A28,PAYOUT!$AD:$AD) -> 0
A29: 22 | B29: 121009101617 | D29: M2-Modified Pag-IBIG 2 | E29: CALASAGSAG | F29: JOEVEN | H29: CABINAN | I29: MAR 2026 | J29: =SUMIF(PAYOUT!$A:$A,'MP2'!$A29,PAYOUT!$L:$L) -> 81796 | L29: =SUMIF(PAYOUT!$A:$A,'MP2'!$A29,PAYOUT!$AD:$AD) -> 0
A30: 23 | B30: 107001521691 | C30: 521183012186 | D30: M2-Modified Pag-IBIG 2 | E30: CANILANG | F30: ASHLEE | H30: PERALTA | I30: MAR 2026 | J30: =SUMIF(PAYOUT!$A:$A,'MP2'!$A30,PAYOUT!$L:$L) -> 42178 | L30: =SUMIF(PAYOUT!$A:$A,'MP2'!$A30,PAYOUT!$AD:$AD) -> 1000
A31: 24 | B31: 107002404170 | D31: M2-Modified Pag-IBIG 2 | E31: COSICO | F31: THERESA AURORA | H31: BAGAOISAN | I31: MAR 2026 | J31: =SUMIF(PAYOUT!$A:$A,'MP2'!$A31,PAYOUT!$L:$L) -> 55499 | L31: =SUMIF(PAYOUT!$A:$A,'MP2'!$A31,PAYOUT!$AD:$AD) -> 0
A32: 25 | B32: 108000387241 | D32: M2-Modified Pag-IBIG 2 | E32: DACILLO | F32: EDMER | H32: BAUTISTA | I32: MAR 2026 | J32: =SUMIF(PAYOUT!$A:$A,'MP2'!$A32,PAYOUT!$L:$L) -> 42178 | L32: =SUMIF(PAYOUT!$A:$A,'MP2'!$A32,PAYOUT!$AD:$AD) -> 0
A33: 27 | B33: 121161065445 | D33: M2-Modified Pag-IBIG 2 | E33: DE LA CRUZ | F33: ROY SON | H33: REDOMA | I33: MAR 2026 | J33: =SUMIF(PAYOUT!$A:$A,'MP2'!$A33,PAYOUT!$L:$L) -> 53818 | L33: =SUMIF(PAYOUT!$A:$A,'MP2'!$A33,PAYOUT!$AD:$AD) -> 0
A34: 29 | B34: 121156428649 | C34: 524005030600 | D34: M2-Modified Pag-IBIG 2 | E34: DELA CUADRA | F34: JOVANEE | H34: SANSALONA | I34: MAR 2026 | J34: =SUMIF(PAYOUT!$A:$A,'MP2'!$A34,PAYOUT!$L:$L) -> 43442 | L34: =SUMIF(PAYOUT!$A:$A,'MP2'!$A34,PAYOUT!$AD:$AD) -> 1000
A35: 30 | B35: 121143321613 | D35: M2-Modified Pag-IBIG 2 | E35: DELA TORRE | F35: JULROSE | H35: HERNANDEZ | I35: MAR 2026 | J35: =SUMIF(PAYOUT!$A:$A,'MP2'!$A35,PAYOUT!$L:$L) -> 42178 | L35: =SUMIF(PAYOUT!$A:$A,'MP2'!$A35,PAYOUT!$AD:$AD) -> 0
A36: 31 | B36: 107002405379 | C36: 524087001973 | D36: M2-Modified Pag-IBIG 2 | E36: DELLAVA | F36: ROBERT | H36: DORADO | I36: MAR 2026 | J36: =SUMIF(PAYOUT!$A:$A,'MP2'!$A36,PAYOUT!$L:$L) -> 17360 | L36: =SUMIF(PAYOUT!$A:$A,'MP2'!$A36,PAYOUT!$AD:$AD) -> 500
A37: 32 | B37: 107002369811 | D37: M2-Modified Pag-IBIG 2 | E37: DELOS SANTOS | F37: JOSEFINA | H37: MENDOZA | I37: MAR 2026 | J37: =SUMIF(PAYOUT!$A:$A,'MP2'!$A37,PAYOUT!$L:$L) -> 26917 | L37: =SUMIF(PAYOUT!$A:$A,'MP2'!$A37,PAYOUT!$AD:$AD) -> 0
A38: 28 | B38: 121065979598 | D38: M2-Modified Pag-IBIG 2 | E38: DE MESA | F38: MARIA CARMINA | H38: MACABENTA | I38: MAR 2026 | J38: =SUMIF(PAYOUT!$A:$A,'MP2'!$A38,PAYOUT!$L:$L) -> 32109 | L38: =SUMIF(PAYOUT!$A:$A,'MP2'!$A38,PAYOUT!$AD:$AD) -> 0
A39: 33 | B39: 121068518978 | C39: 524005031021 | D39: M2-Modified Pag-IBIG 2 | E39: DEÑADO | F39: EMERSON | H39: RONSAIRO | I39: MAR 2026 | J39: =SUMIF(PAYOUT!$A:$A,'MP2'!$A39,PAYOUT!$L:$L) -> 43015 | L39: =SUMIF(PAYOUT!$A:$A,'MP2'!$A39,PAYOUT!$AD:$AD) -> 1000
A40: 34 | B40: 121134512335 | D40: M2-Modified Pag-IBIG 2 | E40: DREJE | F40: SHERRIE | H40: CORTEZ | I40: MAR 2026 | J40: =SUMIF(PAYOUT!$A:$A,'MP2'!$A40,PAYOUT!$L:$L) -> 54371 | L40: =SUMIF(PAYOUT!$A:$A,'MP2'!$A40,PAYOUT!$AD:$AD) -> 0
...

Sheet CODES
A2: MEMBERSHIP PROGRAM
A4: For Pag-IBIG I Savings | B4: F1-Pag-IBIG 1
A5: For MP2 Savings | B5: M2-Modified Pag-IBIG 2
A8: REMARKS
A10: Deceased | B10: D
A11: Leave Without Pay/AWOL | B11: L
A12: Newly Hired | B12: N
A13: Resigned/Separated from the Company | B13: RS
A14: Retired | B14: RT

Sheet PAYOUT
A4: ='[1]PER DIVISION'!A4 -> GENERAL PAYROLL FOR THE MONTH OF MARCH 2026
B6: NAME | O6: GSIS | AC6: HDMF (Pag-ibig) | AE6: HDMF | AG6: ATIEA | AL6: AMPCI | AN6: TENANTS | AW6: Provident
B7: SURNAME | C7: FIRST NAME | D7: MI | E7: ITEM | F7: DIVISION | G7: ITEM NUMBER | H7: DATE OF ORIGINAL APPOINTMENT | I7: DATE OF LAST PROMOTION | J7: SALARY GRADE | K7: STEP | L7: BASIC SALARY | M7: PERA | N7: TOTAL | O7: Life and Retirement (SIC) | P7: Policy Loan (Regular) | Q7: Emerg. Loan | R7: R E L (Housing) | S7: Conso. Loan | T7: Optional Premium (OULI) | U7: Policy Loan (Optional) | V7: MPL | W7: MPL LITE | X7: CPL | Y7: GFAL | Z7: Unutilized Daily Subsistence Allowance | AA7: Withholding Tax | AB7: Philhealth | AC7: MPL/STLRF | AD7: Pag-ibig II/MP2 | AE7: Personal Cont. | AF7: Mobile Phone Amort. | AG7: Monthly Dues | AH7: Loans | AI7: Undeducted Previous Transaction Fee | AJ7: Share | AK7: Healthcard | AL7: Coop Share | AM7: Coop Loans | AN7: Accommodation | AO7: Water Bill | AP7: Electric Bill | AQ7: Repairs | AR7: Security | AS7: Disallowance | AT7: Landbank Loan | AU7: UCPB Loan | AV7: DAMC Loan | AW7: Prov. Fund Share | AX7: Prov. (Healthcard) | AY7: Prov. Fund Loan | AZ7: Total Deductions | BA7: Net Take Home Pay | BB7: 15th | BC7: 30th
A8: 1 | B8: Abcede | C8: Dianne | D8: P. | E8: Agric. I | F8: PAD | G8: OSEC-DAB-AG1-116-2014 | H8: 45376 | I8: 45376 | J8: 11 | K8: 1 | L8: =IFERROR(VLOOKUP(J8, [1]DATA!$A$4:$I$36, MATCH(K8, [1]DATA!$B$3:$I$3, 0)+1, FALSE), "") -> 31705 | M8: 2000 | N8: =L8+M8 -> 33705 | O8: =ROUND(L8*9%,2) -> 2853.45 | AA8: 1468.9 | AB8: =ROUND(IF(L8>79999.99,900,IF(L8<10000.01,137.5,IF(10000<L8>80000,L8*2.5%))),2)-0.01 -> 792.62 | AD8: 1000 | AE8: 200 | AG8: 100 | AN8: 2000 | AO8: 395.48 | AZ8: =ROUND(SUM(O8:AY8),2) -> 8810.45 | BA8: =ROUND(N8-AZ8,2) -> 24894.55 | BB8: =ROUND(BA8/2,2) -> 12447.28 | BC8: =BA8-BB8 -> 12447.27
A9: =A8+1 -> 2 | B9: Aguilar | C9: Roxette Gelyn | D9: R. | E9: PLO I | F9: PPD | G9: OSEC-DAB-PLO1-12-1998 | H9: 45236 | I9: 45236 | J9: 11 | K9: 1 | L9: =IFERROR(VLOOKUP(J9, [1]DATA!$A$4:$I$36, MATCH(K9, [1]DATA!$B$3:$I$3, 0)+1, FALSE), "") -> 31705 | M9: 2000 | N9: =L9+M9 -> 33705 | O9: =ROUND(L9*9%,2) -> 2853.45 | AA9: 1468.9 | AB9: =ROUND(IF(L9>79999.99,900,IF(L9<10000.01,137.5,IF(10000<L9>80000,L9*2.5%))),2)-0.01 -> 792.62 | AE9: 200 | AF9: 0 | AG9: 100 | AN9: 2000 | AP9: 449.15 | AZ9: =ROUND(SUM(O9:AY9),2) -> 7864.12 | BA9: =ROUND(N9-AZ9,2) -> 25840.88 | BB9: =ROUND(BA9/2,2) -> 12920.44 | BC9: =BA9-BB9 -> 12920.44
A10: =A9+1 -> 3 | B10: Alberto | C10: Camilo | D10: M. | E10: DMO I | F10: CDMD | G10: OSEC-DAB-DMO1-125-2014 | H10: 35282 | I10: 42383 | J10: 11 | K10: 4 | L10: =IFERROR(VLOOKUP(J10, [1]DATA!$A$4:$I$36, MATCH(K10, [1]DATA!$B$3:$I$3, 0)+1, FALSE), "") -> 32401 | M10: 2000 | N10: =L10+M10 -> 34401 | O10: =ROUND(L10*9%,2) -> 2916.09 | S10: 3649.18 | AA10: 1587.48 | AB10: =ROUND(IF(L10>79999.99,900,IF(L10<10000.01,137.5,IF(10000<L10>80000,L10*2.5%))),2)-0.01 -> 810.02 | AC10: 6012.73 | AD10: 500 | AE10: 200 | AF10: 0 | AG10: 100 | AM10: 1000 | AS10: 0 | AW10: 0 | AY10: 5162.5 | AZ10: =ROUND(SUM(O10:AY10),2) -> 21938 | BA10: =ROUND(N10-AZ10,2) -> 12463 | BB10: =ROUND(BA10/2,2) -> 6231.5 | BC10: =BA10-BB10 -> 6231.5
A11: =A10+1 -> 4 | B11: Alcantara | C11: Justine Ann | D11: C. | E11: DMO I | F11: CDMD | G11: OSEC-DAB-DMO1-129-2014 | H11: 45665 | I11: 45665 | J11: 11 | K11: 1 | L11: =IFERROR(VLOOKUP(J11, [1]DATA!$A$4:$I$36, MATCH(K11, [1]DATA!$B$3:$I$3, 0)+1, FALSE), "") -> 31705 | M11: 2000 | N11: =L11+M11 -> 33705 | O11: =ROUND(L11*9%,2) -> 2853.45 | AA11: 1468.9 | AB11: =ROUND(IF(L11>79999.99,900,IF(L11<10000.01,137.5,IF(10000<L11>80000,L11*2.5%))),2)-0.01 -> 792.62 | AE11: 200 | AG11: 100 | AN11: 2000 | AO11: 461.39 | AP11: 704.35 | AZ11: =ROUND(SUM(O11:AY11),2) -> 8580.71 | BA11: =ROUND(N11-AZ11,2) -> 25124.29 | BB11: =ROUND(BA11/2,2) -> 12562.15 | BC11: =BA11-BB11 -> 12562.14
A12: =A11+1 -> 5 | B12: Alfonso | C12: Cindy | D12: C. | E12: PEO III | F12: PPD | G12: OSEC-DAB-PEO3-55-2014 | H12: 42278 | I12: 45737 | J12: 18 | K12: 1 | L12: =IFERROR(VLOOKUP(J12, [1]DATA!$A$4:$I$36, MATCH(K12, [1]DATA!$B$3:$I$3, 0)+1, FALSE), "") -> 53818 | M12: 2000 | N12: =L12+M12 -> 55818 | O12: =ROUND(L12*9%,2) -> 4843.62 | Y12: 9634.44 | AA12: 5936.18 | AB12: =ROUND(IF(L12>79999.99,900,IF(L12<10000.01,137.5,IF(10000<L12>80000,L12*2.5%))),2) -> 1345.45 | AE12: 200 | AF12: 0 | AG12: 100 | AS12: 500 | AW12: 0 | AZ12: =ROUND(SUM(O12:AY12),2) -> 22559.69 | BA12: =ROUND(N12-AZ12,2) -> 33258.31 | BB12: =ROUND(BA12/2,2) -> 16629.16 | BC12: =BA12-BB12 -> 16629.15
A13: =A12+1 -> 6 | B13: Alforque I | C13: G. Mark Anthony | D13: C | E13: PEO II | F13: PPD | G13: OSEC-DAB-PEO2-13-1998 | H13: 42451 | I13: 44090 | J13: 15 | K13: 2 | L13: =IFERROR(VLOOKUP(J13, [1]DATA!$A$4:$I$36, MATCH(K13, [1]DATA!$B$3:$I$3, 0)+1, FALSE), "") -> 42594 | M13: 2000 | N13: =L13+M13 -> 44594 | O13: =ROUND(L13*9%,2) -> 3833.46 | AA13: 3791.96 | AB13: =ROUND(IF(L13>79999.99,900,IF(L13<10000.01,137.5,IF(10000<L13>80000,L13*2.5%))),2) -> 1064.85 | AD13: 3000 | AE13: 1000 | AF13: 0 | AG13: 100 | AL13: 1000 | AS13: 0 | AW13: 0 | AZ13: =ROUND(SUM(O13:AY13),2) -> 13790.27 | BA13: =ROUND(N13-AZ13,2) -> 30803.73 | BB13: =ROUND(BA13/2,2) -> 15401.87 | BC13: =BA13-BB13 -> 15401.86
A14: =A13+1 -> 7 | B14: Alvarez | C14: Clarissa | D14: M. | E14: Adm. Asst. III | F14: AFU-OD | G14: OSEC-DAB-ADAS3-98-2004 | H14: 45700 | I14: 45700 | J14: 9 | K14: 1 | L14: =IFERROR(VLOOKUP(J14, [1]DATA!$A$4:$I$36, MATCH(K14, [1]DATA!$B$3:$I$3, 0)+1, FALSE), "") -> 24329 | M14: 2000 | N14: =L14+M14 -> 26329 | O14: =ROUND(L14*9%,2) -> 2189.61 | AA14: 593.27 | AB14: =ROUND(IF(L14>79999.99,900,IF(L14<10000.01,137.5,IF(10000<L14>80000,L14*2.5%))),2)-0.01 -> 608.22 | AE14: 200 | AF14: 0 | AG14: 100 | AS14: 0 | AW14: 0 | AZ14: =ROUND(SUM(O14:AY14),2) -> 3691.1 | BA14: =ROUND(N14-AZ14,2) -> 22637.9 | BB14: =ROUND(BA14/2,2) -> 11318.95 | BC14: =BA14-BB14 -> 11318.95
A15: =A14+1 -> 8 | B15: Alvarez | C15: Mark Nello | D15: B. | E15: Agric. II | F15: PAD | G15: OSEC-DAB-AG2-1317-1998 | H15: 42278 | I15: 44986 | J15: 15 | K15: 1 | L15: =IFERROR(VLOOKUP(J15, [1]DATA!$A$4:$I$36, MATCH(K15, [1]DATA!$B$3:$I$3, 0)+1, FALSE), "") -> 42178 | M15: 2000 | N15: =L15+M15 -> 44178 | O15: =ROUND(L15*9%,2) -> 3796.02 | V15: 9317.65 | AA15: 3695.42 | AB15: =ROUND(IF(L15>79999.99,900,IF(L15<10000.01,137.5,IF(10000<L15>80000,L15*2.5%))),2) -> 1054.45 | AD15: 2000 | AE15: 500 | AF15: 0 | AG15: 100 | AS15: 0 | AZ15: =ROUND(SUM(O15:AY15),2) -> 20463.54 | BA15: =ROUND(N15-AZ15,2) -> 23714.46 | BB15: =ROUND(BA15/2,2) -> 11857.23 | BC15: =BA15-BB15 -> 11857.23
A16: =A15+1 -> 9 | B16: Aninacion | C16: Joshua | D16: G. | E16: PLO II | F16: PPD | G16: OSEC-DAB-PLO2-54-2014 | H16: 43549 | I16: 44271 | J16: 15 | K16: 2 | L16: =IFERROR(VLOOKUP(J16, [1]DATA!$A$4:$I$36, MATCH(K16, [1]DATA!$B$3:$I$3, 0)+1, FALSE), "") -> 42594 | M16: 2000 | N16: =L16+M16 -> 44594 | O16: =ROUND(L16*9%,2) -> 3833.46 | AA16: 3791.96 | AB16: =ROUND(IF(L16>79999.99,900,IF(L16<10000.01,137.5,IF(10000<L16>80000,L16*2.5%))),2) -> 1064.85 | AE16: 200 | AF16: 0 | AG16: 100 | AS16: 0 | AZ16: =ROUND(SUM(O16:AY16),2) -> 8990.27 | BA16: =ROUND(N16-AZ16,2) -> 35603.73 | BB16: =ROUND(BA16/2,2) -> 17801.87 | BC16: =BA16-BB16 -> 17801.86
A17: =A16+1 -> 10 | B17: Antipas | C17: Andrea Jane | D17: M. | E17: Adm. Asst. I | F17: ISD | G17: OSEC-DAB-ADAS1-52-2004 | H17: 45376 | I17: 45376 | J17: 7 | K17: 1 | L17: =IFERROR(VLOOKUP(J17, [1]DATA!$A$4:$I$36, MATCH(K17, [1]DATA!$B$3:$I$3, 0)+1, FALSE), "") -> 20914 | M17: 2000 | N17: =L17+M17 -> 22914 | O17: =ROUND(L17*9%,2) -> 1882.26 | AA17: 0 | AB17: =ROUND(IF(L17>79999.99,900,IF(L17<10000.01,137.5,IF(10000<L17>80000,L17*2.5%))),2) -> 522.85 | AD17: 1000 | AE17: 200 | AG17: 100 | AK17: 1000 | AZ17: =ROUND(SUM(O17:AY17),2) -> 4705.11 | BA17: =ROUND(N17-AZ17,2) -> 18208.89 | BB17: =ROUND(BA17/2,2) -> 9104.45 | BC17: =BA17-BB17 -> 9104.44
A18: =A17+1 -> 11 | B18: Arceo | C18: Antonieta | D18: J. | E18: Director III | F18: OD | G18: OSEC-DAB-DIR3-55-1998 | H18: 34243 | I18: 44998 | J18: 27 | K18: 1 | L18: =IFERROR(VLOOKUP(J18, [1]DATA!$A$4:$I$36, MATCH(K18, [1]DATA!$B$3:$I$3, 0)+1, FALSE), "") -> 148940 | M18: 2000 | N18: =L18+M18 -> 150940 | O18: =ROUND(L18*9%,2) -> 13404.6 | P18: 500 | Q18: 655.56 | V18: 21327.3 | W18: 2333.33 | AA18: 33536.75 | AB18: 2500 | AD18: 0 | AE18: 200 | AF18: 3000 | AS18: 0 | AT18: 9470.26 | AW18: 0 | AY18: 7364.14 | AZ18: =ROUND(SUM(O18:AY18),2) -> 94291.94 | BA18: =ROUND(N18-AZ18,2) -> 56648.06 | BB18: =ROUND(BA18/2,2) -> 28324.03 | BC18: =BA18-BB18 -> 28324.03
A19: =A18+1 -> 12 | B19: Balangatan | C19: Jun | D19: G. | E19: OCO II | F19: ISD | G19: OSEC-DAB-OCO2-3-1998 | H19: 34078 | I19: 38628 | J19: 8 | K19: 7 | L19: =IFERROR(VLOOKUP(J19, [1]DATA!$A$4:$I$36, MATCH(K19, [1]DATA!$B$3:$I$3, 0)+1, FALSE), "") -> 23668 | M19: 2000 | N19: =L19+M19 -> 25668 | O19: =ROUND(L19*9%,2) -> 2130.12 | P19: 200 | V19: 4847.84 | AA19: 23.91 | AB19: =ROUND(IF(L19>79999.99,900,IF(L19<10000.01,137.5,IF(10000<L19>80000,L19*2.5%))),2) -> 591.7 | AC19: 4679.53 | AE19: 200 | AF19: 0 | AG19: 100 | AL19: 300 | AM19: 1000 | AS19: 0 | AW19: 0 | AY19: 4325.35 | AZ19: =ROUND(SUM(O19:AY19),2) -> 18398.45 | BA19: =ROUND(N19-AZ19,2) -> 7269.55 | BB19: =ROUND(BA19/2,2) -> 3634.78 | BC19: =BA19-BB19 -> 3634.77
A20: =A19+1 -> 13 | B20: Baluyut | C20: Julia Marie | D20: M. | E20: DMO I | F20: CDMD | G20: OSEC-DAB-DMO1-130-2014 | H20: 45376 | I20: 45376 | J20: 11 | K20: 1 | L20: =IFERROR(VLOOKUP(J20, [1]DATA!$A$4:$I$36, MATCH(K20, [1]DATA!$B$3:$I$3, 0)+1, FALSE), "") -> 31705 | M20: 2000 | N20: =L20+M20 -> 33705 | O20: =ROUND(L20*9%,2) -> 2853.45 | AA20: 1468.9 | AB20: =ROUND(IF(L20>79999.99,900,IF(L20<10000.01,137.5,IF(10000<L20>80000,L20*2.5%))),2)-0.01 -> 792.62 | AE20: 200 | AG20: 100 | AZ20: =ROUND(SUM(O20:AY20),2) -> 5414.97 | BA20: =ROUND(N20-AZ20,2) -> 28290.03 | BB20: =ROUND(BA20/2,2) -> 14145.02 | BC20: =BA20-BB20 -> 14145.01
A21: =A20+1 -> 14 | B21: Bautista | C21: Marilyn | D21: J. | E21: SG I | F21: AFU-OD | G21: OSEC-DAB-SECG1-262-1998 | H21: 34121 | I21: 34121 | J21: 3 | K21: 8 | L21: =IFERROR(VLOOKUP(J21, [1]DATA!$A$4:$I$36, MATCH(K21, [1]DATA!$B$3:$I$3, 0)+1, FALSE), "") -> 17360 | M21: 2000 | N21: =L21+M21 -> 19360 | O21: =ROUND(L21*9%,2) -> 1562.4 | Q21: 655.56 | S21: 2100.56 | T21: 0 | U21: 0 | Y21: 2837.17 | AA21: 0 | AB21: =ROUND(IF(L21>79999.99,900,IF(L21<10000.01,137.5,IF(10000<L21>80000,L21*2.5%))),2) -> 434 | AE21: 500 | AF21: 1200 | AG21: 100 | AS21: 1000 | AW21: 0 | AY21: 1820.83 | AZ21: =ROUND(SUM(O21:AY21),2) -> 12210.52 | BA21: =ROUND(N21-AZ21,2) -> 7149.48 | BB21: =ROUND(BA21/2,2) -> 3574.74 | BC21: =BA21-BB21 -> 3574.74
A22: =A21+1 -> 15 | B22: Bayot | C22: Czarina | D22: M. | E22: DMO III | F22: CDMD | G22: OSEC-DAB-DMO3-63-2014 | H22: 42451 | I22: 45397 | J22: 18 | K22: 1 | L22: =IFERROR(VLOOKUP(J22, [1]DATA!$A$4:$I$36, MATCH(K22, [1]DATA!$B$3:$I$3, 0)+1, FALSE), "") -> 53818 | M22: 2000 | N22: =L22+M22 -> 55818 | O22: =ROUND(L22*9%,2) -> 4843.62 | AA22: 6395.7 | AB22: =ROUND(IF(L22>79999.99,900,IF(L22<10000.01,137.5,IF(10000<L22>80000,L22*2.5%))),2) -> 1345.45 | AE22: 200 | AF22: 0 | AG22: 100 | AS22: 1135.55 | AX22: 891.15 | AY22: 3034.72 | AZ22: =ROUND(SUM(O22:AY22),2) -> 17946.19 | BA22: =ROUND(N22-AZ22,2) -> 37871.81 | BB22: =ROUND(BA22/2,2) -> 18935.91 | BC22: =BA22-BB22 -> 18935.9
A23: =A22+1 -> 16 | B23: Bibit | C23: Darwin | D23: C. | E23: Adm. Asst. II | F23: ISD | G23: OSEC-DAB-ADAS2-98-2004 | H23: 34073 | I23: 34073 | J23: 8 | K23: 8 | L23: =IFERROR(VLOOKUP(J23, [1]DATA!$A$4:$I$36, MATCH(K23, [1]DATA!$B$3:$I$3, 0)+1, FALSE), "") -> 23883 | M23: 2000 | N23: =L23+M23 -> 25883 | O23: =ROUND(L23*9%,2) -> 2149.47 | P23: 320 | S23: 0 | V23: 3558.84 | Y23: 5648.41 | AA23: 73.05 | AB23: =ROUND(IF(L23>79999.99,900,IF(L23<10000.01,137.5,IF(10000<L23>80000,L23*2.5%))),2)-0.01 -> 597.07 | AC23: 1195.45 | AE23: 200 | AF23: 0 | AG23: 100 | AL23: 100 | AM23: 3750 | AO23: 922.78 | AP23: 1408.7 | AS23: 0 | AW23: 0 | AZ23: =ROUND(SUM(O23:AY23),2) -> 20023.77 | BA23: =ROUND(N23-AZ23,2) -> 5859.23 | BB23: =ROUND(BA23/2,2) -> 2929.62 | BC23: =BA23-BB23 -> 2929.61
A24: =A23+1 -> 17 | B24: Bolon | C24: Richard | D24: E. | E24: Adm. Aide V | F24: AFU-OD | G24: OSEC-DAB-ADA5-17-2004 | H24: 37712 | I24: 37712 | J24: 5 | K24: 8 | L24: =IFERROR(VLOOKUP(J24, [1]DATA!$A$4:$I$36, MATCH(K24, [1]DATA!$B$3:$I$3, 0)+1, FALSE), "") -> 19565 | M24: 2000 | N24: =L24+M24 -> 21565 | O24: =ROUND(L24*9%,2) -> 1760.85 | P24: 300 | Q24: 655.56 | V24: 2698.53 | W24: 1166.67 | Y24: 3372.06 | AA24: 0 | AB24: =ROUND(IF(L24>79999.99,900,IF(L24<10000.01,137.5,IF(10000<L24>80000,L24*2.5%))),2)-0.01 -> 489.12 | AC24: 279.7 | AD24: 0 | AE24: 200 | AF24: 0 | AG24: 100 | AH24: 1336 | AS24: 500 | AW24: 0 | AY24: 2994.22 | AZ24: =ROUND(SUM(O24:AY24),2) -> 15852.71 | BA24: =ROUND(N24-AZ24,2) -> 5712.29 | BB24: =ROUND(BA24/2,2) -> 2856.15 | BC24: =BA24-BB24 -> 2856.14
A25: =A24+1 -> 18 | B25: Bombon | C25: Mary Angelyn | D25: P. | E25: DMO II | F25: CDMD | G25: OSEC-DAB-DMO2-62-2014 | H25: 44291 | I25: 45719 | J25: 15 | K25: 1 | L25: =IFERROR(VLOOKUP(J25, [1]DATA!$A$4:$I$36, MATCH(K25, [1]DATA!$B$3:$I$3, 0)+1, FALSE), "") -> 42178 | M25: 2000 | N25: =L25+M25 -> 44178 | O25: =ROUND(L25*9%,2) -> 3796.02 | AA25: 3335.99 | AB25: =ROUND(IF(L25>79999.99,900,IF(L25<10000.01,137.5,IF(10000<L25>80000,L25*2.5%))),2) -> 1054.45 | AE25: 200 | AF25: 0 | AG25: 100 | AS25: 0 | AT25: 6313.51 | AZ25: =ROUND(SUM(O25:AY25),2) -> 14799.97 | BA25: =ROUND(N25-AZ25,2) -> 29378.03 | BB25: =ROUND(BA25/2,2) -> 14689.02 | BC25: =BA25-BB25 -> 14689.01
A26: =A25+1 -> 19 | B26: Borlagdan | C26: Franco Gabriel | D26: P. | E26: ISR III | F26: ISD | G26: OSEC-DAB-INFOSR3-18-2014 | H26: 42451 | I26: 44271 | J26: 17 | K26: 2 | L26: =IFERROR(VLOOKUP(J26, [1]DATA!$A$4:$I$36, MATCH(K26, [1]DATA!$B$3:$I$3, 0)+1, FALSE), "") -> 50066 | M26: 2000 | N26: =L26+M26 -> 52066 | O26: =ROUND(L26*9%,2) -> 4505.94 | AA26: 5537.02 | AB26: =ROUND(IF(L26>79999.99,900,IF(L26<10000.01,137.5,IF(10000<L26>80000,L26*2.5%))),2) -> 1251.65 | AD26: 1000 | AE26: 200 | AF26: 0 | AG26: 100 | AS26: 0 | AW26: 0 | AZ26: =ROUND(SUM(O26:AY26),2) -> 12594.61 | BA26: =ROUND(N26-AZ26,2) -> 39471.39 | BB26: =ROUND(BA26/2,2) -> 19735.7 | BC26: =BA26-BB26 -> 19735.69
A27: =A26+1 -> 20 | B27: Borromeo | C27: Kemuel | D27: M. | E27: DMO III | F27: CDMD | G27: OSEC-DAB-DMO3-61-2014 | H27: 42383 | I27: 45027 | J27: 18 | K27: 1 | L27: =IFERROR(VLOOKUP(J27, [1]DATA!$A$4:$I$36, MATCH(K27, [1]DATA!$B$3:$I$3, 0)+1, FALSE), "") -> 53818 | M27: 2000 | N27: =L27+M27 -> 55818 | O27: =ROUND(L27*9%,2) -> 4843.62 | Q27: 655.56 | V27: 6918.77 | X27: 1966.67 | AA27: 6395.7 | AB27: =ROUND(IF(L27>79999.99,900,IF(L27<10000.01,137.5,IF(10000<L27>80000,L27*2.5%))),2) -> 1345.45 | AD27: 0 | AE27: 1500 | AF27: 0 | AG27: 100 | AL27: 500 | AS27: 707.29 | AY27: 6165.86 | AZ27: =ROUND(SUM(O27:AY27),2) -> 31098.92 | BA27: =ROUND(N27-AZ27,2) -> 24719.08 | BB27: =ROUND(BA27/2,2) -> 12359.54 | BC27: =BA27-BB27 -> 12359.54
A28: =A27+1 -> 21 | B28: Bunda | C28: Arnel | D28: R. | E28: PLO I | F28: PPD | G28: OSEC-DAB-PLO1-1-1998 | H28: 42278 | I28: 42278 | J28: 11 | K28: 4 | L28: =IFERROR(VLOOKUP(J28, [1]DATA!$A$4:$I$36, MATCH(K28, [1]DATA!$B$3:$I$3, 0)+1, FALSE), "") -> 32401 | M28: 2000 | N28: =L28+M28 -> 34401 | O28: =ROUND(L28*9%,2) -> 2916.09 | Q28: 1152.41 | V28: 4165.63 | W28: 1166.67 | AA28: 1587.48 | AB28: =ROUND(IF(L28>79999.99,900,IF(L28<10000.01,137.5,IF(10000<L28>80000,L28*2.5%))),2)-0.01 -> 810.02 | AD28: 0 | AE28: 200 | AF28: 0 | AG28: 100 | AL28: 100 | AS28: 0 | AW28: 0 | AZ28: =ROUND(SUM(O28:AY28),2) -> 12198.3 | BA28: =ROUND(N28-AZ28,2) -> 22202.7 | BB28: =ROUND(BA28/2,2) -> 11101.35 | BC28: =BA28-BB28 -> 11101.35
A29: =A28+1 -> 22 | B29: Calasagsag | C29: Joeven | D29: C. | E29: Supervising Agric. | F29: PAD | G29: OSEC-DAB-SVAG-105-1998 | H29: 42278 | I29: 45607 | J29: 22 | K29: 1 | L29: =IFERROR(VLOOKUP(J29, [1]DATA!$A$4:$I$36, MATCH(K29, [1]DATA!$B$3:$I$3, 0)+1, FALSE), "") -> 81796 | M29: 2000 | N29: =L29+M29 -> 83796 | O29: =ROUND(L29*9%,2) -> 7361.64 | AA29: 13765.43 | AB29: =L29*2.5% -> 2044.9 | AD29: 0 | AE29: 500 | AG29: 100 | AL29: 500 | AS29: 388.51 | AW29: 0 | AX29: 1201.31 | AY29: 3034.72 | AZ29: =ROUND(SUM(O29:AY29),2) -> 28896.51 | BA29: =ROUND(N29-AZ29,2) -> 54899.49 | BB29: =ROUND(BA29/2,2) -> 27449.75 | BC29: =BA29-BB29 -> 27449.74
A30: =A29+1 -> 23 | B30: Canilang | C30: Ashlee | D30: P. | E30: MPS II | F30: ISD | G30: OSEC-DAB-MPXS2-19-2014 | H30: 43481 | I30: 45027 | J30: 15 | K30: 1 | L30: =IFERROR(VLOOKUP(J30, [1]DATA!$A$4:$I$36, MATCH(K30, [1]DATA!$B$3:$I$3, 0)+1, FALSE), "") -> 42178 | M30: 2000 | N30: =L30+M30 -> 44178 | O30: =ROUND(L30*9%,2) -> 3796.02 | Q30: 1311.12 | V30: 5422.38 | W30: 1400 | X30: 1966.67 | AA30: 3695.42 | AB30: =ROUND(IF(L30>79999.99,900,IF(L30<10000.01,137.5,IF(10000<L30>80000,L30*2.5%))),2) -> 1054.45 | AC30: 984.58 | AD30: 1000 | AE30: 200 | AF30: 0 | AG30: 100 | AN30: 2000 | AO30: 527.3 | AP30: 272.21 | AS30: 0 | AW30: 0 | AY30: 3034.72 | AZ30: =ROUND(SUM(O30:AY30),2) -> 26764.87 | BA30: =ROUND(N30-AZ30,2) -> 17413.13 | BB30: =ROUND(BA30/2,2) -> 8706.57 | BC30: =BA30-BB30 -> 8706.56
A31: =A30+1 -> 24 | B31: Cosico | C31: Theresa Aurora | D31: B. | E31: DMO III | F31: CDMD | G31: OSEC-DAB-DMO3-62-2014 | H31: 37494 | I31: 42278 | J31: 18 | K31: 4 | L31: =IFERROR(VLOOKUP(J31, [1]DATA!$A$4:$I$36, MATCH(K31, [1]DATA!$B$3:$I$3, 0)+1, FALSE), "") -> 55499 | M31: 2000 | N31: =L31+M31 -> 57499 | O31: =ROUND(L31*9%,2) -> 4994.91 | P31: 300 | Q31: 1311.12 | R31: 2040.79 | T31: 263.21 | U31: 500 | V31: 8242.67 | W31: 2333.33 | X31: 1966.67 | AA31: 6798.6 | AB31: =ROUND(IF(L31>79999.99,900,IF(L31<10000.01,137.5,IF(10000<L31>80000,L31*2.5%))),2)-0.01 -> 1387.47 | AC31: 2509.62 | AE31: 200 | AG31: 100 | AL31: 100 | AM31: 1000 | AS31: 0 | AW31: 0 | AX31: 2024.84 | AY31: 5608.24 | AZ31: =ROUND(SUM(O31:AY31),2) -> 41681.47 | BA31: =ROUND(N31-AZ31,2) -> 15817.53 | BB31: =ROUND(BA31/2,2) -> 7908.77 | BC31: =BA31-BB31 -> 7908.76
A32: =A31+1 -> 25 | B32: Dacillo | C32: Edmer | D32: B. | E32: CMT II | F32: ISD | G32: OSEC-DAB-CTMT2-50-2014 | H32: 44418 | I32: 45062 | J32: 15 | K32: 1 | L32: =IFERROR(VLOOKUP(J32, [1]DATA!$A$4:$I$36, MATCH(K32, [1]DATA!$B$3:$I$3, 0)+1, FALSE), "") -> 42178 | M32: 2000 | N32: =L32+M32 -> 44178 | O32: =ROUND(L32*9%,2) -> 3796.02 | AA32: 3695.42 | AB32: =ROUND(IF(L32>79999.99,900,IF(L32<10000.01,137.5,IF(10000<L32>80000,L32*2.5%))),2) -> 1054.45 | AE32: 200 | AF32: 0 | AG32: 100 | AY32: 3034.72 | AZ32: =ROUND(SUM(O32:AY32),2) -> 11880.61 | BA32: =ROUND(N32-AZ32,2) -> 32297.39 | BB32: =ROUND(BA32/2,2) -> 16148.7 | BC32: =BA32-BB32 -> 16148.69
A33: =A32+1 -> 26 | B33: Datuin | C33: Jejorian | D33: Q. | E33: DMO II | F33: CDMD | G33: OSEC-DAB-DMO2-67-2014 | H33: 42348 | I33: 43466 | J33: 15 | K33: 3 | L33: =IFERROR(VLOOKUP(J33, [1]DATA!$A$4:$I$36, MATCH(K33, [1]DATA!$B$3:$I$3, 0)+1, FALSE), "") -> 43015 | M33: 2000 | N33: =L33+M33 -> 45015 | O33: =ROUND(L33*9%,2) -> 3871.35 | Y33: 9634.44 | AA33: 3889.58 | AB33: =ROUND(IF(L33>79999.99,900,IF(L33<10000.01,137.5,IF(10000<L33>80000,L33*2.5%))),2)-0.01 -> 1075.37 | AE33: 200 | AF33: 0 | AG33: 100 | AS33: 0 | AX33: 930.05 | AZ33: =ROUND(SUM(O33:AY33),2) -> 19700.79 | BA33: =ROUND(N33-AZ33,2) -> 25314.21 | BB33: =ROUND(BA33/2,2) -> 12657.11 | BC33: =BA33-BB33 -> 12657.1
A34: =A33+1 -> 27 | B34: de la Cruz | C34: Roy Son | D34: R. | E34: PLO III | F34: PPD | G34: OSEC-DAB-PLO3-3-1998 | H34: 42348 | I34: 46027 | J34: 18 | K34: 1 | L34: =IFERROR(VLOOKUP(J34, [1]DATA!$A$4:$I$36, MATCH(K34, [1]DATA!$B$3:$I$3, 0)+1, FALSE), "") -> 53818 | M34: 2000 | N34: =L34+M34 -> 55818 | O34: =ROUND(L34*9%,2) -> 4843.62 | V34: 1101.28 | W34: 1400 | Y34: 9634.44 | AA34: 6974.58 | AB34: =ROUND(IF(L34>79999.99,900,IF(L34<10000.01,137.5,IF(10000<L34>80000,L34*2.5%))),2) -> 1345.45 | AD34: 0 | AE34: 500 | AF34: 0 | AG34: 100 | AH34: 1336 | AS34: 910.34 | AW34: 0 | AY34: 2124.3 | AZ34: =ROUND(SUM(O34:AY34),2) -> 30270.01 | BA34: =ROUND(N34-AZ34,2) -> 25547.99 | BB34: =ROUND(BA34/2,2) -> 12774 | BC34: =BA34-BB34 -> 12773.99
A35: =A34+1 -> 28 | B35: de Mesa | C35: Maria Carmina | D35: M. | E35: Agric. I | F35: PAD | G35: OSEC-DAB-AG1-162-1998 | H35: 42998 | I35: 42998 | J35: 11 | K35: 3 | L35: =IFERROR(VLOOKUP(J35, [1]DATA!$A$4:$I$36, MATCH(K35, [1]DATA!$B$3:$I$3, 0)+1, FALSE), "") -> 32109 | M35: 2000 | N35: =L35+M35 -> 34109 | O35: =ROUND(L35*9%,2) -> 2889.81 | V35: 4126.25 | Y35: 9634.44 | AA35: 1537.23 | AB35: =ROUND(IF(L35>79999.99,900,IF(L35<10000.01,137.5,IF(10000<L35>80000,L35*2.5%))),2)-0.01 -> 802.72 | AE35: 200 | AF35: 0 | AG35: 100 | AS35: 0 | AW35: 0 | AZ35: =ROUND(SUM(O35:AY35),2) -> 19290.45 | BA35: =ROUND(N35-AZ35,2) -> 14818.55 | BB35: =ROUND(BA35/2,2) -> 7409.28 | BC35: =BA35-BB35 -> 7409.27
A36: =A35+1 -> 29 | B36: dela Cuadra | C36: Jovanee | D36: S. | E36: Agric. II | F36: PAD | G36: OSEC-DAB-AG2-1328-1998 | H36: 42278 | I36: 42278 | J36: 15 | K36: 4 | L36: =IFERROR(VLOOKUP(J36, [1]DATA!$A$4:$I$36, MATCH(K36, [1]DATA!$B$3:$I$3, 0)+1, FALSE), "") -> 43442 | M36: 2000 | N36: =L36+M36 -> 45442 | O36: =ROUND(L36*9%,2) -> 3909.78 | P36: 500 | Q36: 655.56 | V36: 5041 | X36: 1966.67 | AA36: 3998.79 | AB36: =ROUND(IF(L36>79999.99,900,IF(L36<10000.01,137.5,IF(10000<L36>80000,L36*2.5%))),2) -> 1086.05 | AC36: 667.35 | AD36: 1000 | AE36: 200 | AF36: 0 | AG36: 100 | AH36: 1336 | AS36: 1000 | AT36: 4735.13 | AW36: 0 | AY36: 3034.72 | AZ36: =ROUND(SUM(O36:AY36),2) -> 29231.05 | BA36: =ROUND(N36-AZ36,2) -> 16210.95 | BB36: =ROUND(BA36/2,2) -> 8105.48 | BC36: =BA36-BB36 -> 8105.47
A37: =A36+1 -> 30 | B37: dela Torre | C37: Julrose | D37: H. | E37: IO II | F37: ISD | G37: OSEC-DAB-INFO2-25-1998 | H37: 43468 | I37: 45670 | J37: 15 | K37: 1 | L37: =IFERROR(VLOOKUP(J37, [1]DATA!$A$4:$I$36, MATCH(K37, [1]DATA!$B$3:$I$3, 0)+1, FALSE), "") -> 42178 | M37: 2000 | N37: =L37+M37 -> 44178 | O37: =ROUND(L37*9%,2) -> 3796.02 | P37: 500 | Q37: 1311.12 | V37: 5422.38 | W37: 1400 | X37: 1966.67 | AA37: 3695.42 | AB37: =ROUND(IF(L37>79999.99,900,IF(L37<10000.01,137.5,IF(10000<L37>80000,L37*2.5%))),2) -> 1054.45 | AE37: 200 | AF37: 0 | AG37: 100 | AS37: 0 | AT37: 7180.79 | AW37: 0 | AY37: 4552.08 | AZ37: =ROUND(SUM(O37:AY37),2) -> 31178.93 | BA37: =ROUND(N37-AZ37,2) -> 12999.07 | BB37: =ROUND(BA37/2,2) -> 6499.54 | BC37: =BA37-BB37 -> 6499.53
A38: =A37+1 -> 31 | B38: Dellava | C38: Robert | D38: D. | E38: SG I | F38: AFU-OD | G38: OSEC-DAB-SECG1-258-1998 | H38: 37712 | I38: 37712 | J38: 3 | K38: 8 | L38: =IFERROR(VLOOKUP(J38, [1]DATA!$A$4:$I$36, MATCH(K38, [1]DATA!$B$3:$I$3, 0)+1, FALSE), "") -> 17360 | M38: 2000 | N38: =L38+M38 -> 19360 | O38: =ROUND(L38*9%,2) -> 1562.4 | P38: 200 | V38: 2600.69 | AA38: 0 | AB38: =ROUND(IF(L38>79999.99,900,IF(L38<10000.01,137.5,IF(10000<L38>80000,L38*2.5%))),2) -> 434 | AC38: 3737.95 | AD38: 500 | AE38: 200 | AF38: 0 | AG38: 100 | AL38: 100 | AM38: 500 | AS38: 400 | AW38: 0 | AY38: 3034.72 | AZ38: =ROUND(SUM(O38:AY38),2) -> 13369.76 | BA38: =ROUND(N38-AZ38,2) -> 5990.24 | BB38: =ROUND(BA38/2,2) -> 2995.12 | BC38: =BA38-BB38 -> 2995.12
A39: =A38+1 -> 32 | B39: delos Santos | C39: Josefina | D39: M. | E39: AO I | F39: AFU-OD | G39: OSEC-DAB-ADOF1-75-2004 | H39: 35786 | I39: 45737 | J39: 10 | K39: 1 | L39: =IFERROR(VLOOKUP(J39, [1]DATA!$A$4:$I$36, MATCH(K39, [1]DATA!$B$3:$I$3, 0)+1, FALSE), "") -> 26917 | M39: 2000 | N39: =L39+M39 -> 28917 | O39: =ROUND(L39*9%,2) -> 2422.53 | P39: 400 | Q39: 1191.88 | V39: 3986.18 | X39: 1966.67 | Y39: 2505.4 | AA39: 447.46 | AB39: =ROUND(IF(L39>79999.99,900,IF(L39<10000.01,137.5,IF(10000<L39>80000,L39*2.5%))),2)-0.01 -> 672.92 | AD39: 0 | AE39: 300 | AF39: 0 | AG39: 100 | AL39: 100 | AS39: 0 | AT39: 3156.75 | AW39: 0 | AY39: 3034.72 | AZ39: =ROUND(SUM(O39:AY39),2) -> 20284.51 | BA39: =ROUND(N39-AZ39,2) -> 8632.49 | BB39: =ROUND(BA39/2,2) -> 4316.25 | BC39: =BA39-BB39 -> 4316.24
A40: =A39+1 -> 33 | B40: Deñado | C40: Emerson | D40: R. | E40: Agric. II | F40: ISD | G40: OSEC-DAB-AG2-968-1998 | H40: 42451 | I40: 42998 | J40: 15 | K40: 3 | L40: =IFERROR(VLOOKUP(J40, [1]DATA!$A$4:$I$36, MATCH(K40, [1]DATA!$B$3:$I$3, 0)+1, FALSE), "") -> 43015 | M40: 2000 | N40: =L40+M40 -> 45015 | O40: =ROUND(L40*9%,2) -> 3871.35 | AA40: 3889.58 | AB40: =ROUND(IF(L40>79999.99,900,IF(L40<10000.01,137.5,IF(10000<L40>80000,L40*2.5%))),2)-0.01 -> 1075.37 | AD40: 1000 | AE40: 200 | AF40: 0 | AG40: 100 | AL40: 100 | AM40: 7500 | AN40: 2000 | AO40: 527.3 | AP40: 272.21 | AS40: 0 | AU40: 14749.76 | AY40: 3034.72 | AZ40: =ROUND(SUM(O40:AY40),2) -> 38320.29 | BA40: =ROUND(N40-AZ40,2) -> 6694.71 | BB40: =ROUND(BA40/2,2) -> 3347.36 | BC40: =BA40-BB40 -> 3347.35
A41: =A40+1 -> 34 | B41: Dreje | C41: Sherrie | D41: C. | E41: Sr. Agric. | F41: PAD | G41: OSEC-DAB-SRAG-162-1998 | H41: 42278 | I41: 44929 | J41: 18 | K41: 2 | L41: =IFERROR(VLOOKUP(J41, [1]DATA!$A$4:$I$36, MATCH(K41, [1]DATA!$B$3:$I$3, 0)+1, FALSE), "") -> 54371 | M41: 2000 | N41: =L41+M41 -> 56371 | O41: =ROUND(L41*9%,2) -> 4893.39 | Y41: 8646.86 | AA41: 6395.7 | AB41: =ROUND(IF(L41>79999.99,900,IF(L41<10000.01,137.5,IF(10000<L41>80000,L41*2.5%))),2) -> 1359.28 | AE41: 500 | AF41: 0 | AG41: 100 | AK41: 1000 | AN41: 2000 | AO41: 461.39 | AP41: 704.35 | AS41: 0 | AW41: 0 | AY41: 5826.67 | AZ41: =ROUND(SUM(O41:AY41),2) -> 31887.64 | BA41: =ROUND(N41-AZ41,2) -> 24483.36 | BB41: =ROUND(BA41/2,2) -> 12241.68 | BC41: =BA41-BB41 -> 12241.68
A42: =A41+1 -> 35 | B42: Drueco | C42: Janina | D42: G. | E42: DMO II | F42: CDMD | G42: OSEC-DAB-DMO2-60-2014 | H42: 42293 | I42: 42293 | J42: 15 | K42: 4 | L42: =IFERROR(VLOOKUP(J42, [1]DATA!$A$4:$I$36, MATCH(K42, [1]DATA!$B$3:$I$3, 0)+1, FALSE), "") -> 43442 | M42: 2000 | N42: =L42+M42 -> 45442 | O42: =ROUND(L42*9%,2) -> 3909.78 | AA42: 3998.79 | AB42: =ROUND(IF(L42>79999.99,900,IF(L42<10000.01,137.5,IF(10000<L42>80000,L42*2.5%))),2) -> 1086.05 | AD42: 0 | AE42: 200 | AF42: 0 | AG42: 100 | AS42: 1420.64 | AW42: 0 | AX42: 1476.39 | AZ42: =ROUND(SUM(O42:AY42),2) -> 12191.65 | BA42: =ROUND(N42-AZ42,2) -> 33250.35 | BB42: =ROUND(BA42/2,2) -> 16625.18 | BC42: =BA42-BB42 -> 16625.17
A43: =A42+1 -> 36 | B43: Espeña | C43: God Rick | D43: M. | E43: PDO I | F43: PPD | G43: OSEC-DAB-PDO1-60-2014 | H43: 44228 | I43: 44228 | J43: 11 | K43: 2 | L43: =IFERROR(VLOOKUP(J43, [1]DATA!$A$4:$I$36, MATCH(K43, [1]DATA!$B$3:$I$3, 0)+1, FALSE), "") -> 31820 | M43: 2000 | N43: =L43+M43 -> 33820 | O43: =ROUND(L43*9%,2) -> 2863.8 | AA43: 1481.83 | AB43: =ROUND(IF(L43>79999.99,900,IF(L43<10000.01,137.5,IF(10000<L43>80000,L43*2.5%))),2) -> 795.5 | AE43: 200 | AF43: 0 | AG43: 100 | AS43: 0 | AZ43: =ROUND(SUM(O43:AY43),2) -> 5441.13 | BA43: =ROUND(N43-AZ43,2) -> 28378.87 | BB43: =ROUND(BA43/2,2) -> 14189.44 | BC43: =BA43-BB43 -> 14189.43
A44: =A43+1 -> 37 | B44: Estoesta | C44: Dominador | D44: N. | E44: Adm. Aide IV | F44: AFU-OD | G44: OSEC-DAB-ADA4-412-2004 | H44: 34704 | I44: 34704 | J44: 4 | K44: 8 | L44: =IFERROR(VLOOKUP(J44, [1]DATA!$A$4:$I$36, MATCH(K44, [1]DATA!$B$3:$I$3, 0)+1, FALSE), "") -> 18433 | M44: 2000 | N44: =L44+M44 -> 20433 | O44: =ROUND(L44*9%,2) -> 1658.97 | P44: 200 | Q44: 655.56 | V44: 2561.74 | Y44: 3797.05 | AA44: 0 | AB44: =ROUND(IF(L44>79999.99,900,IF(L44<10000.01,137.5,IF(10000<L44>80000,L44*2.5%))),2)-0.01 -> 460.82 | AC44: 1295.63 | AD44: 0 | AE44: 200 | AF44: 0 | AG44: 100 | AH44: 1336 | AS44: 0 | AW44: 0 | AY44: 2124.3 | AZ44: =ROUND(SUM(O44:AY44),2) -> 14390.07 | BA44: =ROUND(N44-AZ44,2) -> 6042.93 | BB44: =ROUND(BA44/2,2) -> 3021.47 | BC44: =BA44-BB44 -> 3021.46
...
