Workbook

Sheet MASTER DATA 
A2: JOB ORDER GENERAL PAYROLL
A3: For The Period of
A4: 02-16-28-2026
A6: No. | B6: ORS Number | C6: ORS Date | E6: Name | F6: Office | G6: Position | H6: Salary Grade | I6: FUND SOURCE | K6: 1st QTR. Work Schedule - | M6: Monthly Rate | N6: Quincena | O6: Daily Rate | P6: Per Hour | Q6: Per Minute | R6: Working Days | S6: Basic Salary | T6: 02-01-15-2026 | W6: =T6 -> 02-01-15-2026 | Z6: 02-16-28-2026 | AC6: =Z6 -> 02-16-28-2026 | AI6: =AF6 | AL6: TOTAL | AO6: Total | AP6: Other Deduction | AR6: Gross Amount | AS6: Withholding Tax | AU6: Deductions | AY6: Net Pay
T7: IN PESO | U7: Late / Under Time | W7: IN PESO | X7: Late / Under Time | Z7: IN PESO | AA7: Late / Under Time | AC7: IN PESO | AD7: Late / Under Time | AG7: Late / Under Time | AI7: IN PESO | AJ7: Late / Under Time | AL7: IN PESO | AM7: Late / Under Time | AP7: Clothing and Others | AQ7: Remarks | AS7: EXPANDED | AT7: PERCENTAGE | AU7: Accommodation (Staff house) | AV7: Water (Staff house) | AW7: Electricity (Staff house) | AX7: Repairs
K8: Time In | L8: Time Out | T8: Absent | U8: Hour | V8: Minute | W8: Absent | X8: Hour | Y8: Minute | Z8: Absent | AA8: Hour | AB8: Minute | AC8: Absent | AD8: Hour | AE8: Minute | AF8: Absent | AG8: Hour | AH8: Minute | AI8: Absent | AJ8: Hour | AK8: Minute | AL8: Absent | AM8: Hour | AN8: Minute | AS8: 0.02 | AT8: 0
A9: 1 | B9: 2 | C9: 3 | D9: 4 | E9: 5 | F9: 6 | G9: 7 | H9: 8 | L9: 10 | M9: 11 | N9: 12 | O9: 13 | P9: 14 | Q9: 15 | R9: 16 | S9: 17 | T9: 18 | U9: 19 | V9: 20 | W9: 21 | X9: 22 | Y9: 23 | Z9: 24 | AA9: 25 | AB9: 26 | AC9: 27 | AD9: 28 | AE9: 29 | AF9: 24 | AG9: 25 | AH9: 26 | AI9: 27 | AJ9: 28 | AK9: 29 | AL9: 30 | AM9: 31 | AN9: 32 | AO9: 33 | AR9: 36 | AS9: 37 | AT9: 38 | AU9: 39 | AV9: 40 | AW9: 41 | AX9: 41 | AY9: 42
A10: 1 | B10: 2026-01-0009 | C10: 46036 | E10: ALBOROTO, JANET P. | F10: GH | G10: Administrative Asst. III | H10: 9 | I10: REVOLVING FUND | J10: ok | M10: =IFERROR(VLOOKUP($H10,'CODE 2'!$J:$K,2,FALSE)," ") -> 21211 | N10: =ROUND((M10/2),2) -> 10605.5 | O10: =M10/22 -> 964.13636 | P10: =O10/8 -> 120.51705 | Q10: =P10/60 -> 2.0086174 | R10: 11 | S10: =ROUND((O10*R10),2) -> 10605.5 | T10: 0 | U10: 0 | V10: 0 | W10: 0 | X10: =ROUND(($P10*$U10),2) -> 0 | Y10: =ROUND(($Q10*$V10),2) -> 0 | AC10: =ROUND(($O10*$Z10),2) -> 0 | AD10: =ROUND(($P10*$AA10),2) -> 0 | AE10: =ROUND(($Q10*$AB10),2) -> 0 | AI10: =IFERROR(ROUND(($O10*$AF10),2)," ") -> 0 | AJ10: =IFERROR(ROUND(($P10*$AG10),2),"") -> 0 | AK10: =IFERROR(ROUND(($Q10*$AH10),2),"") -> 0 | AL10: =ROUND(($W10+$AC10+$AI10),2) -> 0 | AM10: =ROUND(($X10+$AD10+$AJ10),2) -> 0 | AN10: =ROUND(($Y10+$AE10+$AK10),2) -> 0 | AO10: =SUM(AL10:AN10) -> 0 | AR10: =ROUND((S10-AO10-AP10),2) -> 10605.5 | AT10: =ROUND((AR10*$AT$8),2) -> 0 | AY10: =ROUND((AR10-AS10-AT10-AU10-AV10-AW10-AX10),2) -> 10605.5 | AZ10: #REF!
A11: 2 | B11: 2026-01-0010 | C11: 46036 | E11: ARENAS, DIANA ROSE A. | F11: GH | G11: Administrative Asst. IV (Dormitory Assistant) | H11: 10 | I11: REVOLVING FUND | J11: ok | M11: =IFERROR(VLOOKUP($H11,'CODE 2'!$J:$K,2,FALSE)," ") -> 23176 | N11: =ROUND((M11/2),2) -> 11588 | O11: =M11/22 -> 1053.4545 | P11: =O11/8 -> 131.68182 | Q11: =P11/60 -> 2.194697 | R11: 11 | S11: =ROUND((O11*R11),2) -> 11588 | T11: 0 | U11: 0 | V11: 4 | W11: 0 | X11: =ROUND(($P11*$U11),2) -> 0 | Y11: =ROUND(($Q11*$V11),2) -> 8.78 | AC11: =ROUND(($O11*$Z11),2) -> 0 | AD11: =ROUND(($P11*$AA11),2) -> 0 | AE11: =ROUND(($Q11*$AB11),2) -> 0 | AI11: =IFERROR(ROUND(($O11*$AF11),2)," ") -> 0 | AJ11: =IFERROR(ROUND(($P11*$AG11),2),"") -> 0 | AK11: =IFERROR(ROUND(($Q11*$AH11),2),"") -> 0 | AL11: =ROUND(($W11+$AC11+$AI11),2) -> 0 | AM11: =ROUND(($X11+$AD11+$AJ11),2) -> 0 | AN11: =ROUND(($Y11+$AE11+$AK11),2) -> 8.78 | AO11: =SUM(AL11:AN11) -> 8.78 | AR11: =ROUND((S11-AO11-AP11),2) -> 11579.22 | AT11: =ROUND((AR11*$AT$8),2) -> 0 | AY11: =ROUND((AR11-AS11-AT11-AU11-AV11-AW11-AX11),2) -> 11579.22 | AZ11: #REF!
A12: 3 | E12: BERNABE, JOHN MICHAEL A. | F12: GH | G12: Administrative Asst. III | H12: 9 | I12: REVOLVING FUND | J12: ok | M12: =IFERROR(VLOOKUP($H12,'CODE 2'!$J:$K,2,FALSE)," ") -> 21211 | N12: =ROUND((M12/2),2) -> 10605.5 | O12: =M12/22 -> 964.13636 | P12: =O12/8 -> 120.51705 | Q12: =P12/60 -> 2.0086174 | R12: 11 | S12: =ROUND((O12*R12),2) -> 10605.5
A13: 4 | B13: 2026-01-0002 | C13: 46036 | E13: CANNU JR, ALFREDO O. | F13: GH | G13: Administrative Asst. III (Housekeeping Attendant) | H13: 9 | I13: REVOLVING FUND | J13: ok | M13: =IFERROR(VLOOKUP($H13,'CODE 2'!$J:$K,2,FALSE)," ") -> 21211 | N13: =ROUND((M13/2),2) -> 10605.5 | O13: =M13/22 -> 964.13636 | P13: =O13/8 -> 120.51705 | Q13: =P13/60 -> 2.0086174 | R13: 11 | S13: =ROUND((O13*R13),2) -> 10605.5 | T13: 0 | U13: 0 | V13: 14 | W13: =ROUND(($O13*$T13),2) -> 0 | X13: =ROUND(($P13*$U13),2) -> 0 | Y13: =ROUND(($Q13*$V13),2) -> 28.12 | AC13: =ROUND(($O13*$Z13),2) -> 0 | AD13: =ROUND(($P13*$AA13),2) -> 0 | AE13: =ROUND(($Q13*$AB13),2) -> 0 | AI13: =IFERROR(ROUND(($O13*$AF13),2)," ") -> 0 | AJ13: =IFERROR(ROUND(($P13*$AG13),2),"") -> 0 | AK13: =IFERROR(ROUND(($Q13*$AH13),2),"") -> 0 | AL13: =ROUND(($W13+$AC13+$AI13),2) -> 0 | AM13: =ROUND(($X13+$AD13+$AJ13),2) -> 0 | AN13: =ROUND(($Y13+$AE13+$AK13),2) -> 28.12 | AO13: =SUM(AL13:AN13) -> 28.12 | AR13: =ROUND((S13-AO13-AP13),2) -> 10577.38 | AT13: =ROUND((AR13*$AT$8),2) -> 0 | AY13: =ROUND((AR13-AS13-AT13-AU13-AV13-AW13-AX13),2) -> 10577.38 | AZ13: #REF!
A14: 5 | B14: 2026-01-0001 | C14: 46036 | E14: CELOCIA, MERLITA O. | F14: GH | G14: Administrative Asst. III | H14: 9 | I14: REVOLVING FUND | J14: ok | M14: =IFERROR(VLOOKUP($H14,'CODE 2'!$J:$K,2,FALSE)," ") -> 21211 | N14: =ROUND((M14/2),2) -> 10605.5 | O14: =M14/22 -> 964.13636 | P14: =O14/8 -> 120.51705 | Q14: =P14/60 -> 2.0086174 | R14: 11 | S14: =ROUND((O14*R14),2) -> 10605.5 | T14: 0 | U14: 0 | V14: 0 | W14: =ROUND(($O14*$T14),2) -> 0 | X14: =ROUND(($P14*$U14),2) -> 0 | Y14: =ROUND(($Q14*$V14),2) -> 0 | AC14: =ROUND(($O14*$Z14),2) -> 0 | AD14: =ROUND(($P14*$AA14),2) -> 0 | AE14: =ROUND(($Q14*$AB14),2) -> 0 | AI14: =IFERROR(ROUND(($O14*$AF14),2)," ") -> 0 | AJ14: =IFERROR(ROUND(($P14*$AG14),2),"") -> 0 | AK14: =IFERROR(ROUND(($Q14*$AH14),2),"") -> 0 | AL14: =ROUND(($W14+$AC14+$AI14),2) -> 0 | AM14: =ROUND(($X14+$AD14+$AJ14),2) -> 0 | AN14: =ROUND(($Y14+$AE14+$AK14),2) -> 0 | AO14: =SUM(AL14:AN14) -> 0 | AR14: =ROUND((S14-AO14-AP14),2) -> 10605.5 | AT14: =ROUND((AR14*$AT$8),2) -> 0 | AY14: =ROUND((AR14-AS14-AT14-AU14-AV14-AW14-AX14),2) -> 10605.5 | AZ14: #REF!
A15: 6 | E15: CUBIL, JOCELYN R. | F15: GH | G15: Administrative Asst. III | H15: 9 | I15: REVOLVING FUND | J15: ok | M15: =IFERROR(VLOOKUP($H15,'CODE 2'!$J:$K,2,FALSE)," ") -> 21211 | N15: =ROUND((M15/2),2) -> 10605.5 | O15: =M15/22 -> 964.13636 | P15: =O15/8 -> 120.51705 | Q15: =P15/60 -> 2.0086174 | R15: 11 | S15: =ROUND((O15*R15),2) -> 10605.5 | W15: =ROUND(($O15*$T15),2) -> 0 | X15: =ROUND(($P15*$U15),2) -> 0 | Y15: =ROUND(($Q15*$V15),2) -> 0 | AC15: =ROUND(($O15*$Z15),2) -> 0 | AD15: =ROUND(($P15*$AA15),2) -> 0 | AE15: =ROUND(($Q15*$AB15),2) -> 0 | AI15: =IFERROR(ROUND(($O15*$AF15),2)," ") -> 0 | AJ15: =IFERROR(ROUND(($P15*$AG15),2),"") -> 0 | AK15: =IFERROR(ROUND(($Q15*$AH15),2),"") -> 0 | AL15: =ROUND(($W15+$AC15+$AI15),2) -> 0 | AM15: =ROUND(($X15+$AD15+$AJ15),2) -> 0 | AN15: =ROUND(($Y15+$AE15+$AK15),2) -> 0 | AO15: =SUM(AL15:AN15) -> 0 | AT15: =ROUND((AR15*$AT$8),2) -> 0 | AZ15: #REF!
A16: 7 | B16: 2026-01-0006 | C16: 46036 | E16: GULTIANO, HELEN D. | F16: GH | G16: Administrative Asst. III | H16: 9 | I16: REVOLVING FUND | J16: ok | M16: =IFERROR(VLOOKUP($H16,'CODE 2'!$J:$K,2,FALSE)," ") -> 21211 | N16: =ROUND((M16/2),2) -> 10605.5 | O16: =M16/22 -> 964.13636 | P16: =O16/8 -> 120.51705 | Q16: =P16/60 -> 2.0086174 | R16: 11 | S16: =ROUND((O16*R16),2) -> 10605.5 | T16: 0 | U16: 0 | V16: 0 | W16: =ROUND(($O16*$T16),2) -> 0 | X16: =ROUND(($P16*$U16),2) -> 0 | Y16: =ROUND(($Q16*$V16),2) -> 0 | AC16: =ROUND(($O16*$Z16),2) -> 0 | AD16: =ROUND(($P16*$AA16),2) -> 0 | AE16: =ROUND(($Q16*$AB16),2) -> 0 | AI16: =IFERROR(ROUND(($O16*$AF16),2)," ") -> 0 | AJ16: =IFERROR(ROUND(($P16*$AG16),2),"") -> 0 | AK16: =IFERROR(ROUND(($Q16*$AH16),2),"") -> 0 | AL16: =ROUND(($W16+$AC16+$AI16),2) -> 0 | AM16: =ROUND(($X16+$AD16+$AJ16),2) -> 0 | AN16: =ROUND(($Y16+$AE16+$AK16),2) -> 0 | AO16: =SUM(AL16:AN16) -> 0 | AR16: =ROUND((S16-AO16-AP16),2) -> 10605.5 | AT16: =ROUND((AR16*$AT$8),2) -> 0 | AY16: =ROUND((AR16-AS16-AT16-AU16-AV16-AW16-AX16),2) -> 10605.5 | AZ16: #REF!
A17: 8 | B17: 2026-01-0007 | C17: 46036 | E17: TORIO, CECIL P. | F17: GH | G17: Administrative Asst. III | H17: 9 | I17: REVOLVING FUND | J17: ok | M17: =IFERROR(VLOOKUP($H17,'CODE 2'!$J:$K,2,FALSE)," ") -> 21211 | N17: =ROUND((M17/2),2) -> 10605.5 | O17: =M17/22 -> 964.13636 | P17: =O17/8 -> 120.51705 | Q17: =P17/60 -> 2.0086174 | R17: 11 | S17: =ROUND((O17*R17),2) -> 10605.5 | T17: 0 | U17: 0 | V17: 45 | W17: =ROUND(($O17*$T17),2) -> 0 | X17: =ROUND(($P17*$U17),2) -> 0 | Y17: =ROUND(($Q17*$V17),2) -> 90.39 | AC17: =ROUND(($O17*$Z17),2) -> 0 | AD17: =ROUND(($P17*$AA17),2) -> 0 | AE17: =ROUND(($Q17*$AB17),2) -> 0 | AI17: =IFERROR(ROUND(($O17*$AF17),2)," ") -> 0 | AJ17: =IFERROR(ROUND(($P17*$AG17),2),"") -> 0 | AK17: =IFERROR(ROUND(($Q17*$AH17),2),"") -> 0 | AL17: =ROUND(($W17+$AC17+$AI17),2) -> 0 | AM17: =ROUND(($X17+$AD17+$AJ17),2) -> 0 | AN17: =ROUND(($Y17+$AE17+$AK17),2) -> 90.39 | AO17: =SUM(AL17:AN17) -> 90.39 | AR17: =ROUND((S17-AO17-AP17),2) -> 10515.11 | AT17: =ROUND((AR17*$AT$8),2) -> 0 | AY17: =ROUND((AR17-AS17-AT17-AU17-AV17-AW17-AX17),2) -> 10515.11 | AZ17: #REF!
A18: 9 | B18: 2026-01-0008 | C18: 46036 | E18: GASATAN, ENRICO JAN S. | F18: GH | G18: Administrative Asst. III (Housekeeping Attendant) | H18: 9 | I18: REVOLVING FUND | J18: ok | M18: =IFERROR(VLOOKUP($H18,'CODE 2'!$J:$K,2,FALSE)," ") -> 21211 | N18: =ROUND((M18/2),2) -> 10605.5 | O18: =M18/22 -> 964.13636 | P18: =O18/8 -> 120.51705 | Q18: =P18/60 -> 2.0086174 | R18: 11 | S18: =ROUND((O18*R18),2) -> 10605.5 | T18: 0 | U18: 0 | V18: 0 | W18: =ROUND(($O18*$T18),2) -> 0 | X18: =ROUND(($P18*$U18),2) -> 0 | Y18: =ROUND(($Q18*$V18),2) -> 0 | AC18: =ROUND(($O18*$Z18),2) -> 0 | AD18: =ROUND(($P18*$AA18),2) -> 0 | AE18: =ROUND(($Q18*$AB18),2) -> 0 | AI18: =IFERROR(ROUND(($O18*$AF18),2)," ") -> 0 | AJ18: =IFERROR(ROUND(($P18*$AG18),2),"") -> 0 | AK18: =IFERROR(ROUND(($Q18*$AH18),2),"") -> 0 | AL18: =ROUND(($W18+$AC18+$AI18),2) -> 0 | AM18: =ROUND(($X18+$AD18+$AJ18),2) -> 0 | AN18: =ROUND(($Y18+$AE18+$AK18),2) -> 0 | AO18: =SUM(AL18:AN18) -> 0 | AR18: =ROUND((S18-AO18-AP18),2) -> 10605.5 | AT18: =ROUND((AR18*$AT$8),2) -> 0 | AY18: =ROUND((AR18-AS18-AT18-AU18-AV18-AW18-AX18),2) -> 10605.5 | AZ18: #REF!
A19: 10 | B19: 2026-01-0004 | C19: 46036 | E19: JARABESE, LUIS E. | F19: GH | G19: Administrative Asst. III | H19: 9 | I19: REVOLVING FUND | J19: ok | M19: =IFERROR(VLOOKUP($H19,'CODE 2'!$J:$K,2,FALSE)," ") -> 21211 | N19: =ROUND((M19/2),2) -> 10605.5 | O19: =M19/22 -> 964.13636 | P19: =O19/8 -> 120.51705 | Q19: =P19/60 -> 2.0086174 | R19: 11 | S19: =ROUND((O19*R19),2) -> 10605.5 | T19: 0 | U19: 0 | V19: 0 | W19: =ROUND(($O19*$T19),2) -> 0 | X19: =ROUND(($P19*$U19),2) -> 0 | Y19: =ROUND(($Q19*$V19),2) -> 0 | AC19: =ROUND(($O19*$Z19),2) -> 0 | AD19: =ROUND(($P19*$AA19),2) -> 0 | AE19: =ROUND(($Q19*$AB19),2) -> 0 | AI19: =IFERROR(ROUND(($O19*$AF19),2)," ") -> 0 | AJ19: =IFERROR(ROUND(($P19*$AG19),2),"") -> 0 | AK19: =IFERROR(ROUND(($Q19*$AH19),2),"") -> 0 | AL19: =ROUND(($W19+$AC19+$AI19),2) -> 0 | AM19: =ROUND(($X19+$AD19+$AJ19),2) -> 0 | AN19: =ROUND(($Y19+$AE19+$AK19),2) -> 0 | AO19: =SUM(AL19:AN19) -> 0 | AR19: =ROUND((S19-AO19-AP19),2) -> 10605.5 | AT19: =ROUND((AR19*$AT$8),2) -> 0 | AY19: =ROUND((AR19-AS19-AT19-AU19-AV19-AW19-AX19),2) -> 10605.5 | AZ19: #REF!
A20: 11 | B20: 2026-01-0011 | C20: 46036 | E20: ACENO, ALYANNA MARIE | F20: GH | G20: Dormitory Manager I | H20: 9 | I20: REVOLVING FUND | J20: ok | M20: =IFERROR(VLOOKUP($H20,'CODE 2'!$J:$K,2,FALSE)," ") -> 21211 | N20: =ROUND((M20/2),2) -> 10605.5 | O20: =M20/22 -> 964.13636 | P20: =O20/8 -> 120.51705 | Q20: =P20/60 -> 2.0086174 | R20: 11 | S20: =ROUND((O20*R20),2) -> 10605.5 | T20: 0 | U20: 0 | V20: 0 | W20: =ROUND(($O20*$T20),2) -> 0 | X20: =ROUND(($P20*$U20),2) -> 0 | Y20: =ROUND(($Q20*$V20),2) -> 0 | AC20: =ROUND(($O20*$Z20),2) -> 0 | AD20: =ROUND(($P20*$AA20),2) -> 0 | AE20: =ROUND(($Q20*$AB20),2) -> 0 | AI20: =IFERROR(ROUND(($O20*$AF20),2)," ") -> 0 | AJ20: =IFERROR(ROUND(($P20*$AG20),2),"") -> 0 | AK20: =IFERROR(ROUND(($Q20*$AH20),2),"") -> 0 | AL20: =ROUND(($W20+$AC20+$AI20),2) -> 0 | AM20: =ROUND(($X20+$AD20+$AJ20),2) -> 0 | AN20: =ROUND(($Y20+$AE20+$AK20),2) -> 0 | AO20: =SUM(AL20:AN20) -> 0 | AR20: =ROUND((S20-AO20-AP20),2) -> 10605.5 | AT20: =ROUND((AR20*$AT$8),2) -> 0 | AY20: =ROUND((AR20-AS20-AT20-AU20-AV20-AW20-AX20),2) -> 10605.5 | AZ20: #REF!
A21: 12 | B21: 2026-01-0003 | C21: 46036 | E21: BERNABE CHERRY MAY E. | F21: GH | G21: Administrative Asst. II (Reliever) | H21: 8 | I21: REVOLVING FUND | J21: ok | M21: =IFERROR(VLOOKUP($H21,'CODE 2'!$J:$K,2,FALSE)," ") -> 19744 | N21: =ROUND((M21/2),2) -> 9872 | O21: =M21/22 -> 897.45455 | P21: =O21/8 -> 112.18182 | Q21: =P21/60 -> 1.869697 | R21: 11 | S21: =ROUND((O21*R21),2) -> 9872 | T21: 0 | U21: 0 | V21: 0 | W21: =ROUND(($O21*$T21),2) -> 0 | X21: =ROUND(($P21*$U21),2) -> 0 | Y21: =ROUND(($Q21*$V21),2) -> 0 | AC21: =ROUND(($O21*$Z21),2) -> 0 | AD21: =ROUND(($P21*$AA21),2) -> 0 | AE21: =ROUND(($Q21*$AB21),2) -> 0 | AI21: =IFERROR(ROUND(($O21*$AF21),2)," ") -> 0 | AJ21: =IFERROR(ROUND(($P21*$AG21),2),"") -> 0 | AK21: =IFERROR(ROUND(($Q21*$AH21),2),"") -> 0 | AL21: =ROUND(($W21+$AC21+$AI21),2) -> 0 | AM21: =ROUND(($X21+$AD21+$AJ21),2) -> 0 | AN21: =ROUND(($Y21+$AE21+$AK21),2) -> 0 | AO21: =SUM(AL21:AN21) -> 0 | AR21: =ROUND((S21-AO21-AP21),2) -> 9872 | AS21: 0 | AT21: 0 | AU21: 0 | AY21: =ROUND((AR21-AS21-AT21-AU21-AV21-AW21-AX21),2) -> 9872 | AZ21: #REF!
A22: 13 | B22: 2026-01-0005 | C22: 46036 | E22: RIVAS, JOSEPH S. | F22: INFRA | G22: Electrician General Forman | H22: 11 | I22: REVOLVING FUND | J22: OK | M22: =IFERROR(VLOOKUP($H22,'CODE 2'!$J:$K,2,FALSE)," ") -> 27000 | N22: =IFERROR(ROUND((M22/2),2),"") -> 13500 | O22: =IFERROR((M22/22)," ") -> 1227.2727 | P22: =IFERROR((O22/8),"") -> 153.40909 | Q22: =IFERROR((P22/60),"") -> 2.5568182 | R22: 11 | S22: =IFERROR(ROUND((O22*R22),2)," ") -> 13500 | T22: 0 | U22: 0 | V22: 3 | W22: =ROUND(($O22*$T22),2) -> 0 | X22: =ROUND(($P22*$U22),2) -> 0 | Y22: =ROUND(($Q22*$V22),2) -> 7.67 | AC22: =ROUND(($O22*$Z22),2) -> 0 | AD22: =ROUND(($P22*$AA22),2) -> 0 | AE22: =ROUND(($Q22*$AB22),2) -> 0 | AL22: =ROUND(($W22+$AC22+$AI22),2) -> 0 | AM22: =ROUND(($X22+$AD22+$AJ22),2) -> 0 | AN22: =ROUND(($Y22+$AE22+$AK22),2) -> 7.67 | AO22: =SUM(AL22:AN22) -> 7.67 | AR22: =ROUND((S22-AO22-AP22),2) -> 13492.33 | AY22: =ROUND((AR22-AS22-AT22-AU22-AV22-AW22-AX22),2) -> 13492.33 | AZ22: #REF!
A23: 14 | B23: 2026-01-0012 | C23: 46036 | E23: ESTAPON, LESLIE DC. | F23: ACCTG. | G23: Administrative Asst. II | H23: 8 | I23: REVOLVING FUND | J23: OK | M23: =IFERROR(VLOOKUP($H23,'CODE 2'!$J:$K,2,FALSE)," ") -> 19744 | N23: =IFERROR(ROUND((M23/2),2),"") -> 9872 | O23: =IFERROR((M23/22)," ") -> 897.45455 | P23: =IFERROR((O23/8),"") -> 112.18182 | Q23: =IFERROR((P23/60),"") -> 1.869697 | R23: 11 | S23: =IFERROR(ROUND((O23*R23),2)," ") -> 9872 | T23: 0 | U23: 0 | V23: 18 | W23: =ROUND(($O23*$T23),2) -> 0 | X23: =ROUND(($P23*$U23),2) -> 0 | Y23: =ROUND(($Q23*$V23),2) -> 33.65 | AC23: =IFERROR(ROUND(($O23*$Z23),2)," ") -> 0 | AD23: =IFERROR(ROUND(($P23*$AA23),2),"") -> 0 | AE23: =IFERROR(ROUND(($Q23*$AB23),2),"") -> 0 | AI23: =IFERROR(ROUND(($O23*$AF23),2)," ") -> 0 | AJ23: =IFERROR(ROUND(($P23*$AG23),2),"") -> 0 | AK23: =IFERROR(ROUND(($Q23*$AH23),2),"") -> 0 | AL23: =IFERROR(ROUND(($W23+$AC23+$AI23),2),"") -> 0 | AM23: =IFERROR(ROUND(($X23+$AD23+$AJ23),2),"") -> 0 | AN23: =IFERROR(ROUND(($Y23+$AE23+$AK23),2),"") -> 33.65 | AO23: =SUM(AL23:AN23) -> 33.65 | AR23: =IFERROR(ROUND((S23-AO23-AP23),2),"") -> 9838.35 | AY23: =IFERROR(ROUND((AR23-AS23-AT23-AU23-AV23-AW23-AX23),2),"") -> 9838.35 | AZ23: Payroll
A24: 15 | B24: 2026-01-0013 | C24: 46036 | E24: LOZANO, ADRIAN D. | F24: ACCTG. | G24: Administrative Asst. II | H24: 8 | I24: REVOLVING FUND | J24: OK | M24: =IFERROR(VLOOKUP($H24,'CODE 2'!$J:$K,2,FALSE)," ") -> 19744 | N24: =IFERROR(ROUND((M24/2),2),"") -> 9872 | O24: =IFERROR((M24/22)," ") -> 897.45455 | P24: =IFERROR((O24/8),"") -> 112.18182 | Q24: =IFERROR((P24/60),"") -> 1.869697 | R24: 11 | S24: =IFERROR(ROUND((O24*R24),2)," ") -> 9872 | T24: 0 | U24: 0 | V24: 5 | W24: =ROUND(($O24*$T24),2) -> 0 | X24: =ROUND(($P24*$U24),2) -> 0 | Y24: =ROUND(($Q24*$V24),2) -> 9.35 | AC24: =IFERROR(ROUND(($O24*$Z24),2)," ") -> 0 | AD24: =IFERROR(ROUND(($P24*$AA24),2),"") -> 0 | AE24: =IFERROR(ROUND(($Q24*$AB24),2),"") -> 0 | AI24: =IFERROR(ROUND(($O24*$AF24),2)," ") -> 0 | AJ24: =IFERROR(ROUND(($P24*$AG24),2),"") -> 0 | AK24: =IFERROR(ROUND(($Q24*$AH24),2),"") -> 0 | AL24: =IFERROR(ROUND(($W24+$AC24+$AI24),2),"") -> 0 | AM24: =IFERROR(ROUND(($X24+$AD24+$AJ24),2),"") -> 0 | AN24: =IFERROR(ROUND(($Y24+$AE24+$AK24),2),"") -> 9.35 | AO24: =SUM(AL24:AN24) -> 9.35 | AR24: =IFERROR(ROUND((S24-AO24-AP24),2),"") -> 9862.65 | AY24: =IFERROR(ROUND((AR24-AS24-AT24-AU24-AV24-AW24-AX24),2),"") -> 9862.65 | AZ24: Payroll
AZ26: #REF!
A27: Total | S27: =SUM(S10:S26) -> 160759 | AL27: =SUM(AL10:AL26) -> 0 | AM27: =SUM(AM10:AM26) -> 0 | AN27: =SUM(AN10:AN26) -> 177.96 | AO27: =SUM(AO10:AO26) -> 177.96 | AP27: =SUM(AP10:AP26) -> 0 | AR27: =SUM(AR10:AR26) -> 139370.04 | AS27: =SUM(AS10:AS26) -> 0 | AT27: =SUM(AT10:AT26) -> 0 | AU27: =SUM(AU10:AU26) -> 0 | AV27: =SUM(AV10:AV26) -> 0 | AW27: =SUM(AW10:AW26) -> 0 | AX27: =SUM(AX10:AX26) -> 0 | AY27: =SUM(AY10:AY26) -> 139370.04

Sheet GENERAL PAYROLL
B9: GENERAL PAYROLL
B11: Prepared by: Jonalyn T. Tolero
B13: We hereby acknowledge to have received from Valentina S. Cagumbay, Admin. Officer III, the sums herein specified opposite our respective names, being in full compensation of our
B14: services for the period of February 16-28, 2026
A15: Name | C15: Position | D15: Office | E15: Number of Days
F16: Salary per Day | G16: Half Month Salary | H16: Less | K16: Less | N16: Less | R16: add/less | S16: GROSS AMOUNT | T16: Less | V16: Less | Z16: Total Net Received
H17: Absences | I17: Late/UT | J17: =H17&"/"&I17 -> Absences/Late/UT | K17: Absences | L17: Late/UT | M17: Absences/Late/UT | N17: Absences | O17: Late/UT | P17: Absences/Late/UT | Q17: Total Absences/Late/UT | R17: Other Adjustment (Clothing - ATIEA Deductions) | T17: Withholding Tax | V17: Accommodation for the Month of | W17: Water | X17: Electric | Y17: Repairs
H18: February 1-15, 2026 | J18: =H18 -> February 1-15, 2026 | K18: February 16-28, 2026 | M18: =K18 -> February 16-28, 2026 | P18: =N18 | T18: 0.02 | U18: 0.03
A20: =IF(B20="","",COUNTA($B$20:B20)) -> 1 | B20: ALBOROTO, JANET P. | C20: Administrative Asst. III | D20: GH | E20: 11 | F20: =VLOOKUP($B20,'MASTER DATA '!$E:$O,11,FALSE) -> 964.13636 | G20: =VLOOKUP($B20,'MASTER DATA '!$E:$N,10,FALSE) -> 10605.5 | H20: =SUMIF('MASTER DATA '!$E:$E,$B20,'MASTER DATA '!$W:$W) -> 0 | I20: =SUMIF('MASTER DATA '!$E:$E,$B20,'MASTER DATA '!$X:$X)+SUMIF('MASTER DATA '!$E:$E,$B20,'MASTER DATA '!$Y:$Y) -> 0 | J20: =SUM(H20:I20) -> 0 | K20: =SUMIF('MASTER DATA '!$E:$E,$B20,'MASTER DATA '!$AC:$AC) -> 0 | L20: =SUMIF('MASTER DATA '!$E:$E,$B20,'MASTER DATA '!$AD:$AD)+SUMIF('MASTER DATA '!$E:$E,$B20,'MASTER DATA '!$AE:$AE) -> 0 | M20: =SUM(K20:L20) -> 0 | N20: =SUMIF('MASTER DATA '!$E:$E,$B20,'MASTER DATA '!$AI:$AI) -> 0 | O20: =SUMIF('MASTER DATA '!$E:$E,$B20,'MASTER DATA '!$AJ:$AJ)+SUMIF('MASTER DATA '!$E:$E,$B20,'MASTER DATA '!$AK:$AK) -> 0 | P20: =SUM(N20:O20) -> 0 | Q20: =SUMIF('MASTER DATA '!$E:$E,$B20,'MASTER DATA '!$AO:$AO) -> 0 | R20: =SUMIF('MASTER DATA '!$E:$E,$B20,'MASTER DATA '!$AP:$AP) -> 0 | S20: =SUMIF('MASTER DATA '!$E:$E,$B20,'MASTER DATA '!$AR:$AR) -> 10605.5 | T20: =SUMIF('MASTER DATA '!$E:$E,$B20,'MASTER DATA '!$AS:$AS) -> 0 | U20: =SUMIF('MASTER DATA '!$E:$E,$B20,'MASTER DATA '!$AT:$AT) -> 0 | V20: =SUMIF('MASTER DATA '!$E:$E,$B20,'MASTER DATA '!$AU:$AU) -> 0 | W20: =SUMIF('MASTER DATA '!$E:$E,$B20,'MASTER DATA '!$AV:$AV) -> 0 | X20: =SUMIF('MASTER DATA '!$E:$E,$B20,'MASTER DATA '!$AW:$AW) -> 0 | Y20: =SUMIF('MASTER DATA '!$E:$E,$B20,'MASTER DATA '!$AX:$AX) -> 0 | Z20: =SUMIF('MASTER DATA '!$E:$E,$B20,'MASTER DATA '!$AY:$AY) -> 10605.5 | AA20: =IF(B20>=1,"SHOW","HIDE") -> SHOW
A21: =IF(B21="","",COUNTA($B$20:B21)) -> 2 | B21: ARENAS, DIANA ROSE A. | C21: Administrative Asst. IV (Dormitory Assistant) | D21: GH | E21: 11 | F21: =VLOOKUP($B21,'MASTER DATA '!$E:$O,11,FALSE) -> 1053.4545 | G21: =VLOOKUP($B21,'MASTER DATA '!$E:$N,10,FALSE) -> 11588 | H21: =SUMIF('MASTER DATA '!$E:$E,$B21,'MASTER DATA '!$W:$W) -> 0 | I21: =SUMIF('MASTER DATA '!$E:$E,$B21,'MASTER DATA '!$X:$X)+SUMIF('MASTER DATA '!$E:$E,$B21,'MASTER DATA '!$Y:$Y) -> 8.78 | J21: =SUM(H21:I21) -> 8.78 | K21: =SUMIF('MASTER DATA '!$E:$E,$B21,'MASTER DATA '!$AC:$AC) -> 0 | L21: =SUMIF('MASTER DATA '!$E:$E,$B21,'MASTER DATA '!$AD:$AD)+SUMIF('MASTER DATA '!$E:$E,$B21,'MASTER DATA '!$AE:$AE) -> 0 | M21: =SUM(K21:L21) -> 0 | N21: =SUMIF('MASTER DATA '!$E:$E,$B21,'MASTER DATA '!$AI:$AI) -> 0 | O21: =SUMIF('MASTER DATA '!$E:$E,$B21,'MASTER DATA '!$AJ:$AJ)+SUMIF('MASTER DATA '!$E:$E,$B21,'MASTER DATA '!$AK:$AK) -> 0 | P21: =SUM(N21:O21) -> 0 | Q21: =SUMIF('MASTER DATA '!$E:$E,$B21,'MASTER DATA '!$AO:$AO) -> 8.78 | R21: =SUMIF('MASTER DATA '!$E:$E,$B21,'MASTER DATA '!$AP:$AP) -> 0 | S21: =SUMIF('MASTER DATA '!$E:$E,$B21,'MASTER DATA '!$AR:$AR) -> 11579.22 | T21: =SUMIF('MASTER DATA '!$E:$E,$B21,'MASTER DATA '!$AS:$AS) -> 0 | U21: =SUMIF('MASTER DATA '!$E:$E,$B21,'MASTER DATA '!$AT:$AT) -> 0 | V21: =SUMIF('MASTER DATA '!$E:$E,$B21,'MASTER DATA '!$AU:$AU) -> 0 | W21: =SUMIF('MASTER DATA '!$E:$E,$B21,'MASTER DATA '!$AV:$AV) -> 0 | X21: =SUMIF('MASTER DATA '!$E:$E,$B21,'MASTER DATA '!$AW:$AW) -> 0 | Y21: =SUMIF('MASTER DATA '!$E:$E,$B21,'MASTER DATA '!$AX:$AX) -> 0 | Z21: =SUMIF('MASTER DATA '!$E:$E,$B21,'MASTER DATA '!$AY:$AY) -> 11579.22 | AA21: =IF(B21>=1,"SHOW","HIDE") -> SHOW
A22: =IF(B22="","",COUNTA($B$20:B22)) -> 3 | B22: BERNABE, JOHN MICHAEL A. | C22: Administrative Asst. III | D22: GH | E22: 11 | F22: =VLOOKUP($B22,'MASTER DATA '!$E:$O,11,FALSE) -> 964.13636 | G22: =VLOOKUP($B22,'MASTER DATA '!$E:$N,10,FALSE) -> 10605.5 | H22: =SUMIF('MASTER DATA '!$E:$E,$B22,'MASTER DATA '!$W:$W) -> 0 | I22: =SUMIF('MASTER DATA '!$E:$E,$B22,'MASTER DATA '!$X:$X)+SUMIF('MASTER DATA '!$E:$E,$B22,'MASTER DATA '!$Y:$Y) -> 0 | J22: =SUM(H22:I22) -> 0 | K22: =SUMIF('MASTER DATA '!$E:$E,$B22,'MASTER DATA '!$AC:$AC) -> 0 | L22: =SUMIF('MASTER DATA '!$E:$E,$B22,'MASTER DATA '!$AD:$AD)+SUMIF('MASTER DATA '!$E:$E,$B22,'MASTER DATA '!$AE:$AE) -> 0 | M22: =SUM(K22:L22) -> 0 | N22: =SUMIF('MASTER DATA '!$E:$E,$B22,'MASTER DATA '!$AI:$AI) -> 0 | O22: =SUMIF('MASTER DATA '!$E:$E,$B22,'MASTER DATA '!$AJ:$AJ)+SUMIF('MASTER DATA '!$E:$E,$B22,'MASTER DATA '!$AK:$AK) -> 0 | P22: =SUM(N22:O22) -> 0 | Q22: =SUMIF('MASTER DATA '!$E:$E,$B22,'MASTER DATA '!$AO:$AO) -> 0 | R22: =SUMIF('MASTER DATA '!$E:$E,$B22,'MASTER DATA '!$AP:$AP) -> 0 | S22: =SUMIF('MASTER DATA '!$E:$E,$B22,'MASTER DATA '!$AR:$AR) -> 0 | T22: =SUMIF('MASTER DATA '!$E:$E,$B22,'MASTER DATA '!$AS:$AS) -> 0 | U22: =SUMIF('MASTER DATA '!$E:$E,$B22,'MASTER DATA '!$AT:$AT) -> 0 | V22: =SUMIF('MASTER DATA '!$E:$E,$B22,'MASTER DATA '!$AU:$AU) -> 0 | W22: =SUMIF('MASTER DATA '!$E:$E,$B22,'MASTER DATA '!$AV:$AV) -> 0 | X22: =SUMIF('MASTER DATA '!$E:$E,$B22,'MASTER DATA '!$AW:$AW) -> 0 | Y22: =SUMIF('MASTER DATA '!$E:$E,$B22,'MASTER DATA '!$AX:$AX) -> 0 | Z22: =SUMIF('MASTER DATA '!$E:$E,$B22,'MASTER DATA '!$AY:$AY) -> 0 | AA22: =IF(B22>=1,"SHOW","HIDE") -> SHOW
A23: =IF(B23="","",COUNTA($B$20:B23)) -> 4 | B23: CANNU JR, ALFREDO O. | C23: Administrative Asst. III (Housekeeping Attendant) | D23: GH | E23: 11 | F23: =VLOOKUP($B23,'MASTER DATA '!$E:$O,11,FALSE) -> 964.13636 | G23: =VLOOKUP($B23,'MASTER DATA '!$E:$N,10,FALSE) -> 10605.5 | H23: =SUMIF('MASTER DATA '!$E:$E,$B23,'MASTER DATA '!$W:$W) -> 0 | I23: =SUMIF('MASTER DATA '!$E:$E,$B23,'MASTER DATA '!$X:$X)+SUMIF('MASTER DATA '!$E:$E,$B23,'MASTER DATA '!$Y:$Y) -> 28.12 | J23: =SUM(H23:I23) -> 28.12 | K23: =SUMIF('MASTER DATA '!$E:$E,$B23,'MASTER DATA '!$AC:$AC) -> 0 | L23: =SUMIF('MASTER DATA '!$E:$E,$B23,'MASTER DATA '!$AD:$AD)+SUMIF('MASTER DATA '!$E:$E,$B23,'MASTER DATA '!$AE:$AE) -> 0 | M23: =SUM(K23:L23) -> 0 | N23: =SUMIF('MASTER DATA '!$E:$E,$B23,'MASTER DATA '!$AI:$AI) -> 0 | O23: =SUMIF('MASTER DATA '!$E:$E,$B23,'MASTER DATA '!$AJ:$AJ)+SUMIF('MASTER DATA '!$E:$E,$B23,'MASTER DATA '!$AK:$AK) -> 0 | P23: =SUM(N23:O23) -> 0 | Q23: =SUMIF('MASTER DATA '!$E:$E,$B23,'MASTER DATA '!$AO:$AO) -> 28.12 | R23: =SUMIF('MASTER DATA '!$E:$E,$B23,'MASTER DATA '!$AP:$AP) -> 0 | S23: =SUMIF('MASTER DATA '!$E:$E,$B23,'MASTER DATA '!$AR:$AR) -> 10577.38 | T23: =SUMIF('MASTER DATA '!$E:$E,$B23,'MASTER DATA '!$AS:$AS) -> 0 | U23: =SUMIF('MASTER DATA '!$E:$E,$B23,'MASTER DATA '!$AT:$AT) -> 0 | V23: =SUMIF('MASTER DATA '!$E:$E,$B23,'MASTER DATA '!$AU:$AU) -> 0 | W23: =SUMIF('MASTER DATA '!$E:$E,$B23,'MASTER DATA '!$AV:$AV) -> 0 | X23: =SUMIF('MASTER DATA '!$E:$E,$B23,'MASTER DATA '!$AW:$AW) -> 0 | Y23: =SUMIF('MASTER DATA '!$E:$E,$B23,'MASTER DATA '!$AX:$AX) -> 0 | Z23: =SUMIF('MASTER DATA '!$E:$E,$B23,'MASTER DATA '!$AY:$AY) -> 10577.38 | AA23: =IF(B23>=1,"SHOW","HIDE") -> SHOW
A24: =IF(B24="","",COUNTA($B$20:B24)) -> 5 | B24: CELOCIA, MERLITA O. | C24: Administrative Asst. III | D24: GH | E24: 11 | F24: =VLOOKUP($B24,'MASTER DATA '!$E:$O,11,FALSE) -> 964.13636 | G24: =VLOOKUP($B24,'MASTER DATA '!$E:$N,10,FALSE) -> 10605.5 | H24: =SUMIF('MASTER DATA '!$E:$E,$B24,'MASTER DATA '!$W:$W) -> 0 | I24: =SUMIF('MASTER DATA '!$E:$E,$B24,'MASTER DATA '!$X:$X)+SUMIF('MASTER DATA '!$E:$E,$B24,'MASTER DATA '!$Y:$Y) -> 0 | J24: =SUM(H24:I24) -> 0 | K24: =SUMIF('MASTER DATA '!$E:$E,$B24,'MASTER DATA '!$AC:$AC) -> 0 | L24: =SUMIF('MASTER DATA '!$E:$E,$B24,'MASTER DATA '!$AD:$AD)+SUMIF('MASTER DATA '!$E:$E,$B24,'MASTER DATA '!$AE:$AE) -> 0 | M24: =SUM(K24:L24) -> 0 | N24: =SUMIF('MASTER DATA '!$E:$E,$B24,'MASTER DATA '!$AI:$AI) -> 0 | O24: =SUMIF('MASTER DATA '!$E:$E,$B24,'MASTER DATA '!$AJ:$AJ)+SUMIF('MASTER DATA '!$E:$E,$B24,'MASTER DATA '!$AK:$AK) -> 0 | P24: =SUM(N24:O24) -> 0 | Q24: =SUMIF('MASTER DATA '!$E:$E,$B24,'MASTER DATA '!$AO:$AO) -> 0 | R24: =SUMIF('MASTER DATA '!$E:$E,$B24,'MASTER DATA '!$AP:$AP) -> 0 | S24: =SUMIF('MASTER DATA '!$E:$E,$B24,'MASTER DATA '!$AR:$AR) -> 10605.5 | T24: =SUMIF('MASTER DATA '!$E:$E,$B24,'MASTER DATA '!$AS:$AS) -> 0 | U24: =SUMIF('MASTER DATA '!$E:$E,$B24,'MASTER DATA '!$AT:$AT) -> 0 | V24: =SUMIF('MASTER DATA '!$E:$E,$B24,'MASTER DATA '!$AU:$AU) -> 0 | W24: =SUMIF('MASTER DATA '!$E:$E,$B24,'MASTER DATA '!$AV:$AV) -> 0 | X24: =SUMIF('MASTER DATA '!$E:$E,$B24,'MASTER DATA '!$AW:$AW) -> 0 | Y24: =SUMIF('MASTER DATA '!$E:$E,$B24,'MASTER DATA '!$AX:$AX) -> 0 | Z24: =SUMIF('MASTER DATA '!$E:$E,$B24,'MASTER DATA '!$AY:$AY) -> 10605.5 | AA24: =IF(B24>=1,"SHOW","HIDE") -> SHOW
A25: =IF(B25="","",COUNTA($B$20:B25)) -> 6 | B25: CUBIL, JOCELYN R. | C25: Administrative Asst. III | D25: GH | E25: 11 | F25: =VLOOKUP($B25,'MASTER DATA '!$E:$O,11,FALSE) -> 964.13636 | G25: =VLOOKUP($B25,'MASTER DATA '!$E:$N,10,FALSE) -> 10605.5 | H25: =SUMIF('MASTER DATA '!$E:$E,$B25,'MASTER DATA '!$W:$W) -> 0 | I25: =SUMIF('MASTER DATA '!$E:$E,$B25,'MASTER DATA '!$X:$X)+SUMIF('MASTER DATA '!$E:$E,$B25,'MASTER DATA '!$Y:$Y) -> 0 | J25: =SUM(H25:I25) -> 0 | K25: =SUMIF('MASTER DATA '!$E:$E,$B25,'MASTER DATA '!$AC:$AC) -> 0 | L25: =SUMIF('MASTER DATA '!$E:$E,$B25,'MASTER DATA '!$AD:$AD)+SUMIF('MASTER DATA '!$E:$E,$B25,'MASTER DATA '!$AE:$AE) -> 0 | M25: =SUM(K25:L25) -> 0 | N25: =SUMIF('MASTER DATA '!$E:$E,$B25,'MASTER DATA '!$AI:$AI) -> 0 | O25: =SUMIF('MASTER DATA '!$E:$E,$B25,'MASTER DATA '!$AJ:$AJ)+SUMIF('MASTER DATA '!$E:$E,$B25,'MASTER DATA '!$AK:$AK) -> 0 | P25: =SUM(N25:O25) -> 0 | Q25: =SUMIF('MASTER DATA '!$E:$E,$B25,'MASTER DATA '!$AO:$AO) -> 0 | R25: =SUMIF('MASTER DATA '!$E:$E,$B25,'MASTER DATA '!$AP:$AP) -> 0 | S25: =SUMIF('MASTER DATA '!$E:$E,$B25,'MASTER DATA '!$AR:$AR) -> 0 | T25: =SUMIF('MASTER DATA '!$E:$E,$B25,'MASTER DATA '!$AS:$AS) -> 0 | U25: =SUMIF('MASTER DATA '!$E:$E,$B25,'MASTER DATA '!$AT:$AT) -> 0 | V25: =SUMIF('MASTER DATA '!$E:$E,$B25,'MASTER DATA '!$AU:$AU) -> 0 | W25: =SUMIF('MASTER DATA '!$E:$E,$B25,'MASTER DATA '!$AV:$AV) -> 0 | X25: =SUMIF('MASTER DATA '!$E:$E,$B25,'MASTER DATA '!$AW:$AW) -> 0 | Y25: =SUMIF('MASTER DATA '!$E:$E,$B25,'MASTER DATA '!$AX:$AX) -> 0 | Z25: =SUMIF('MASTER DATA '!$E:$E,$B25,'MASTER DATA '!$AY:$AY) -> 0 | AA25: =IF(B25>=1,"SHOW","HIDE") -> SHOW
A26: =IF(B26="","",COUNTA($B$20:B26)) -> 7 | B26: GULTIANO, HELEN D. | C26: Administrative Asst. III | D26: GH | E26: 11 | F26: =VLOOKUP($B26,'MASTER DATA '!$E:$O,11,FALSE) -> 964.13636 | G26: =VLOOKUP($B26,'MASTER DATA '!$E:$N,10,FALSE) -> 10605.5 | H26: =SUMIF('MASTER DATA '!$E:$E,$B26,'MASTER DATA '!$W:$W) -> 0 | I26: =SUMIF('MASTER DATA '!$E:$E,$B26,'MASTER DATA '!$X:$X)+SUMIF('MASTER DATA '!$E:$E,$B26,'MASTER DATA '!$Y:$Y) -> 0 | J26: =SUM(H26:I26) -> 0 | K26: =SUMIF('MASTER DATA '!$E:$E,$B26,'MASTER DATA '!$AC:$AC) -> 0 | L26: =SUMIF('MASTER DATA '!$E:$E,$B26,'MASTER DATA '!$AD:$AD)+SUMIF('MASTER DATA '!$E:$E,$B26,'MASTER DATA '!$AE:$AE) -> 0 | M26: =SUM(K26:L26) -> 0 | N26: =SUMIF('MASTER DATA '!$E:$E,$B26,'MASTER DATA '!$AI:$AI) -> 0 | O26: =SUMIF('MASTER DATA '!$E:$E,$B26,'MASTER DATA '!$AJ:$AJ)+SUMIF('MASTER DATA '!$E:$E,$B26,'MASTER DATA '!$AK:$AK) -> 0 | P26: =SUM(N26:O26) -> 0 | Q26: =SUMIF('MASTER DATA '!$E:$E,$B26,'MASTER DATA '!$AO:$AO) -> 0 | R26: =SUMIF('MASTER DATA '!$E:$E,$B26,'MASTER DATA '!$AP:$AP) -> 0 | S26: =SUMIF('MASTER DATA '!$E:$E,$B26,'MASTER DATA '!$AR:$AR) -> 10605.5 | T26: =SUMIF('MASTER DATA '!$E:$E,$B26,'MASTER DATA '!$AS:$AS) -> 0 | U26: =SUMIF('MASTER DATA '!$E:$E,$B26,'MASTER DATA '!$AT:$AT) -> 0 | V26: =SUMIF('MASTER DATA '!$E:$E,$B26,'MASTER DATA '!$AU:$AU) -> 0 | W26: =SUMIF('MASTER DATA '!$E:$E,$B26,'MASTER DATA '!$AV:$AV) -> 0 | X26: =SUMIF('MASTER DATA '!$E:$E,$B26,'MASTER DATA '!$AW:$AW) -> 0 | Y26: =SUMIF('MASTER DATA '!$E:$E,$B26,'MASTER DATA '!$AX:$AX) -> 0 | Z26: =SUMIF('MASTER DATA '!$E:$E,$B26,'MASTER DATA '!$AY:$AY) -> 10605.5 | AA26: =IF(B26>=1,"SHOW","HIDE") -> SHOW
A27: =IF(B27="","",COUNTA($B$20:B27)) -> 8 | B27: TORIO, CECIL P. | C27: Administrative Asst. III | D27: GH | E27: 11 | F27: =VLOOKUP($B27,'MASTER DATA '!$E:$O,11,FALSE) -> 964.13636 | G27: =VLOOKUP($B27,'MASTER DATA '!$E:$N,10,FALSE) -> 10605.5 | H27: =SUMIF('MASTER DATA '!$E:$E,$B27,'MASTER DATA '!$W:$W) -> 0 | I27: =SUMIF('MASTER DATA '!$E:$E,$B27,'MASTER DATA '!$X:$X)+SUMIF('MASTER DATA '!$E:$E,$B27,'MASTER DATA '!$Y:$Y) -> 90.39 | J27: =SUM(H27:I27) -> 90.39 | K27: =SUMIF('MASTER DATA '!$E:$E,$B27,'MASTER DATA '!$AC:$AC) -> 0 | L27: =SUMIF('MASTER DATA '!$E:$E,$B27,'MASTER DATA '!$AD:$AD)+SUMIF('MASTER DATA '!$E:$E,$B27,'MASTER DATA '!$AE:$AE) -> 0 | M27: =SUM(K27:L27) -> 0 | N27: =SUMIF('MASTER DATA '!$E:$E,$B27,'MASTER DATA '!$AI:$AI) -> 0 | O27: =SUMIF('MASTER DATA '!$E:$E,$B27,'MASTER DATA '!$AJ:$AJ)+SUMIF('MASTER DATA '!$E:$E,$B27,'MASTER DATA '!$AK:$AK) -> 0 | P27: =SUM(N27:O27) -> 0 | Q27: =SUMIF('MASTER DATA '!$E:$E,$B27,'MASTER DATA '!$AO:$AO) -> 90.39 | R27: =SUMIF('MASTER DATA '!$E:$E,$B27,'MASTER DATA '!$AP:$AP) -> 0 | S27: =SUMIF('MASTER DATA '!$E:$E,$B27,'MASTER DATA '!$AR:$AR) -> 10515.11 | T27: =SUMIF('MASTER DATA '!$E:$E,$B27,'MASTER DATA '!$AS:$AS) -> 0 | U27: =SUMIF('MASTER DATA '!$E:$E,$B27,'MASTER DATA '!$AT:$AT) -> 0 | V27: =SUMIF('MASTER DATA '!$E:$E,$B27,'MASTER DATA '!$AU:$AU) -> 0 | W27: =SUMIF('MASTER DATA '!$E:$E,$B27,'MASTER DATA '!$AV:$AV) -> 0 | X27: =SUMIF('MASTER DATA '!$E:$E,$B27,'MASTER DATA '!$AW:$AW) -> 0 | Y27: =SUMIF('MASTER DATA '!$E:$E,$B27,'MASTER DATA '!$AX:$AX) -> 0 | Z27: =SUMIF('MASTER DATA '!$E:$E,$B27,'MASTER DATA '!$AY:$AY) -> 10515.11 | AA27: =IF(B27>=1,"SHOW","HIDE") -> SHOW
A28: =IF(B28="","",COUNTA($B$20:B28)) -> 9 | B28: GASATAN, ENRICO JAN S. | C28: Administrative Asst. III (Housekeeping Attendant) | D28: GH | E28: 11 | F28: =VLOOKUP($B28,'MASTER DATA '!$E:$O,11,FALSE) -> 964.13636 | G28: =VLOOKUP($B28,'MASTER DATA '!$E:$N,10,FALSE) -> 10605.5 | H28: =SUMIF('MASTER DATA '!$E:$E,$B28,'MASTER DATA '!$W:$W) -> 0 | I28: =SUMIF('MASTER DATA '!$E:$E,$B28,'MASTER DATA '!$X:$X)+SUMIF('MASTER DATA '!$E:$E,$B28,'MASTER DATA '!$Y:$Y) -> 0 | J28: =SUM(H28:I28) -> 0 | K28: =SUMIF('MASTER DATA '!$E:$E,$B28,'MASTER DATA '!$AC:$AC) -> 0 | L28: =SUMIF('MASTER DATA '!$E:$E,$B28,'MASTER DATA '!$AD:$AD)+SUMIF('MASTER DATA '!$E:$E,$B28,'MASTER DATA '!$AE:$AE) -> 0 | M28: =SUM(K28:L28) -> 0 | N28: =SUMIF('MASTER DATA '!$E:$E,$B28,'MASTER DATA '!$AI:$AI) -> 0 | O28: =SUMIF('MASTER DATA '!$E:$E,$B28,'MASTER DATA '!$AJ:$AJ)+SUMIF('MASTER DATA '!$E:$E,$B28,'MASTER DATA '!$AK:$AK) -> 0 | P28: =SUM(N28:O28) -> 0 | Q28: =SUMIF('MASTER DATA '!$E:$E,$B28,'MASTER DATA '!$AO:$AO) -> 0 | R28: =SUMIF('MASTER DATA '!$E:$E,$B28,'MASTER DATA '!$AP:$AP) -> 0 | S28: =SUMIF('MASTER DATA '!$E:$E,$B28,'MASTER DATA '!$AR:$AR) -> 10605.5 | T28: =SUMIF('MASTER DATA '!$E:$E,$B28,'MASTER DATA '!$AS:$AS) -> 0 | U28: =SUMIF('MASTER DATA '!$E:$E,$B28,'MASTER DATA '!$AT:$AT) -> 0 | V28: =SUMIF('MASTER DATA '!$E:$E,$B28,'MASTER DATA '!$AU:$AU) -> 0 | W28: =SUMIF('MASTER DATA '!$E:$E,$B28,'MASTER DATA '!$AV:$AV) -> 0 | X28: =SUMIF('MASTER DATA '!$E:$E,$B28,'MASTER DATA '!$AW:$AW) -> 0 | Y28: =SUMIF('MASTER DATA '!$E:$E,$B28,'MASTER DATA '!$AX:$AX) -> 0 | Z28: =SUMIF('MASTER DATA '!$E:$E,$B28,'MASTER DATA '!$AY:$AY) -> 10605.5 | AA28: =IF(B28>=1,"SHOW","HIDE") -> SHOW
A29: =IF(B29="","",COUNTA($B$20:B29)) -> 10 | B29: JARABESE, LUIS E. | C29: Administrative Asst. II | D29: GH | E29: 11 | F29: =VLOOKUP($B29,'MASTER DATA '!$E:$O,11,FALSE) -> 964.13636 | G29: =VLOOKUP($B29,'MASTER DATA '!$E:$N,10,FALSE) -> 10605.5 | H29: =SUMIF('MASTER DATA '!$E:$E,$B29,'MASTER DATA '!$W:$W) -> 0 | I29: =SUMIF('MASTER DATA '!$E:$E,$B29,'MASTER DATA '!$X:$X)+SUMIF('MASTER DATA '!$E:$E,$B29,'MASTER DATA '!$Y:$Y) -> 0 | J29: =SUM(H29:I29) -> 0 | K29: =SUMIF('MASTER DATA '!$E:$E,$B29,'MASTER DATA '!$AC:$AC) -> 0 | L29: =SUMIF('MASTER DATA '!$E:$E,$B29,'MASTER DATA '!$AD:$AD)+SUMIF('MASTER DATA '!$E:$E,$B29,'MASTER DATA '!$AE:$AE) -> 0 | M29: =SUM(K29:L29) -> 0 | N29: =SUMIF('MASTER DATA '!$E:$E,$B29,'MASTER DATA '!$AI:$AI) -> 0 | O29: =SUMIF('MASTER DATA '!$E:$E,$B29,'MASTER DATA '!$AJ:$AJ)+SUMIF('MASTER DATA '!$E:$E,$B29,'MASTER DATA '!$AK:$AK) -> 0 | P29: =SUM(N29:O29) -> 0 | Q29: =SUMIF('MASTER DATA '!$E:$E,$B29,'MASTER DATA '!$AO:$AO) -> 0 | R29: =SUMIF('MASTER DATA '!$E:$E,$B29,'MASTER DATA '!$AP:$AP) -> 0 | S29: =SUMIF('MASTER DATA '!$E:$E,$B29,'MASTER DATA '!$AR:$AR) -> 10605.5 | T29: =SUMIF('MASTER DATA '!$E:$E,$B29,'MASTER DATA '!$AS:$AS) -> 0 | U29: =SUMIF('MASTER DATA '!$E:$E,$B29,'MASTER DATA '!$AT:$AT) -> 0 | V29: =SUMIF('MASTER DATA '!$E:$E,$B29,'MASTER DATA '!$AU:$AU) -> 0 | W29: =SUMIF('MASTER DATA '!$E:$E,$B29,'MASTER DATA '!$AV:$AV) -> 0 | X29: =SUMIF('MASTER DATA '!$E:$E,$B29,'MASTER DATA '!$AW:$AW) -> 0 | Y29: =SUMIF('MASTER DATA '!$E:$E,$B29,'MASTER DATA '!$AX:$AX) -> 0 | Z29: =SUMIF('MASTER DATA '!$E:$E,$B29,'MASTER DATA '!$AY:$AY) -> 10605.5 | AA29: =IF(B29>=1,"SHOW","HIDE") -> SHOW
A30: =IF(B30="","",COUNTA($B$20:B30)) -> 11 | B30: ACENO, ALYANNA MARIE | C30: Dormitory Manager I | D30: GH | E30: 11 | F30: =VLOOKUP($B30,'MASTER DATA '!$E:$O,11,FALSE) -> 964.13636 | G30: =VLOOKUP($B30,'MASTER DATA '!$E:$N,10,FALSE) -> 10605.5 | H30: =SUMIF('MASTER DATA '!$E:$E,$B30,'MASTER DATA '!$W:$W) -> 0 | I30: =SUMIF('MASTER DATA '!$E:$E,$B30,'MASTER DATA '!$X:$X)+SUMIF('MASTER DATA '!$E:$E,$B30,'MASTER DATA '!$Y:$Y) -> 0 | J30: =SUM(H30:I30) -> 0 | K30: =SUMIF('MASTER DATA '!$E:$E,$B30,'MASTER DATA '!$AC:$AC) -> 0 | L30: =SUMIF('MASTER DATA '!$E:$E,$B30,'MASTER DATA '!$AD:$AD)+SUMIF('MASTER DATA '!$E:$E,$B30,'MASTER DATA '!$AE:$AE) -> 0 | M30: =SUM(K30:L30) -> 0 | N30: =SUMIF('MASTER DATA '!$E:$E,$B30,'MASTER DATA '!$AI:$AI) -> 0 | O30: =SUMIF('MASTER DATA '!$E:$E,$B30,'MASTER DATA '!$AJ:$AJ)+SUMIF('MASTER DATA '!$E:$E,$B30,'MASTER DATA '!$AK:$AK) -> 0 | P30: =SUM(N30:O30) -> 0 | Q30: =SUMIF('MASTER DATA '!$E:$E,$B30,'MASTER DATA '!$AO:$AO) -> 0 | R30: =SUMIF('MASTER DATA '!$E:$E,$B30,'MASTER DATA '!$AP:$AP) -> 0 | S30: =SUMIF('MASTER DATA '!$E:$E,$B30,'MASTER DATA '!$AR:$AR) -> 10605.5 | T30: =SUMIF('MASTER DATA '!$E:$E,$B30,'MASTER DATA '!$AS:$AS) -> 0 | U30: =SUMIF('MASTER DATA '!$E:$E,$B30,'MASTER DATA '!$AT:$AT) -> 0 | V30: =SUMIF('MASTER DATA '!$E:$E,$B30,'MASTER DATA '!$AU:$AU) -> 0 | W30: =SUMIF('MASTER DATA '!$E:$E,$B30,'MASTER DATA '!$AV:$AV) -> 0 | X30: =SUMIF('MASTER DATA '!$E:$E,$B30,'MASTER DATA '!$AW:$AW) -> 0 | Y30: =SUMIF('MASTER DATA '!$E:$E,$B30,'MASTER DATA '!$AX:$AX) -> 0 | Z30: =SUMIF('MASTER DATA '!$E:$E,$B30,'MASTER DATA '!$AY:$AY) -> 10605.5 | AA30: =IF(B30>=1,"SHOW","HIDE") -> SHOW
A31: =IF(B31="","",COUNTA($B$20:B31)) -> 12 | B31: BERNABE CHERRY MAY E. | C31: Administrative Asst. II | D31: GH | E31: 11 | F31: =VLOOKUP($B31,'MASTER DATA '!$E:$O,11,FALSE) -> 897.45455 | G31: =VLOOKUP($B31,'MASTER DATA '!$E:$N,10,FALSE) -> 9872 | H31: =SUMIF('MASTER DATA '!$E:$E,$B31,'MASTER DATA '!$W:$W) -> 0 | I31: =SUMIF('MASTER DATA '!$E:$E,$B31,'MASTER DATA '!$X:$X)+SUMIF('MASTER DATA '!$E:$E,$B31,'MASTER DATA '!$Y:$Y) -> 0 | J31: =SUM(H31:I31) -> 0 | K31: =SUMIF('MASTER DATA '!$E:$E,$B31,'MASTER DATA '!$AC:$AC) -> 0 | L31: =SUMIF('MASTER DATA '!$E:$E,$B31,'MASTER DATA '!$AD:$AD)+SUMIF('MASTER DATA '!$E:$E,$B31,'MASTER DATA '!$AE:$AE) -> 0 | M31: =SUM(K31:L31) -> 0 | N31: =SUMIF('MASTER DATA '!$E:$E,$B31,'MASTER DATA '!$AI:$AI) -> 0 | O31: =SUMIF('MASTER DATA '!$E:$E,$B31,'MASTER DATA '!$AJ:$AJ)+SUMIF('MASTER DATA '!$E:$E,$B31,'MASTER DATA '!$AK:$AK) -> 0 | P31: =SUM(N31:O31) -> 0 | Q31: =SUMIF('MASTER DATA '!$E:$E,$B31,'MASTER DATA '!$AO:$AO) -> 0 | R31: =SUMIF('MASTER DATA '!$E:$E,$B31,'MASTER DATA '!$AP:$AP) -> 0 | S31: =SUMIF('MASTER DATA '!$E:$E,$B31,'MASTER DATA '!$AR:$AR) -> 9872 | T31: =SUMIF('MASTER DATA '!$E:$E,$B31,'MASTER DATA '!$AS:$AS) -> 0 | U31: =SUMIF('MASTER DATA '!$E:$E,$B31,'MASTER DATA '!$AT:$AT) -> 0 | V31: =SUMIF('MASTER DATA '!$E:$E,$B31,'MASTER DATA '!$AU:$AU) -> 0 | W31: =SUMIF('MASTER DATA '!$E:$E,$B31,'MASTER DATA '!$AV:$AV) -> 0 | X31: =SUMIF('MASTER DATA '!$E:$E,$B31,'MASTER DATA '!$AW:$AW) -> 0 | Y31: =SUMIF('MASTER DATA '!$E:$E,$B31,'MASTER DATA '!$AX:$AX) -> 0 | Z31: =SUMIF('MASTER DATA '!$E:$E,$B31,'MASTER DATA '!$AY:$AY) -> 9872 | AA31: =IF(B31>=1,"SHOW","HIDE") -> SHOW
A32: =IF(B32="","",COUNTA($B$20:B32)) -> 13 | B32: RIVAS, JOSEPH S. | C32: Electrician General Forman | D32: INFRA | E32: 11 | F32: =VLOOKUP($B32,'MASTER DATA '!$E:$O,11,FALSE) -> 1227.2727 | G32: =VLOOKUP($B32,'MASTER DATA '!$E:$N,10,FALSE) -> 13500 | H32: =SUMIF('MASTER DATA '!$E:$E,$B32,'MASTER DATA '!$W:$W) -> 0 | I32: =SUMIF('MASTER DATA '!$E:$E,$B32,'MASTER DATA '!$X:$X)+SUMIF('MASTER DATA '!$E:$E,$B32,'MASTER DATA '!$Y:$Y) -> 7.67 | J32: =SUM(H32:I32) -> 7.67 | K32: =SUMIF('MASTER DATA '!$E:$E,$B32,'MASTER DATA '!$AC:$AC) -> 0 | L32: =SUMIF('MASTER DATA '!$E:$E,$B32,'MASTER DATA '!$AD:$AD)+SUMIF('MASTER DATA '!$E:$E,$B32,'MASTER DATA '!$AE:$AE) -> 0 | M32: =SUM(K32:L32) -> 0 | N32: =SUMIF('MASTER DATA '!$E:$E,$B32,'MASTER DATA '!$AI:$AI) -> 0 | O32: =SUMIF('MASTER DATA '!$E:$E,$B32,'MASTER DATA '!$AJ:$AJ)+SUMIF('MASTER DATA '!$E:$E,$B32,'MASTER DATA '!$AK:$AK) -> 0 | P32: =SUM(N32:O32) -> 0 | Q32: =SUMIF('MASTER DATA '!$E:$E,$B32,'MASTER DATA '!$AO:$AO) -> 7.67 | R32: =SUMIF('MASTER DATA '!$E:$E,$B32,'MASTER DATA '!$AP:$AP) -> 0 | S32: =SUMIF('MASTER DATA '!$E:$E,$B32,'MASTER DATA '!$AR:$AR) -> 13492.33 | T32: =SUMIF('MASTER DATA '!$E:$E,$B32,'MASTER DATA '!$AS:$AS) -> 0 | U32: =SUMIF('MASTER DATA '!$E:$E,$B32,'MASTER DATA '!$AT:$AT) -> 0 | V32: =SUMIF('MASTER DATA '!$E:$E,$B32,'MASTER DATA '!$AU:$AU) -> 0 | W32: =SUMIF('MASTER DATA '!$E:$E,$B32,'MASTER DATA '!$AV:$AV) -> 0 | X32: =SUMIF('MASTER DATA '!$E:$E,$B32,'MASTER DATA '!$AW:$AW) -> 0 | Y32: =SUMIF('MASTER DATA '!$E:$E,$B32,'MASTER DATA '!$AX:$AX) -> 0 | Z32: =SUMIF('MASTER DATA '!$E:$E,$B32,'MASTER DATA '!$AY:$AY) -> 13492.33 | AA32: =IF(B32>=1,"SHOW","HIDE") -> SHOW
A33: 14 | B33: ESTAPON, LESLIE DC. | C33: Administrative Asst. II | D33: ACCTG | E33: 11 | F33: =VLOOKUP($B33,'MASTER DATA '!$E:$O,11,FALSE) -> 897.45455 | G33: =VLOOKUP($B33,'MASTER DATA '!$E:$N,10,FALSE) -> 9872 | H33: =SUMIF('MASTER DATA '!$E:$E,$B33,'MASTER DATA '!$W:$W) -> 0 | I33: =SUMIF('MASTER DATA '!$E:$E,$B33,'MASTER DATA '!$X:$X)+SUMIF('MASTER DATA '!$E:$E,$B33,'MASTER DATA '!$Y:$Y) -> 33.65 | J33: =SUM(H33:I33) -> 33.65 | K33: =SUMIF('MASTER DATA '!$E:$E,$B33,'MASTER DATA '!$AC:$AC) -> 0 | L33: =SUMIF('MASTER DATA '!$E:$E,$B33,'MASTER DATA '!$AD:$AD)+SUMIF('MASTER DATA '!$E:$E,$B33,'MASTER DATA '!$AE:$AE) -> 0 | M33: =SUM(K33:L33) -> 0 | N33: =SUMIF('MASTER DATA '!$E:$E,$B33,'MASTER DATA '!$AI:$AI) -> 0 | O33: =SUMIF('MASTER DATA '!$E:$E,$B33,'MASTER DATA '!$AJ:$AJ)+SUMIF('MASTER DATA '!$E:$E,$B33,'MASTER DATA '!$AK:$AK) -> 0 | P33: =SUM(N33:O33) -> 0 | Q33: =SUMIF('MASTER DATA '!$E:$E,$B33,'MASTER DATA '!$AO:$AO) -> 33.65 | R33: =SUMIF('MASTER DATA '!$E:$E,$B33,'MASTER DATA '!$AP:$AP) -> 0 | S33: =SUMIF('MASTER DATA '!$E:$E,$B33,'MASTER DATA '!$AR:$AR) -> 9838.35 | T33: =SUMIF('MASTER DATA '!$E:$E,$B33,'MASTER DATA '!$AS:$AS) -> 0 | U33: =SUMIF('MASTER DATA '!$E:$E,$B33,'MASTER DATA '!$AT:$AT) -> 0 | V33: =SUMIF('MASTER DATA '!$E:$E,$B33,'MASTER DATA '!$AU:$AU) -> 0 | W33: =SUMIF('MASTER DATA '!$E:$E,$B33,'MASTER DATA '!$AV:$AV) -> 0 | X33: =SUMIF('MASTER DATA '!$E:$E,$B33,'MASTER DATA '!$AW:$AW) -> 0 | Y33: =SUMIF('MASTER DATA '!$E:$E,$B33,'MASTER DATA '!$AX:$AX) -> 0 | Z33: =SUMIF('MASTER DATA '!$E:$E,$B33,'MASTER DATA '!$AY:$AY) -> 9838.35
A34: 15 | B34: LOZANO, ADRIAN D. | C34: Administrative Asst. II | D34: ACCTG | E34: 11 | F34: =VLOOKUP($B34,'MASTER DATA '!$E:$O,11,FALSE) -> 897.45455 | G34: =VLOOKUP($B34,'MASTER DATA '!$E:$N,10,FALSE) -> 9872 | H34: =SUMIF('MASTER DATA '!$E:$E,$B34,'MASTER DATA '!$W:$W) -> 0 | I34: =SUMIF('MASTER DATA '!$E:$E,$B34,'MASTER DATA '!$X:$X)+SUMIF('MASTER DATA '!$E:$E,$B34,'MASTER DATA '!$Y:$Y) -> 9.35 | J34: =SUM(H34:I34) -> 9.35 | K34: =SUMIF('MASTER DATA '!$E:$E,$B34,'MASTER DATA '!$AC:$AC) -> 0 | L34: =SUMIF('MASTER DATA '!$E:$E,$B34,'MASTER DATA '!$AD:$AD)+SUMIF('MASTER DATA '!$E:$E,$B34,'MASTER DATA '!$AE:$AE) -> 0 | M34: =SUM(K34:L34) -> 0 | N34: =SUMIF('MASTER DATA '!$E:$E,$B34,'MASTER DATA '!$AI:$AI) -> 0 | O34: =SUMIF('MASTER DATA '!$E:$E,$B34,'MASTER DATA '!$AJ:$AJ)+SUMIF('MASTER DATA '!$E:$E,$B34,'MASTER DATA '!$AK:$AK) -> 0 | P34: =SUM(N34:O34) -> 0 | Q34: =SUMIF('MASTER DATA '!$E:$E,$B34,'MASTER DATA '!$AO:$AO) -> 9.35 | R34: =SUMIF('MASTER DATA '!$E:$E,$B34,'MASTER DATA '!$AP:$AP) -> 0 | S34: =SUMIF('MASTER DATA '!$E:$E,$B34,'MASTER DATA '!$AR:$AR) -> 9862.65 | T34: =SUMIF('MASTER DATA '!$E:$E,$B34,'MASTER DATA '!$AS:$AS) -> 0 | U34: =SUMIF('MASTER DATA '!$E:$E,$B34,'MASTER DATA '!$AT:$AT) -> 0 | V34: =SUMIF('MASTER DATA '!$E:$E,$B34,'MASTER DATA '!$AU:$AU) -> 0 | W34: =SUMIF('MASTER DATA '!$E:$E,$B34,'MASTER DATA '!$AV:$AV) -> 0 | X34: =SUMIF('MASTER DATA '!$E:$E,$B34,'MASTER DATA '!$AW:$AW) -> 0 | Y34: =SUMIF('MASTER DATA '!$E:$E,$B34,'MASTER DATA '!$AX:$AX) -> 0 | Z34: =SUMIF('MASTER DATA '!$E:$E,$B34,'MASTER DATA '!$AY:$AY) -> 9862.65
A36: Total | G36: =SUM(G20:G34) -> 160759 | H36: =SUM(H20:H34) -> 0 | I36: =SUM(I20:I34) -> 177.96 | J36: =SUM(J20:J34) -> 177.96 | K36: =SUM(K20:K34) -> 0 | L36: =SUM(L20:L34) -> 0 | M36: =SUM(M20:M34) -> 0 | N36: =SUM(N20:N29) -> 0 | O36: =SUM(O20:O29) -> 0 | P36: =SUM(P20:P34) -> 0 | Q36: =SUM(Q20:Q34) -> 177.96 | R36: =SUM(R20:R34) -> 0 | S36: =SUM(S20:S34) -> 139370.04 | T36: =SUM(T20:T34) -> 0 | U36: =SUM(U20:U34) -> 0 | V36: =SUM(V20:V34) -> 0 | W36: =SUM(W20:W34) -> 0 | ... Z36: =SUM(Z20:Z34) -> 139370.04
A38: CERTIFIED: Services duty rendered as stated. | G38: APPROVED:
B41: MARISA O. GALGO | G41: REMELYN R. RECOTER, MNSA, CESO III
B42: AO V, HRMO, Admin Unit | G42: Director IV
A43: CERTIFIED: Supporting documents complete and proper and | G43: CERTIFIED: Each employee whose name appears above has been paid the amount
B44: cash available in the amount of | G44: indicated opposite on his/her name. | V44: ALOBS No.
V45: Date:
V46: JBV No.
B47: GILLIAN ROSE L. SALUIB | G47: JOSEFINA M. DELOS SANTOS | V47: Date:
B48: Accountant III, Head Finance Unit | G48: AO I, Disbursing Officer | S48: Date
G53: GENERAL PAYROLL
B57: Prepared by: Jonalyn T. Tolero
B60: We hereby acknowledge to have received from Valentina S. Cagumbay, Admin. Officer III, the sums herein specified opposite our respective names, being in full compensation of our
B61: services for the period of January 1-15, 2024
A62: Name | C62: Position | E62: Number of Days
F63: Salary per Day | G63: Half Month Salary | H63: Less | K63: Less | N63: Less | R63: add/less | S63: Total | T63: Less | V63: Less | Z63: Total Net Received
H64: Absences | I64: Late/UT | K64: Absences | L64: Late/UT | N64: Absences | O64: Late/UT | R64: Other Adjustment | T64: Withholding Tax | V64: Accommodation for the Month of | W64: Water | X64: Electric | Y64: Repairs
...

Sheet TXTLIST
A1: TXTLIST FOR THE PERIOD OF | B1: ='MASTER DATA '!A4 -> 02-16-28-2026
A3: NAME | B3: AMOUNT
A4: ACENO, ALYANNA MARIE | B4: =SUMIF('MASTER DATA '!$E:$E,TXTLIST!$A4,'MASTER DATA '!$AY:$AY) -> 10605.5
A5: ALBOROTO, JANET P. | B5: =SUMIF('MASTER DATA '!$E:$E,TXTLIST!$A5,'MASTER DATA '!$AY:$AY) -> 10605.5
A6: ARENAS, DIANA ROSE A. | B6: =SUMIF('MASTER DATA '!$E:$E,TXTLIST!$A6,'MASTER DATA '!$AY:$AY) -> 11579.22
A7: BERNABE, JOHN MICHAEL A. | B7: =SUMIF('MASTER DATA '!$E:$E,TXTLIST!$A7,'MASTER DATA '!$AY:$AY) -> 0
A8: BERNABE CHERRY MAY E. | B8: =SUMIF('MASTER DATA '!$E:$E,TXTLIST!$A8,'MASTER DATA '!$AY:$AY) -> 9872
A9: CANNU JR, ALFREDO O. | B9: =SUMIF('MASTER DATA '!$E:$E,TXTLIST!$A9,'MASTER DATA '!$AY:$AY) -> 10577.38
A10: CELOCIA, MERLITA O. | B10: =SUMIF('MASTER DATA '!$E:$E,TXTLIST!$A10,'MASTER DATA '!$AY:$AY) -> 10605.5
A11: CUBIL, JOCELYN R. | B11: =SUMIF('MASTER DATA '!$E:$E,TXTLIST!$A11,'MASTER DATA '!$AY:$AY) -> 0
A12: GULTIANO, HELEN D. | B12: =SUMIF('MASTER DATA '!$E:$E,TXTLIST!$A12,'MASTER DATA '!$AY:$AY) -> 10605.5
A13: TORIO, CECIL P. | B13: =SUMIF('MASTER DATA '!$E:$E,TXTLIST!$A13,'MASTER DATA '!$AY:$AY) -> 10515.11
A14: GASATAN, ENRICO JAN S. | B14: =SUMIF('MASTER DATA '!$E:$E,TXTLIST!$A14,'MASTER DATA '!$AY:$AY) -> 10605.5
A15: JARABESE, LUIS E. | B15: =SUMIF('MASTER DATA '!$E:$E,TXTLIST!$A15,'MASTER DATA '!$AY:$AY) -> 10605.5
... A18: LOZANO, ADRIAN D. | B18: =SUMIF('MASTER DATA '!$E:$E,TXTLIST!$A18,'MASTER DATA '!$AY:$AY) -> 9862.65
A20: TOTAL | B20: =SUM(B4:B19) -> 139370.04

Sheet CODE
B1: SERIES | C1: CODE | D1: NO. | E1: NAME | F1: OFFICE | G1: POSITION
B2: 1 | C2: =CONCATENATE(B2,"-",F2) -> 1-CDMD | D2: =IF(E2="","",COUNTA($E$2:E2)) -> 1 | E2: AUSTRIA, CHRISTIAN JOCEF B. | F2: CDMD | G2: Administrative Asst. III
B3: 2 | C3: =CONCATENATE(B3,"-",F3) -> 2-CDMD | D3: =IF(E3="","",COUNTA($E$2:E3)) -> 2 | E3: SALVANIA, DIANNE MARIE U. | F3: CDMD | G3: Development Mngt. Officer I
B4: 3 | C4: =CONCATENATE(B4,"-",F4) -> 3-CDMD | D4: =IF(E4="","",COUNTA($E$2:E4)) -> 3 | E4: MONTIEL, KRISTEL DIANNE A. | F4: CDMD | G4: Development Mngt. Officer I
B5: 4 | C5: =CONCATENATE(B5,"-",F5) -> 4-CDMD | D5: =IF(E5="","",COUNTA($E$2:E5)) -> 4 | E5: KATIPUNAN, JERUSHA KYLE ANGELA M. | F5: CDMD | G5: Development Mngt. Officer I
B6: 1 | C6: =CONCATENATE(B6,"-",F6) -> 1-PPD | D6: =IF(E6="","",COUNTA($E$2:E6)) -> 5 | E6: ESMER, GLECY R. | F6: PPD | G6: Administrative Asst. II
B7: 2 | C7: =CONCATENATE(B7,"-",F7) -> 2-PPD | D7: =IF(E7="","",COUNTA($E$2:E7)) -> 6 | E7: AGUILAR, ROXETTE | F7: PPD | G7: Planning Officer I
B8: 1 | C8: =CONCATENATE(B8,"-",F8) -> 1-ISD | D8: =IF(E8="","",COUNTA($E$2:E8)) -> 7 | E8: ANTIPAS, ANDREA JANE M. | F8: ISD | G8: Administrative Asst. II
B9: 2 | C9: =CONCATENATE(B9,"-",F9) -> 2-ISD | D9: =IF(E9="","",COUNTA($E$2:E9)) -> 8 | E9: GABAO, JENNY ROSE B. | F9: ISD | G9: Information Officer I
B10: 3 | C10: =CONCATENATE(B10,"-",F10) -> 3-ISD | D10: =IF(E10="","",COUNTA($E$2:E10)) -> 9 | E10: LAMPAS, CHRISTIAN JOSEPH P | F10: ISD | G10: Computer Maintenance Tech. I
B11: 4 | C11: =CONCATENATE(B11,"-",F11) -> 4-ISD | D11: =IF(E11="","",COUNTA($E$2:E11)) -> 10 | E11: MANDANI, AVE M. | F11: ISD | G11: Bookbinder III
B12: 5 | C12: =CONCATENATE(B12,"-",F12) -> 5-ISD | D12: =IF(E12="","",COUNTA($E$2:E12)) -> 11 | E12: PERNIA, JONAS S. | F12: ISD | G12: Administrative Asst. II
B13: 6 | C13: =CONCATENATE(B13,"-",F13) -> 6-ISD | D13: =IF(E13="","",COUNTA($E$2:E13)) -> 12 | E13: SAREFE, ANGELIA KAY N. | F13: ISD | G13: Information Officer I
... B55: 9 | C55: =CONCATENATE(B55,"-",F55) -> 9-PAD | D55: =IF(E55="","",COUNTA($E$2:E55)) -> 54 | E55: MEJIA, JONNIEL | F55: PAD | G55: Administrative Aide VI

Sheet CODE 2
A1: OFFICE | J1: SALARY GRADE | K1: RATE | M1: Current | O1: ,
A2: DO | B2: PAD | C2: Partnership & Accreditation Division (PAD) | J2: 6 | K2: 17553
A3: ADO | B3: PPD | C3: Policy and Planning Division (PPD) | J3: 7 | K3: 18620 | M3: GAM SERIES | N3: PAYEE | O3: PAP
A4: PAD | B4: CDMD | C4: Career Development and Management Division (CDMD) | J4: 8 | K4: 19744 | N4: 7th
A5: PPD | B5: ISD | C5: Information Service Division (ISD) | J5: 9 | K5: 21211 | M5: 02-101101-2023-01-000001 | N5: ARLENE GEMINIANA S. NILO | O5: GMS | P5: GMS
A6: ISD | B6: ADO | C6: Assistant Director Office | J6: 10 | K6: 23176 | M6: 02-101101-2023-01-000001 | N6: ARLENE GEMINIANA S. NILO | O6: GMS | P6: GMS
A7: CDMD | B7: DO | C7: Office of the Director | J7: 11 | K7: 27000 | M7: 02-101101-2023-01-000001 | N7: ARLENE GEMINIANA S. NILO | O7: GMS | P7: GMS
J8: 12 | K8: 29165 | M8: 02-101101-2023-01-000002 | N8: PLDT | O8: GMS | P8: GMS
J9: 13 | K9: 31320 | M9: 02-101101-2023-01-000003 | N9: PLDT | O9: GMS | P9: GMS
J10: 14 | K10: 33843 | M10: 02-101101-2023-01-000004 | N10: REMELYN R. RECOTER | O10: GMS | P10: GMS
J11: 15 | K11: 36619 | M11: 02-101101-2023-01-000005 | N11: ATI GUESTHOUSE REVOLVING FUND | O11: OTHER ESETS
J12: 16 | K12: 39672 | M12: 02-101101-2023-01-000006 | N12: TJS CLEAR ART | O12: OTHER ESETS
M13: 02-101101-2023-01-000007 | N13: SWEET JESSABEL M. DE GUZMAN | O13: GMS | P13: GMS
M14: 02-101101-2023-01-000008 | N14: LIYANNE L. MAGOS | O14: GMS | P14: GMS
M15: 02-101101-2023-01-000009 | N15: ROSELY-ANN G. CELOCIA | O15: GMS | P15: GMS
M16: 02-101101-2023-01-000010 | N16: ANGENNITTE F. BRUZON | O16: OTHER ESETS
M17: 02-101101-2023-01-000011 | N17: MA. RUBEN ANA D. RUBINO | O17: OTHER ESETS
M18: 02-101101-2023-01-000012 | N18: JHEY ANN M. NEPOMUCENO | O18: OTHER ESETS
M19: 02-101101-2023-01-000013 | N19: JONEL PERALTA | O19: OTHER ESETS
M20: 02-101101-2023-01-000014 | N20: CLEMENT PAUL P. EDORIA | O20: OTHER ESETS
M21: 02-101101-2023-01-000015 | N21: JOSEPH S. RIVAS | O21: OTHER ESETS
M22: 02-101101-2023-01-000016 | N22: ELVIS JOHN L. CATUBAY | O22: OTHER ESETS
M23: 02-101101-2023-01-000017 | N23: JOPETER C. FLORES | O23: OTHER ESETS
M24: 02-101101-2023-01-000018 | N24: JOSEN L. CUARTERON | O24: OTHER ESETS
M25: 02-101101-2023-01-000019 | N25: JACKSON T. TAPIADOR | O25: OTHER ESETS
M26: 02-101101-2023-01-000020 | N26: FERDINAND D. MARCELO | O26: OTHER ESETS
M27: 02-101101-2023-01-000021 | N27: JHOUSWELL LEE MELVIN B. DE GUZMAN | O27: OTHER ESETS
... M149: 02-101101-2023-01-000117 | N149: HACIENDA GRACIA RESORT AND HOTEL | O149: OTHER ESETS

Sheet PREMIUM
A1: AGRICULTURAL TRAINING INSTITUTE - CENTRAL OFFICE
A2: JOB ORDER 20% PREMIUM GENERAL PAYROLL
A4: ACTUAL GROSS SALARY RECEIVED
A5: FOR THE PERIOD OF JANUARY TO JUNE FY 2023
A6: No. | B6: ORS Number | C6: ORS Date | E6: Name | F6: Office | G6: Position | H6: Salary Grade | I6: FUND SOURCE | J6: Expanded Tax Exempt | K6: JANUARY | L6: JANUARY | M6: JANUARY | N6: FEBRUARY | O6: FEBRUARY | P6: FEBRUARY | Q6: MARCH | R6: MARCH | S6: MARCH | T6: APRIL | U6: APRIL | V6: APRIL | W6: MAY | X6: MAY | Y6: MAY | Z6: JUNE | AA6: JUNE | AB6: JUNE | AC6: TOTAL | AD6: 20% PREMIUM | AE6: Withholding Tax | AG6: NET RECEIVED
AE7: EXPANDED | AF7: PERCENTAGE
K8: 1 - 15 | L8: 16 - 31 | M8: 1 - 31 | N8: 1 - 15 | O8: 16 - 28 | P8: 1 - 28 | Q8: 1 - 15 | R8: 16 - 31 | S8: 1 - 31 | T8: 1 - 15 | U8: 16 - 30 | V8: 16 - 30 | W8: 1 - 15 | X8: 16 - 31 | Y8: 16 - 31 | Z8: 1 - 15 | AA8: 16 - 30 | AB8: 16 - 30 | AC8: JAN. TO JUNE | AE8: 0.02 | AF8: 0.01
A9: 1 | B9: 2 | C9: 3 | D9: 4 | E9: 5 | F9: 6 | G9: 7 | H9: 8 | J9: 9 | AE9: 37 | AF9: 38
A10: =IF(B10="","",COUNTA($B$10:B10)) -> 1 | B10: ='MASTER DATA '!B10 -> 2026-01-0009 | C10: ='MASTER DATA '!C10 -> 46036 | D10: ='MASTER DATA '!D10 | E10: ='MASTER DATA '!E10 -> ALBOROTO, JANET P. | F10: ='MASTER DATA '!F10 -> GH | G10: ='MASTER DATA '!G10 -> Administrative Asst. III | H10: ='MASTER DATA '!H10 -> 9 | I10: ='MASTER DATA '!I10 -> REVOLVING FUND | J10: ='MASTER DATA '!J10 -> ok | M10: =SUM(K10:L10) -> 0 | P10: =SUM(N10:O10) -> 0 | S10: =SUM(Q10:R10) -> 0 | V10: =SUM(T10:U10) -> 0 | Y10: =SUM(W10:X10) -> 0 | AB10: =SUM(Z10:AA10) -> 0 | AC10: =M10+P10+S10+V10+Y10+AB10 -> 0 | AD10: =AC10*0.2 -> 0 | AF10: =ROUND((AD10*$AF$8),2) -> 0 | AG10: =AD10-AE10-AF10 -> 0
A11: =IF(B11="","",COUNTA($B$10:B11)) -> 2 | B11: ='MASTER DATA '!B11 -> 2026-01-0010 | C11: ='MASTER DATA '!C11 -> 46036 | D11: ='MASTER DATA '!D11 | E11: ='MASTER DATA '!E11 -> ARENAS, DIANA ROSE A. | F11: ='MASTER DATA '!F11 -> GH | G11: ='MASTER DATA '!G11 -> Administrative Asst. IV (Dormitory Assistant) | H11: ='MASTER DATA '!H11 -> 10 | I11: ='MASTER DATA '!I11 -> REVOLVING FUND | J11: ='MASTER DATA '!J11 -> ok | M11: =SUM(K11:L11) -> 0 | P11: =SUM(N11:O11) -> 0 | S11: =SUM(Q11:R11) -> 0 | V11: =SUM(T11:U11) -> 0 | Y11: =SUM(W11:X11) -> 0 | AB11: =SUM(Z11:AA11) -> 0 | AC11: =M11+P11+S11+V11+Y11+AB11 -> 0 | AD11: =AC11*0.2 -> 0 | AF11: =ROUND((AD11*$AF$8),2) -> 0 | AG11: =AD11-AE11-AF11 -> 0
A12: =IF(B12="","",COUNTA($B$10:B12)) | B12: ='MASTER DATA '!B12 | C12: ='MASTER DATA '!C12 | D12: ='MASTER DATA '!D12 | E12: ='MASTER DATA '!E13 -> CANNU JR, ALFREDO O. | F12: ='MASTER DATA '!F12 -> GH | G12: ='MASTER DATA '!G12 -> Administrative Asst. III | H12: ='MASTER DATA '!H12 -> 9 | I12: ='MASTER DATA '!I12 -> REVOLVING FUND | J12: ='MASTER DATA '!J12 -> ok | M12: =SUM(K12:L12) -> 0 | P12: =SUM(N12:O12) -> 0 | S12: =SUM(Q12:R12) -> 0 | V12: =SUM(T12:U12) -> 0 | Y12: =SUM(W12:X12) -> 0 | AB12: =SUM(Z12:AA12) -> 0 | AC12: =M12+P12+S12+V12+Y12+AB12 -> 0 | AD12: =AC12*0.2 -> 0 | AF12: =ROUND((AD12*$AF$8),2) -> 0 | AG12: =AD12-AE12-AF12 -> 0
A13: =IF(B13="","",COUNTA($B$10:B13)) -> 3 | B13: ='MASTER DATA '!B13 -> 2026-01-0002 | C13: ='MASTER DATA '!C13 -> 46036 | D13: ='MASTER DATA '!D13 | E13: ='MASTER DATA '!E14 -> CELOCIA, MERLITA O. | F13: ='MASTER DATA '!F13 -> GH | G13: ='MASTER DATA '!G13 -> Administrative Asst. III (Housekeeping Attendant) | H13: ='MASTER DATA '!H13 -> 9 | I13: ='MASTER DATA '!I13 -> REVOLVING FUND | J13: ='MASTER DATA '!J13 -> ok | M13: =SUM(K13:L13) -> 0 | P13: =SUM(N13:O13) -> 0 | S13: =SUM(Q13:R13) -> 0 | V13: =SUM(T13:U13) -> 0 | Y13: =SUM(W13:X13) -> 0 | AB13: =SUM(Z13:AA13) -> 0 | AC13: =M13+P13+S13+V13+Y13+AB13 -> 0 | AD13: =AC13*0.2 -> 0 | AF13: =ROUND((AD13*$AF$8),2) -> 0 | AG13: =AD13-AE13-AF13 -> 0
A14: =IF(B14="","",COUNTA($B$10:B14)) -> 4 | B14: ='MASTER DATA '!B14 -> 2026-01-0001 | C14: ='MASTER DATA '!C14 -> 46036 | D14: ='MASTER DATA '!D14 | E14: ='MASTER DATA '!E15 -> CUBIL, JOCELYN R. | F14: ='MASTER DATA '!F14 -> GH | G14: ='MASTER DATA '!G14 -> Administrative Asst. III | H14: ='MASTER DATA '!H14 -> 9 | I14: ='MASTER DATA '!I14 -> REVOLVING FUND | J14: ='MASTER DATA '!J14 -> ok | M14: =SUM(K14:L14) -> 0 | P14: =SUM(N14:O14) -> 0 | S14: =SUM(Q14:R14) -> 0 | V14: =SUM(T14:U14) -> 0 | Y14: =SUM(W14:X14) -> 0 | AB14: =SUM(Z14:AA14) -> 0 | AC14: =M14+P14+S14+V14+Y14+AB14 -> 0 | AD14: =AC14*0.2 -> 0 | AF14: =ROUND((AD14*$AF$8),2) -> 0 | AG14: =AD14-AE14-AF14 -> 0
A15: =IF(B15="","",COUNTA($B$10:B15)) | B15: ='MASTER DATA '!B15 | C15: ='MASTER DATA '!C15 | D15: ='MASTER DATA '!D15 | E15: ='MASTER DATA '!E16 -> GULTIANO, HELEN D. | F15: ='MASTER DATA '!F15 -> GH | G15: ='MASTER DATA '!G15 -> Administrative Asst. III | H15: ='MASTER DATA '!H15 -> 9 | I15: ='MASTER DATA '!I15 -> REVOLVING FUND | J15: ='MASTER DATA '!J15 -> ok | M15: =SUM(K15:L15) -> 0 | P15: =SUM(N15:O15) -> 0 | S15: =SUM(Q15:R15) -> 0 | V15: =SUM(T15:U15) -> 0 | Y15: =SUM(W15:X15) -> 0 | AB15: =SUM(Z15:AA15) -> 0 | AC15: =M15+P15+S15+V15+Y15+AB15 -> 0 | AD15: =AC15*0.2 -> 0 | AF15: =ROUND((AD15*$AF$8),2) -> 0 | AG15: =AD15-AE15-AF15 -> 0
A16: =IF(B16="","",COUNTA($B$10:B16)) -> 5 | B16: ='MASTER DATA '!B16 -> 2026-01-0006 | C16: ='MASTER DATA '!C16 -> 46036 | D16: ='MASTER DATA '!D16 | E16: ='MASTER DATA '!E17 -> TORIO, CECIL P. | F16: ='MASTER DATA '!F16 -> GH | G16: ='MASTER DATA '!G16 -> Administrative Asst. III | H16: ='MASTER DATA '!H16 -> 9 | I16: ='MASTER DATA '!I16 -> REVOLVING FUND | J16: ='MASTER DATA '!J16 -> ok | M16: =SUM(K16:L16) -> 0 | P16: =SUM(N16:O16) -> 0 | S16: =SUM(Q16:R16) -> 0 | V16: =SUM(T16:U16) -> 0 | Y16: =SUM(W16:X16) -> 0 | AB16: =SUM(Z16:AA16) -> 0 | AC16: =M16+P16+S16+V16+Y16+AB16 -> 0 | AD16: =AC16*0.2 -> 0 | AF16: =ROUND((AD16*$AF$8),2) -> 0 | AG16: =AD16-AE16-AF16 -> 0
A17: =IF(B17="","",COUNTA($B$10:B17)) -> 6 | B17: ='MASTER DATA '!B17 -> 2026-01-0007 | C17: ='MASTER DATA '!C17 -> 46036 | D17: ='MASTER DATA '!D17 | E17: ='MASTER DATA '!E18 -> GASATAN, ENRICO JAN S. | F17: ='MASTER DATA '!F17 -> GH | G17: ='MASTER DATA '!G17 -> Administrative Asst. III | H17: ='MASTER DATA '!H17 -> 9 | I17: ='MASTER DATA '!I17 -> REVOLVING FUND | J17: ='MASTER DATA '!J17 -> ok | M17: =SUM(K17:L17) -> 0 | P17: =SUM(N17:O17) -> 0 | S17: =SUM(Q17:R17) -> 0 | V17: =SUM(T17:U17) -> 0 | Y17: =SUM(W17:X17) -> 0 | AB17: =SUM(Z17:AA17) -> 0 | AC17: =M17+P17+S17+V17+Y17+AB17 -> 0 | AD17: =AC17*0.2 -> 0 | AF17: =ROUND((AD17*$AF$8),2) -> 0 | AG17: =AD17-AE17-AF17 -> 0
A18: =IF(B18="","",COUNTA($B$10:B18)) -> 7 | B18: ='MASTER DATA '!B18 -> 2026-01-0008 | C18: ='MASTER DATA '!C18 -> 46036 | D18: ='MASTER DATA '!D18 | E18: ='MASTER DATA '!E19 -> JARABESE, LUIS E. | F18: ='MASTER DATA '!F18 -> GH | G18: ='MASTER DATA '!G18 -> Administrative Asst. III (Housekeeping Attendant) | H18: ='MASTER DATA '!H18 -> 9 | I18: ='MASTER DATA '!I18 -> REVOLVING FUND | J18: ='MASTER DATA '!J18 -> ok | M18: =SUM(K18:L18) -> 0 | P18: =SUM(N18:O18) -> 0 | S18: =SUM(Q18:R18) -> 0 | V18: =SUM(T18:U18) -> 0 | Y18: =SUM(W18:X18) -> 0 | AB18: =SUM(Z18:AA18) -> 0 | AC18: =M18+P18+S18+V18+Y18+AB18 -> 0 | AD18: =AC18*0.2 -> 0 | AF18: =ROUND((AD18*$AF$8),2) -> 0 | AG18: =AD18-AE18-AF18 -> 0
A19: =IF(B19="","",COUNTA($B$10:B19)) -> 8 | B19: ='MASTER DATA '!B19 -> 2026-01-0004 | C19: ='MASTER DATA '!C19 -> 46036 | D19: ='MASTER DATA '!D19 | E19: =#REF! -> #REF! | F19: ='MASTER DATA '!F19 -> GH | G19: ='MASTER DATA '!G19 -> Administrative Asst. III | H19: ='MASTER DATA '!H19 -> 9 | I19: ='MASTER DATA '!I19 -> REVOLVING FUND | J19: ='MASTER DATA '!J19 -> ok | M19: =SUM(K19:L19) -> 0 | P19: =SUM(N19:O19) -> 0 | S19: =SUM(Q19:R19) -> 0 | V19: =SUM(T19:U19) -> 0 | Y19: =SUM(W19:X19) -> 0 | AB19: =SUM(Z19:AA19) -> 0 | AC19: =M19+P19+S19+V19+Y19+AB19 -> 0 | AD19: =AC19*0.2 -> 0 | AF19: =ROUND((AD19*$AF$8),2) -> 0 | AG19: =AD19-AE19-AF19 -> 0
