Workbook

Sheet disallowance
B2: NAME | C2: Monthly Deduction (Disallowance A) | E2: Monthly Deduction (Disallowance B) | F2: disallowance B | G2: TOTAL DEDUCTION MONTHLY
A3: 1 | B3: Al P. Camaya | C3: 1000 | D3: Note | E3: 1000 | G3: =C3+E3 -> 2000
A4: 2 | B4: Alfredo S. Aton | C4: 0 | E4: 833.33333
A5: 4 | B5: Althea D. Perez | C5: 574.83333 | D5: OKAY | E5: 1055.5556 | F5: OKAY | G5: 1630.3889
A6: 5 | B6: Alyza Jane D. Villamarzo | C6: 458.33333 | D6: OKAY | E6: 0 | F6: OKAY | G6: 458.33333
A7: 6 | B7: Amelito A. Belaro | C7: 273.35417 | D7: OKAY | E7: 0 | F7: OKAY | G7: 273.35417
A8: 9 | B8: Angelica Marie T. Umali | C8: 429.16667 | D8: OKAY | E8: 0 | F8: OKAY | G8: 429.16667
A9: 10 | B9: Ansherina G. Torres | C9: 899.83333 | D9: OKAY | E9: 760.11111 | F9: OKAY | G9: 1659.9444
A10: 11 | B10: Antonieta J. Arceo | C10: 979.16667 | D10: OKAY | E10: 1000 | F10: OKAY | G10: 1979.1667
A11: 12 | B11: Arlene S. Nilo | C11: 0 | D11: OKAY | E11: 0 | F11: OKAY | G11: 0
A12: 13 | B12: Armando R. Ricablanca | C12: 0 | D12: Note | E12: 0 | F12: OKAY | G12: 0
A13: 14 | B13: Arnel R. Bunda | D13: -31.25 | E13: 0 | F13: OKAY | H13: -31.25
A14: 16 | B14: Athena AB. Baguisi | C14: 934.29708 | D14: OKAY | E14: 0.0011111111 | F14: OKAY | G14: 934.29819
A15: 17 | B15: Basil F. Nunez | D15: -62.5 | E15: 0 | F15: OKAY | H15: -62.5
A16: 18 | B16: Beatriz A. Yanga | C16: 0 | D16: 121827 | E16: 0 | F16: 35000 | G16: 0
A17: 19 | B17: Bernard James R. Tandang | C17: 2102.9583 | E17: 1569.4444 | F17: OKAY | G17: 3672.4028
A18: 20 | B18: Camilo M. Alberto | C18: 0 | D18: OKAY | E18: 0 | F18: OKAY | G18: 0
A19: 21 | B19: Charisa N. Miral | C19: 1512.3333 | D19: OKAY | E19: 1944.4444 | F19: OKAY | G19: 3456.7778
A20: 22 | B20: Christine U. Suay | C20: 691.5 | D20: OKAY | E20: 0 | F20: OKAY | G20: 691.5
A21: 23 | B21: Cindy C. Alfonso | C21: 979.16667 | D21: OKAY | E21: 500 | F21: OKAY | G21: 1479.1667
A22: 24 | B22: Cipriano M. De Guzman | C22: 544.83333 | D22: OKAY | E22: 277.77778 | G22: 822.61111
A23: 25 | B23: Clemente A. Gabion | C23: 1139.9792 | D23: OKAY | E23: 0 | F23: OKAY | G23: 1139.9792
A24: 26 | B24: Corazon Z. Cabangbang | C24: 608.79 | D24: OKAY | E24: 0 | F24: OKAY | G24: 608.79
A25: 27 | B25: Cyril C. Cuerbo | C25: 428 | D25: OKAY | E25: 0 | F25: OKAY | G25: 428
A26: 28 | B26: Czarina S. Mamino | C26: 0 | D26: OKAY | E26: 555.55556 | F26: OKAY | G26: 555.55556
A27: 29 | B27: Dailinda D. Yadao | C27: 0 | D27: OKAY | E27: 0 | F27: OKAY | G27: 0
A28: 31 | B28: Daniel U. Nilo | C28: 0 | D28: OKAY | E28: 0 | F28: OKAY | G28: 0
A29: 33 | B29: Darwin C. Bibit | C29: 978.125 | D29: OKAY | E29: 0 | F29: OKAY | G29: 978.125
A30: 34 | B30: Demetrio P. Legarde | C30: 0 | D30: 106621 | E30: 0 | F30: 35000 | G30: 0
A31: 35 | B31: Dino Jenn C. Lubguban | D31: -41.666667 | E31: 0 | F31: OKAY | H31: -41.666667
A32: 36 | B32: Dominador N. Estoesta | C32: 580.16667 | D32: OKAY | E32: 0 | F32: OKAY | G32: 580.16667
A33: 37 | B33: Donato M. Tangonan | C33: 565.0625 | D33: OKAY | E33: 0 | F33: OKAY | G33: 565.0625
A34: 38 | B34: Edena P. Sayson | C34: 0 | D34: Note | E34: 0 | F34: Note | G34: 3500
A35: 39 | B35: Editha S. Vinuya | C35: 1033.5417 | D35: OKAY | E35: 1944.4444 | F35: OKAY | G35: 2977.9861
A36: 40 | B36: Elsa A. Parot | C36: 2905.1667 | E36: 1944.4444 | G36: 4849.6111
A37: 41 | B37: Emerson R. Deñado | C37: 489.58333 | D37: OKAY | E37: 0 | F37: OKAY | G37: 489.58333
A38: 42 | B38: Emmanuel I. Mendoza | C38: 668.4375 | D38: OKAY | E38: 0 | F38: OKAY | G38: 668.4375
A39: 43 | B39: Erika Z. Vizcarra | C39: 197.91667 | D39: OKAY | E39: 0 | F39: OKAY | G39: 197.91667
A40: 44 | B40: Erlinda R. Vinarao | C40: 0 | D40: Note | E40: 0 | F40: Note | G40: 0
A41: 45 | B41: Eufemia A. Atienza | D41: OKAY | E41: 2000 | F41: OKAY | G41: 2000
...

Sheet PER DIVISION
A4: GENERAL PAYROLL FOR THE MONTH OF MARCH 2026
C6: GROSS SALARY | D6: DEDUCTIONS | E6: NET TAKE HOME PAY
B7: OD | C7: =SUMIF(PAYOUT!$F:$F,'PER DIVISION'!$B:$B,PAYOUT!N:N) -> 330485 | D7: =SUMIF(PAYOUT!$F:$F,'PER DIVISION'!$B:$B,PAYOUT!AZ:AZ) -> 156279.82 | E7: =C7-D7 -> 174205.18
B8: AFU-OD | C8: =SUMIF(PAYOUT!$F:$F,'PER DIVISION'!$B:$B,PAYOUT!N:N) -> 698293 | D8: =SUMIF(PAYOUT!$F:$F,'PER DIVISION'!$B:$B,PAYOUT!AZ:AZ) -> 346871.17 | E8: =C8-D8 -> 351421.83 | F8: =SUMIF(PAYOUT!$F:$F,'PER DIVISION'!$B:$B,PAYOUT!BA:BA)-E8 -> 0
B9: CDMD | C9: =SUMIF(PAYOUT!$F:$F,'PER DIVISION'!$B:$B,PAYOUT!N:N) -> 780421 | D9: =SUMIF(PAYOUT!$F:$F,'PER DIVISION'!$B:$B,PAYOUT!AZ:AZ) -> 352045.31 | E9: =C9-D9 -> 428375.69 | F9: =SUMIF(PAYOUT!$F:$F,'PER DIVISION'!$B:$B,PAYOUT!BA:BA)-E9 -> 0
B10: ISD | C10: =SUMIF(PAYOUT!$F:$F,'PER DIVISION'!$B:$B,PAYOUT!N:N) -> 803664 | D10: =SUMIF(PAYOUT!$F:$F,'PER DIVISION'!$B:$B,PAYOUT!AZ:AZ) -> 375711.08 | E10: =C10-D10 -> 427952.92 | F10: =SUMIF(PAYOUT!$F:$F,'PER DIVISION'!$B:$B,PAYOUT!BA:BA)-E10 -> 0
B11: PAD | C11: =SUMIF(PAYOUT!$F:$F,'PER DIVISION'!$B:$B,PAYOUT!N:N) -> 701706 | D11: =SUMIF(PAYOUT!$F:$F,'PER DIVISION'!$B:$B,PAYOUT!AZ:AZ) -> 361221.02 | E11: =C11-D11 -> 340484.98 | F11: =SUMIF(PAYOUT!$F:$F,'PER DIVISION'!$B:$B,PAYOUT!BA:BA)-E11 -> 0
B12: PPD | C12: =SUMIF(PAYOUT!$F:$F,'PER DIVISION'!$B:$B,PAYOUT!N:N) -> 786858 | D12: =SUMIF(PAYOUT!$F:$F,'PER DIVISION'!$B:$B,PAYOUT!AZ:AZ) -> 304753.98 | E12: =C12-D12 -> 482104.02 | F12: =SUMIF(PAYOUT!$F:$F,'PER DIVISION'!$B:$B,PAYOUT!BA:BA)-E12 -> 0
C13: =SUMIF(PAYOUT!$F:$F,'PER DIVISION'!$B:$B,PAYOUT!N:N) -> 0
B14: TOTAL | C14: =SUM(C7:C13) -> 4101427 | D14: =SUM(D7:D13) -> 1896882.4 | E14: =SUM(E7:E13) -> 2204544.6 | F14: =SUM(F8:F13) -> 0
A18: Prepared By:
B19: JONALYN T. TOLERO
B20: Admin Assistant III
A23: Certified By:
B24: MARISA O. GALGO
B26: AO V, HRMO-AFU-OD

Sheet DATA
A2: Third Tranche
A3: Salary Grade | B3: 1 | C3: 2 | D3: 3 | E3: 4 | F3: 5 | G3: 6 | H3: 7 | I3: 8
A4: 1 | B4: 14634 | C4: 14730 | D4: 14849 | E4: 14968 | F4: 15089 | G4: 15211 | H4: 15333 | I4: 15456
A5: 2 | B5: 15522 | C5: 15636 | D5: 15752 | E5: 15869 | F5: 15986 | G5: 16103 | H5: 16223 | I5: 16342
A6: 3 | B6: 16486 | C6: 16610 | D6: 16732 | E6: 16856 | F6: 16982 | G6: 17106 | H6: 17234 | I6: 17360
A7: 4 | B7: 17506 | C7: 17636 | D7: 17767 | E7: 17898 | F7: 18031 | G7: 18163 | H7: 18298 | I7: 18433
A8: 5 | B8: 18581 | C8: 18720 | D8: 18858 | E8: 18998 | F8: 19137 | G8: 19280 | H8: 19423 | I8: 19565
A9: 6 | B9: 19710 | C9: 19862 | D9: 20009 | E9: 20158 | F9: 20307 | G9: 20456 | H9: 20609 | I9: 20761
A10: 7 | B10: 20914 | C10: 21069 | D10: 21224 | E10: 21382 | F10: 21539 | G10: 21699 | H10: 21859 | I10: 22022
A11: 8 | B11: 22423 | C11: 22627 | D11: 22832 | E11: 23038 | F11: 23246 | G11: 23456 | H11: 23668 | I11: 23883
A12: 9 | B12: 24329 | C12: 24523 | D12: 24720 | E12: 24917 | F12: 25117 | G12: 25318 | H12: 25521 | I12: 25725
A13: 10 | B13: 26917 | C13: 27131 | D13: 27347 | E13: 27565 | F13: 27786 | G13: 28007 | H13: 28230 | I13: 28456
A14: 11 | B14: 31705 | C14: 31820 | D14: 32109 | E14: 32401 | F14: 32697 | G14: 32998 | H14: 33302 | I14: 33611
A15: 12 | B15: 33947 | C15: 34069 | D15: 34357 | E15: 34648 | F15: 34943 | G15: 35242 | H15: 35544 | I15: 35850
... A35: 32 | B35: 356237 | C35: 363257 | D35: 370418 | E35: 377359 | F35: 384805 | G35: 392400 | H35: 400150 | I35: 408055
A36: 33 | B36: 449157 | C36: 462329

Sheet PAYOUT
A4: ='PER DIVISION'!A4 -> GENERAL PAYROLL FOR THE MONTH OF MARCH 2026
B6: NAME | O6: GSIS | AC6: HDMF (Pag-ibig) | AE6: HDMF | AG6: ATIEA | AL6: AMPCI | AN6: TENANTS | AW6: Provident | BI6: Disallowance
B7: SURNAME | C7: FIRST NAME | D7: MI | E7: ITEM | F7: DIVISION | G7: ITEM NUMBER | H7: DATE OF ORIGINAL APPOINTMENT | I7: DATE OF LAST PROMOTION | J7: SALARY GRADE | K7: STEP | L7: BASIC SALARY | M7: PERA | N7: TOTAL | O7: Life and Retirement (SIC) | P7: Policy Loan (Regular) | Q7: Emerg. Loan | R7: R E L (Housing) | S7: Conso. Loan | T7: Optional Premium (OULI) | U7: Policy Loan (Optional) | V7: MPL | W7: MPL LITE | X7: CPL | Y7: GFAL | Z7: Unutilized Daily Subsistence Allowance | AA7: Withholding Tax | AB7: Philhealth | AC7: MPL/STLRF | AD7: Pag-ibig II/MP2 | AE7: Personal Cont. | AF7: Mobile Phone Amort. | AG7: Monthly Dues | AH7: Loans | AI7: Undeducted Previous Transaction Fee | AJ7: Share | AK7: Healthcard | AL7: Coop Share | AM7: Coop Loans | AN7: Accommodation | AO7: Water Bill | AP7: Electric Bill | AQ7: Repairs | AR7: Security | AS7: Disallowance | AT7: Landbank Loan | AU7: UCPB Loan | AV7: DAMC Loan | AW7: Prov. Fund Share | AX7: Prov. (Healthcard) | AY7: Prov. Fund Loan | AZ7: Total Deductions | BA7: Net Take Home Pay | BB7: 15th | BC7: 30th
A8: 1 | B8: Abcede | C8: Dianne | D8: P. | E8: Agric. I | F8: PAD | G8: OSEC-DAB-AG1-116-2014 | H8: 45376 | I8: 45376 | J8: 11 | K8: 1 | L8: =IFERROR(VLOOKUP(J8, DATA!$A$4:$I$36, MATCH(K8, DATA!$B$3:$I$3, 0)+1, FALSE), "") -> 31705 | M8: 2000 | N8: =L8+M8 -> 33705 | O8: =ROUND(L8*9%,2) -> 2853.45 | AA8: 1468.9 | AB8: =ROUND(IF(L8>79999.99,900,IF(L8<10000.01,137.5,IF(10000<L8>80000,L8*2.5%))),2)-0.01 -> 792.62 | AD8: 1000 | AE8: 200 | AG8: 100 | AN8: 2000 | AO8: 395.48 | AZ8: =ROUND(SUM(O8:AY8),2) -> 8810.45 | BA8: =ROUND(N8-AZ8,2) -> 24894.55 | BB8: =ROUND(BA8/2,2) -> 12447.28 | BC8: =BA8-BB8 -> 12447.27
A9: =A8+1 -> 2 | B9: Aguilar | C9: Roxette Gelyn | D9: R. | E9: PLO I | F9: PPD | G9: OSEC-DAB-PLO1-12-1998 | H9: 45236 | I9: 45236 | J9: 11 | K9: 1 | L9: =IFERROR(VLOOKUP(J9, DATA!$A$4:$I$36, MATCH(K9, DATA!$B$3:$I$3, 0)+1, FALSE), "") -> 31705 | M9: 2000 | N9: =L9+M9 -> 33705 | O9: =ROUND(L9*9%,2) -> 2853.45 | AA9: 1468.9 | AB9: =ROUND(IF(L9>79999.99,900,IF(L9<10000.01,137.5,IF(10000<L9>80000,L9*2.5%))),2)-0.01 -> 792.62 | AE9: 200 | AF9: 0 | AG9: 100 | AN9: 2000 | AP9: 449.15 | AZ9: =ROUND(SUM(O9:AY9),2) -> 7864.12 | BA9: =ROUND(N9-AZ9,2) -> 25840.88 | BB9: =ROUND(BA9/2,2) -> 12920.44 | BC9: =BA9-BB9 -> 12920.44
A10: =A9+1 -> 3 | B10: Alberto | C10: Camilo | D10: M. | E10: DMO I | F10: CDMD | G10: OSEC-DAB-DMO1-125-2014 | H10: 35282 | I10: 42383 | J10: 11 | K10: 4 | L10: =IFERROR(VLOOKUP(J10, DATA!$A$4:$I$36, MATCH(K10, DATA!$B$3:$I$3, 0)+1, FALSE), "") -> 32401 | M10: 2000 | N10: =L10+M10 -> 34401 | O10: =ROUND(L10*9%,2) -> 2916.09 | S10: 3649.18 | AA10: 1587.48 | AB10: =ROUND(IF(L10>79999.99,900,IF(L10<10000.01,137.5,IF(10000<L10>80000,L10*2.5%))),2)-0.01 -> 810.02 | AC10: 6012.73 | AD10: 500 | AE10: 200 | AF10: 0 | AG10: 100 | AM10: 1000 | AS10: 0 | AW10: 0 | AY10: 5162.5 | AZ10: =ROUND(SUM(O10:AY10),2) -> 21938 | BA10: =ROUND(N10-AZ10,2) -> 12463 | BB10: =ROUND(BA10/2,2) -> 6231.5 | BC10: =BA10-BB10 -> 6231.5 | BI10: 0
A11: =A10+1 -> 4 | B11: Alcantara | C11: Justine Ann | D11: C. | E11: DMO I | F11: CDMD | G11: OSEC-DAB-DMO1-129-2014 | H11: 45665 | I11: 45665 | J11: 11 | K11: 1 | L11: =IFERROR(VLOOKUP(J11, DATA!$A$4:$I$36, MATCH(K11, DATA!$B$3:$I$3, 0)+1, FALSE), "") -> 31705 | M11: 2000 | N11: =L11+M11 -> 33705 | O11: =ROUND(L11*9%,2) -> 2853.45 | AA11: 1468.9 | AB11: =ROUND(IF(L11>79999.99,900,IF(L11<10000.01,137.5,IF(10000<L11>80000,L11*2.5%))),2)-0.01 -> 792.62 | AE11: 200 | AG11: 100 | AN11: 2000 | AO11: 461.39 | AP11: 704.35 | AZ11: =ROUND(SUM(O11:AY11),2) -> 8580.71 | BA11: =ROUND(N11-AZ11,2) -> 25124.29 | BB11: =ROUND(BA11/2,2) -> 12562.15 | BC11: =BA11-BB11 -> 12562.14
A12: =A11+1 -> 5 | B12: Alfonso | C12: Cindy | D12: C. | E12: PEO III | F12: PPD | G12: OSEC-DAB-PEO3-55-2014 | H12: 42278 | I12: 45737 | J12: 18 | K12: 1 | L12: =IFERROR(VLOOKUP(J12, DATA!$A$4:$I$36, MATCH(K12, DATA!$B$3:$I$3, 0)+1, FALSE), "") -> 53818 | M12: 2000 | N12: =L12+M12 -> 55818 | O12: =ROUND(L12*9%,2) -> 4843.62 | Y12: 9634.44 | AA12: 5936.18 | AB12: =ROUND(IF(L12>79999.99,900,IF(L12<10000.01,137.5,IF(10000<L12>80000,L12*2.5%))),2) -> 1345.45 | AE12: 200 | AF12: 0 | AG12: 100 | AS12: 500 | AW12: 0 | AZ12: =ROUND(SUM(O12:AY12),2) -> 22559.69 | BA12: =ROUND(N12-AZ12,2) -> 33258.31 | BB12: =ROUND(BA12/2,2) -> 16629.16 | BC12: =BA12-BB12 -> 16629.15 | BI12: 1479.1667
A13: =A12+1 -> 6 | B13: Alforque I | C13: G. Mark Anthony | D13: C | E13: PEO II | F13: PPD | G13: OSEC-DAB-PEO2-13-1998 | H13: 42451 | I13: 44090 | J13: 15 | K13: 2 | L13: =IFERROR(VLOOKUP(J13, DATA!$A$4:$I$36, MATCH(K13, DATA!$B$3:$I$3, 0)+1, FALSE), "") -> 42594 | M13: 2000 | N13: =L13+M13 -> 44594 | O13: =ROUND(L13*9%,2) -> 3833.46 | AA13: 3791.96 | AB13: =ROUND(IF(L13>79999.99,900,IF(L13<10000.01,137.5,IF(10000<L13>80000,L13*2.5%))),2) -> 1064.85 | AD13: 3000 | AE13: 1000 | AF13: 0 | AG13: 100 | AL13: 1000 | AS13: 0 | AW13: 0 | AZ13: =ROUND(SUM(O13:AY13),2) -> 13790.27 | BA13: =ROUND(N13-AZ13,2) -> 30803.73 | BB13: =ROUND(BA13/2,2) -> 15401.87 | BC13: =BA13-BB13 -> 15401.86 | BI13: 637.02083
A14: =A13+1 -> 7 | B14: Alvarez | C14: Clarissa | D14: M. | E14: Adm. Asst. III | F14: AFU-OD | G14: OSEC-DAB-ADAS3-98-2004 | H14: 45700 | I14: 45700 | J14: 9 | K14: 1 | L14: =IFERROR(VLOOKUP(J14, DATA!$A$4:$I$36, MATCH(K14, DATA!$B$3:$I$3, 0)+1, FALSE), "") -> 24329 | M14: 2000 | N14: =L14+M14 -> 26329 | O14: =ROUND(L14*9%,2) -> 2189.61 | AA14: 593.27 | AB14: =ROUND(IF(L14>79999.99,900,IF(L14<10000.01,137.5,IF(10000<L14>80000,L14*2.5%))),2)-0.01 -> 608.22 | AE14: 200 | AF14: 0 | AG14: 100 | AS14: 0 | AW14: 0 | AZ14: =ROUND(SUM(O14:AY14),2) -> 3691.1 | BA14: =ROUND(N14-AZ14,2) -> 22637.9 | BB14: =ROUND(BA14/2,2) -> 11318.95 | BC14: =BA14-BB14 -> 11318.95 | BI14: 578
A15: =A14+1 -> 8 | B15: Alvarez | C15: Mark Nello | D15: B. | E15: Agric. II | F15: PAD | G15: OSEC-DAB-AG2-1317-1998 | H15: 42278 | I15: 44986 | J15: 15 | K15: 1 | L15: =IFERROR(VLOOKUP(J15, DATA!$A$4:$I$36, MATCH(K15, DATA!$B$3:$I$3, 0)+1, FALSE), "") -> 42178 | M15: 2000 | N15: =L15+M15 -> 44178 | O15: =ROUND(L15*9%,2) -> 3796.02 | V15: 9317.65 | AA15: 3695.42 | AB15: =ROUND(IF(L15>79999.99,900,IF(L15<10000.01,137.5,IF(10000<L15>80000,L15*2.5%))),2) -> 1054.45 | AD15: 2000 | AE15: 500 | AF15: 0 | AG15: 100 | AS15: 0 | AZ15: =ROUND(SUM(O15:AY15),2) -> 20463.54 | BA15: =ROUND(N15-AZ15,2) -> 23714.46 | BB15: =ROUND(BA15/2,2) -> 11857.23 | BC15: =BA15-BB15 -> 11857.23 | BI15: 578
A16: =A15+1 -> 9 | B16: Aninacion | C16: Joshua | D16: G. | E16: PLO II | F16: PPD | G16: OSEC-DAB-PLO2-54-2014 | H16: 43549 | I16: 44271 | J16: 15 | K16: 2 | L16: =IFERROR(VLOOKUP(J16, DATA!$A$4:$I$36, MATCH(K16, DATA!$B$3:$I$3, 0)+1, FALSE), "") -> 42594 | M16: 2000 | N16: =L16+M16 -> 44594 | O16: =ROUND(L16*9%,2) -> 3833.46 | AA16: 3791.96 | AB16: =ROUND(IF(L16>79999.99,900,IF(L16<10000.01,137.5,IF(10000<L16>80000,L16*2.5%))),2) -> 1064.85 | AE16: 200 | AF16: 0 | AG16: 100 | AS16: 0 | AZ16: =ROUND(SUM(O16:AY16),2) -> 8990.27 | BA16: =ROUND(N16-AZ16,2) -> 35603.73 | BB16: =ROUND(BA16/2,2) -> 17801.87 | BC16: =BA16-BB16 -> 17801.86
A17: =A16+1 -> 10 | B17: Antipas | C17: Andrea Jane | D17: M. | E17: Adm. Asst. I | F17: ISD | G17: OSEC-DAB-ADAS1-52-2004 | H17: 45376 | I17: 45376 | J17: 7 | K17: 1 | L17: =IFERROR(VLOOKUP(J17, DATA!$A$4:$I$36, MATCH(K17, DATA!$B$3:$I$3, 0)+1, FALSE), "") -> 20914 | M17: 2000 | N17: =L17+M17 -> 22914 | O17: =ROUND(L17*9%,2) -> 1882.26 | AA17: 0 | AB17: =ROUND(IF(L17>79999.99,900,IF(L17<10000.01,137.5,IF(10000<L17>80000,L17*2.5%))),2) -> 522.85 | AD17: 1000 | AE17: 200 | AG17: 100 | AK17: 1000 | AZ17: =ROUND(SUM(O17:AY17),2) -> 4705.11 | BA17: =ROUND(N17-AZ17,2) -> 18208.89 | BB17: =ROUND(BA17/2,2) -> 9104.45 | BC17: =BA17-BB17 -> 9104.44
A18: =A17+1 -> 11 | B18: Arceo | C18: Antonieta | D18: J. | E18: Director III | F18: OD | G18: OSEC-DAB-DIR3-55-1998 | H18: 34243 | I18: 44998 | J18: 27 | K18: 1 | L18: =IFERROR(VLOOKUP(J18, DATA!$A$4:$I$36, MATCH(K18, DATA!$B$3:$I$3, 0)+1, FALSE), "") -> 148940 | M18: 2000 | N18: =L18+M18 -> 150940 | O18: =ROUND(L18*9%,2) -> 13404.6 | P18: 500 | Q18: 655.56 | V18: 21327.3 | W18: 2333.33 | AA18: 33536.75 | AB18: 2500 | AD18: 0 | AE18: 200 | AF18: 3000 | AS18: 0 | AT18: 9470.26 | AW18: 0 | AY18: 7364.14 | AZ18: =ROUND(SUM(O18:AY18),2) -> 94291.94 | BA18: =ROUND(N18-AZ18,2) -> 56648.06 | BB18: =ROUND(BA18/2,2) -> 28324.03 | BC18: =BA18-BB18 -> 28324.03 | BI18: 1979.1667
A19: =A18+1 -> 12 | B19: Balangatan | C19: Jun | D19: G. | E19: OCO II | F19: ISD | G19: OSEC-DAB-OCO2-3-1998 | H19: 34078 | I19: 38628 | J19: 8 | K19: 7 | L19: =IFERROR(VLOOKUP(J19, DATA!$A$4:$I$36, MATCH(K19, DATA!$B$3:$I$3, 0)+1, FALSE), "") -> 23668 | M19: 2000 | N19: =L19+M19 -> 25668 | O19: =ROUND(L19*9%,2) -> 2130.12 | P19: 200 | V19: 4847.84 | AA19: 23.91 | AB19: =ROUND(IF(L19>79999.99,900,IF(L19<10000.01,137.5,IF(10000<L19>80000,L19*2.5%))),2) -> 591.7 | AC19: 4679.53 | AE19: 200 | AF19: 0 | AG19: 100 | AL19: 300 | AM19: 1000 | AS19: 0 | AW19: 0 | AY19: 4325.35 | AZ19: =ROUND(SUM(O19:AY19),2) -> 18398.45 | BA19: =ROUND(N19-AZ19,2) -> 7269.55 | BB19: =ROUND(BA19/2,2) -> 3634.78 | BC19: =BA19-BB19 -> 3634.77 | BI19: 0
A20: =A19+1 -> 13 | B20: Baluyut | C20: Julia Marie | D20: M. | E20: DMO I | F20: CDMD | G20: OSEC-DAB-DMO1-130-2014 | H20: 45376 | I20: 45376 | J20: 11 | K20: 1 | L20: =IFERROR(VLOOKUP(J20, DATA!$A$4:$I$36, MATCH(K20, DATA!$B$3:$I$3, 0)+1, FALSE), "") -> 31705 | M20: 2000 | N20: =L20+M20 -> 33705 | O20: =ROUND(L20*9%,2) -> 2853.45 | AA20: 1468.9 | AB20: =ROUND(IF(L20>79999.99,900,IF(L20<10000.01,137.5,IF(10000<L20>80000,L20*2.5%))),2)-0.01 -> 792.62 | AE20: 200 | AG20: 100 | AZ20: =ROUND(SUM(O20:AY20),2) -> 5414.97 | BA20: =ROUND(N20-AZ20,2) -> 28290.03 | BB20: =ROUND(BA20/2,2) -> 14145.02 | BC20: =BA20-BB20 -> 14145.01
A21: =A20+1 -> 14 | B21: Bautista | C21: Marilyn | D21: J. | E21: SG I | F21: AFU-OD | G21: OSEC-DAB-SECG1-262-1998 | H21: 34121 | I21: 34121 | J21: 3 | K21: 8 | L21: =IFERROR(VLOOKUP(J21, DATA!$A$4:$I$36, MATCH(K21, DATA!$B$3:$I$3, 0)+1, FALSE), "") -> 17360 | M21: 2000 | N21: =L21+M21 -> 19360 | O21: =ROUND(L21*9%,2) -> 1562.4 | Q21: 655.56 | S21: 2100.56 | T21: 0 | U21: 0 | Y21: 2837.17 | AA21: 0 | AB21: =ROUND(IF(L21>79999.99,900,IF(L21<10000.01,137.5,IF(10000<L21>80000,L21*2.5%))),2) -> 434 | AE21: 500 | AF21: 1200 | AG21: 100 | AS21: 1000 | AW21: 0 | AY21: 1820.83 | AZ21: =ROUND(SUM(O21:AY21),2) -> 12210.52 | BA21: =ROUND(N21-AZ21,2) -> 7149.48 | BB21: =ROUND(BA21/2,2) -> 3574.74 | BC21: =BA21-BB21 -> 3574.74 | BI21: 325.4375
A22: =A21+1 -> 15 | B22: Bayot | C22: Czarina | D22: M. | E22: DMO III | F22: CDMD | G22: OSEC-DAB-DMO3-63-2014 | H22: 42451 | I22: 45397 | J22: 18 | K22: 1 | L22: =IFERROR(VLOOKUP(J22, DATA!$A$4:$I$36, MATCH(K22, DATA!$B$3:$I$3, 0)+1, FALSE), "") -> 53818 | M22: 2000 | N22: =L22+M22 -> 55818 | O22: =ROUND(L22*9%,2) -> 4843.62 | AA22: 6395.7 | AB22: =ROUND(IF(L22>79999.99,900,IF(L22<10000.01,137.5,IF(10000<L22>80000,L22*2.5%))),2) -> 1345.45 | AE22: 200 | AF22: 0 | AG22: 100 | AS22: 1135.55 | AX22: 891.15 | AY22: 3034.72 | AZ22: =ROUND(SUM(O22:AY22),2) -> 17946.19 | BA22: =ROUND(N22-AZ22,2) -> 37871.81 | BB22: =ROUND(BA22/2,2) -> 18935.91 | BC22: =BA22-BB22 -> 18935.9 | BI22: 555.55556
A23: =A22+1 -> 16 | B23: Bibit | C23: Darwin | D23: C. | E23: Adm. Asst. II | F23: ISD | G23: OSEC-DAB-ADAS2-98-2004 | H23: 34073 | I23: 34073 | J23: 8 | K23: 8 | L23: =IFERROR(VLOOKUP(J23, DATA!$A$4:$I$36, MATCH(K23, DATA!$B$3:$I$3, 0)+1, FALSE), "") -> 23883 | M23: 2000 | N23: =L23+M23 -> 25883 | O23: =ROUND(L23*9%,2) -> 2149.47 | P23: 320 | S23: 0 | V23: 3558.84 | Y23: 5648.41 | AA23: 73.05 | AB23: =ROUND(IF(L23>79999.99,900,IF(L23<10000.01,137.5,IF(10000<L23>80000,L23*2.5%))),2)-0.01 -> 597.07 | AC23: 1195.45 | AE23: 200 | AF23: 0 | AG23: 100 | AL23: 100 | AM23: 3750 | AO23: 922.78 | AP23: 1408.7 | AS23: 0 | AW23: 0 | AZ23: =ROUND(SUM(O23:AY23),2) -> 20023.77 | BA23: =ROUND(N23-AZ23,2) -> 5859.23 | BB23: =ROUND(BA23/2,2) -> 2929.62 | BC23: =BA23-BB23 -> 2929.61 | BI23: 978.125
A24: =A23+1 -> 17 | B24: Bolon | C24: Richard | D24: E. | E24: Adm. Aide V | F24: AFU-OD | G24: OSEC-DAB-ADA5-17-2004 | H24: 37712 | I24: 37712 | J24: 5 | K24: 8 | L24: =IFERROR(VLOOKUP(J24, DATA!$A$4:$I$36, MATCH(K24, DATA!$B$3:$I$3, 0)+1, FALSE), "") -> 19565 | M24: 2000 | N24: =L24+M24 -> 21565 | O24: =ROUND(L24*9%,2) -> 1760.85 | P24: 300 | Q24: 655.56 | V24: 2698.53 | W24: 1166.67 | Y24: 3372.06 | AA24: 0 | AB24: =ROUND(IF(L24>79999.99,900,IF(L24<10000.01,137.5,IF(10000<L24>80000,L24*2.5%))),2)-0.01 -> 489.12 | AC24: 279.7 | AD24: 0 | AE24: 200 | AF24: 0 | AG24: 100 | AH24: 1336 | AS24: 500 | AW24: 0 | AY24: 2994.22 | AZ24: =ROUND(SUM(O24:AY24),2) -> 15852.71 | BA24: =ROUND(N24-AZ24,2) -> 5712.29 | BB24: =ROUND(BA24/2,2) -> 2856.15 | BC24: =BA24-BB24 -> 2856.14 | BI24: 590.9375
A25: =A24+1 -> 18 | B25: Bombon | C25: Mary Angelyn | D25: P. | E25: DMO II | F25: CDMD | G25: OSEC-DAB-DMO2-62-2014 | H25: 44291 | I25: 45719 | J25: 15 | K25: 1 | L25: =IFERROR(VLOOKUP(J25, DATA!$A$4:$I$36, MATCH(K25, DATA!$B$3:$I$3, 0)+1, FALSE), "") -> 42178 | M25: 2000 | N25: =L25+M25 -> 44178 | O25: =ROUND(L25*9%,2) -> 3796.02 | AA25: 3335.99 | AB25: =ROUND(IF(L25>79999.99,900,IF(L25<10000.01,137.5,IF(10000<L25>80000,L25*2.5%))),2) -> 1054.45 | AE25: 200 | AF25: 0 | AG25: 100 | AS25: 0 | AT25: 6313.51 | AZ25: =ROUND(SUM(O25:AY25),2) -> 14799.97 | BA25: =ROUND(N25-AZ25,2) -> 29378.03 | BB25: =ROUND(BA25/2,2) -> 14689.02 | BC25: =BA25-BB25 -> 14689.01
A26: =A25+1 -> 19 | B26: Borlagdan | C26: Franco Gabriel | D26: P. | E26: ISR III | F26: ISD | G26: OSEC-DAB-INFOSR3-18-2014 | H26: 42451 | I26: 44271 | J26: 17 | K26: 2 | L26: =IFERROR(VLOOKUP(J26, DATA!$A$4:$I$36, MATCH(K26, DATA!$B$3:$I$3, 0)+1, FALSE), "") -> 50066 | M26: 2000 | N26: =L26+M26 -> 52066 | O26: =ROUND(L26*9%,2) -> 4505.94 | AA26: 5537.02 | AB26: =ROUND(IF(L26>79999.99,900,IF(L26<10000.01,137.5,IF(10000<L26>80000,L26*2.5%))),2) -> 1251.65 | AD26: 1000 | AE26: 200 | AF26: 0 | AG26: 100 | AS26: 0 | AW26: 0 | AZ26: =ROUND(SUM(O26:AY26),2) -> 12594.61 | BA26: =ROUND(N26-AZ26,2) -> 39471.39 | BB26: =ROUND(BA26/2,2) -> 19735.7 | BC26: =BA26-BB26 -> 19735.69
A27: =A26+1 -> 20 | B27: Borromeo | C27: Kemuel | D27: M. | E27: DMO III | F27: CDMD | G27: OSEC-DAB-DMO3-61-2014 | H27: 42383 | I27: 45027 | J27: 18 | K27: 1 | L27: =IFERROR(VLOOKUP(J27, DATA!$A$4:$I$36, MATCH(K27, DATA!$B$3:$I$3, 0)+1, FALSE), "") -> 53818 | M27: 2000 | N27: =L27+M27 -> 55818 | O27: =ROUND(L27*9%,2) -> 4843.62 | Q27: 655.56 | V27: 6918.77 | X27: 1966.67 | AA27: 6395.7 | AB27: =ROUND(IF(L27>79999.99,900,IF(L27<10000.01,137.5,IF(10000<L27>80000,L27*2.5%))),2) -> 1345.45 | AD27: 0 | AE27: 1500 | AF27: 0 | AG27: 100 | AL27: 500 | AS27: 707.29 | AY27: 6165.86 | AZ27: =ROUND(SUM(O27:AY27),2) -> 31098.92 | BA27: =ROUND(N27-AZ27,2) -> 24719.08 | BB27: =ROUND(BA27/2,2) -> 12359.54 | BC27: =BA27-BB27 -> 12359.54 | BI27: 763.34722
A28: =A27+1 -> 21 | B28: Bunda | C28: Arnel | D28: R. | E28: PLO I | F28: PPD | G28: OSEC-DAB-PLO1-1-1998 | H28: 42278 | I28: 42278 | J28: 11 | K28: 4 | L28: =IFERROR(VLOOKUP(J28, DATA!$A$4:$I$36, MATCH(K28, DATA!$B$3:$I$3, 0)+1, FALSE), "") -> 32401 | M28: 2000 | N28: =L28+M28 -> 34401 | O28: =ROUND(L28*9%,2) -> 2916.09 | Q28: 1152.41 | V28: 4165.63 | W28: 1166.67 | AA28: 1587.48 | AB28: =ROUND(IF(L28>79999.99,900,IF(L28<10000.01,137.5,IF(10000<L28>80000,L28*2.5%))),2)-0.01 -> 810.02 | AD28: 0 | AE28: 200 | AF28: 0 | AG28: 100 | AL28: 100 | AS28: 0 | AW28: 0 | AZ28: =ROUND(SUM(O28:AY28),2) -> 12198.3 | BA28: =ROUND(N28-AZ28,2) -> 22202.7 | BB28: =ROUND(BA28/2,2) -> 11101.35 | BC28: =BA28-BB28 -> 11101.35 | BI28: 0
A29: =A28+1 -> 22 | B29: Calasagsag | C29: Joeven | D29: C. | E29: Supervising Agric. | F29: PAD | G29: OSEC-DAB-SVAG-105-1998 | H29: 42278 | I29: 45607 | J29: 22 | K29: 1 | L29: =IFERROR(VLOOKUP(J29, DATA!$A$4:$I$36, MATCH(K29, DATA!$B$3:$I$3, 0)+1, FALSE), "") -> 81796 | M29: 2000 | N29: =L29+M29 -> 83796 | O29: =ROUND(L29*9%,2) -> 7361.64 | AA29: 13765.43 | AB29: =L29*2.5% -> 2044.9 | AD29: 0 | AE29: 500 | AG29: 100 | AL29: 500 | AS29: 388.51 | AW29: 0 | AX29: 1201.31 | AY29: 3034.72 | AZ29: =ROUND(SUM(O29:AY29),2) -> 28896.51 | BA29: =ROUND(N29-AZ29,2) -> 54899.49 | BB29: =ROUND(BA29/2,2) -> 27449.75 | BC29: =BA29-BB29 -> 27449.74 | BI29: 339.58333
A30: =A29+1 -> 23 | B30: Canilang | C30: Ashlee | D30: P. | E30: MPS II | F30: ISD | G30: OSEC-DAB-MPXS2-19-2014 | H30: 43481 | I30: 45027 | J30: 15 | K30: 1 | L30: =IFERROR(VLOOKUP(J30, DATA!$A$4:$I$36, MATCH(K30, DATA!$B$3:$I$3, 0)+1, FALSE), "") -> 42178 | M30: 2000 | N30: =L30+M30 -> 44178 | O30: =ROUND(L30*9%,2) -> 3796.02 | Q30: 1311.12 | V30: 5422.38 | W30: 1400 | X30: 1966.67 | AA30: 3695.42 | AB30: =ROUND(IF(L30>79999.99,900,IF(L30<10000.01,137.5,IF(10000<L30>80000,L30*2.5%))),2) -> 1054.45 | AC30: 984.58 | AD30: 1000 | AE30: 200 | AF30: 0 | AG30: 100 | AN30: 2000 | AO30: 527.3 | AP30: 272.21 | AS30: 0 | AW30: 0 | AY30: 3034.72 | AZ30: =ROUND(SUM(O30:AY30),2) -> 26764.87 | BA30: =ROUND(N30-AZ30,2) -> 17413.13 | BB30: =ROUND(BA30/2,2) -> 8706.57 | BC30: =BA30-BB30 -> 8706.56 | BI30: 0
A31: =A30+1 -> 24 | B31: Cosico | C31: Theresa Aurora | D31: B. | E31: DMO III | F31: CDMD | G31: OSEC-DAB-DMO3-62-2014 | H31: 37494 | I31: 42278 | J31: 18 | K31: 4 | L31: =IFERROR(VLOOKUP(J31, DATA!$A$4:$I$36, MATCH(K31, DATA!$B$3:$I$3, 0)+1, FALSE), "") -> 55499 | M31: 2000 | N31: =L31+M31 -> 57499 | O31: =ROUND(L31*9%,2) -> 4994.91 | P31: 300 | Q31: 1311.12 | R31: 2040.79 | T31: 263.21 | U31: 500 | V31: 8242.67 | W31: 2333.33 | X31: 1966.67 | AA31: 6798.6 | AB31: =ROUND(IF(L31>79999.99,900,IF(L31<10000.01,137.5,IF(10000<L31>80000,L31*2.5%))),2)-0.01 -> 1387.47 | AC31: 2509.62 | AE31: 200 | AG31: 100 | AL31: 100 | AM31: 1000 | AS31: 0 | AW31: 0 | AX31: 2024.84 | AY31: 5608.24 | AZ31: =ROUND(SUM(O31:AY31),2) -> 41681.47 | BA31: =ROUND(N31-AZ31,2) -> 15817.53 | BB31: =ROUND(BA31/2,2) -> 7908.77 | BC31: =BA31-BB31 -> 7908.76 | BI31: 555.55556
A32: =A31+1 -> 25 | B32: Dacillo | C32: Edmer | D32: B. | E32: CMT II | F32: ISD | G32: OSEC-DAB-CTMT2-50-2014 | H32: 44418 | I32: 45062 | J32: 15 | K32: 1 | L32: =IFERROR(VLOOKUP(J32, DATA!$A$4:$I$36, MATCH(K32, DATA!$B$3:$I$3, 0)+1, FALSE), "") -> 42178 | M32: 2000 | N32: =L32+M32 -> 44178 | O32: =ROUND(L32*9%,2) -> 3796.02 | AA32: 3695.42 | AB32: =ROUND(IF(L32>79999.99,900,IF(L32<10000.01,137.5,IF(10000<L32>80000,L32*2.5%))),2) -> 1054.45 | AE32: 200 | AF32: 0 | AG32: 100 | AY32: 3034.72 | AZ32: =ROUND(SUM(O32:AY32),2) -> 11880.61 | BA32: =ROUND(N32-AZ32,2) -> 32297.39 | BB32: =ROUND(BA32/2,2) -> 16148.7 | BC32: =BA32-BB32 -> 16148.69
A33: =A32+1 -> 26 | B33: Datuin | C33: Jejorian | D33: Q. | E33: DMO II | F33: CDMD | G33: OSEC-DAB-DMO2-67-2014 | H33: 42348 | I33: 43466 | J33: 15 | K33: 3 | L33: =IFERROR(VLOOKUP(J33, DATA!$A$4:$I$36, MATCH(K33, DATA!$B$3:$I$3, 0)+1, FALSE), "") -> 43015 | M33: 2000 | N33: =L33+M33 -> 45015 | O33: =ROUND(L33*9%,2) -> 3871.35 | Y33: 9634.44 | AA33: 3889.58 | AB33: =ROUND(IF(L33>79999.99,900,IF(L33<10000.01,137.5,IF(10000<L33>80000,L33*2.5%))),2)-0.01 -> 1075.37 | AE33: 200 | AF33: 0 | AG33: 100 | AS33: 0 | AX33: 930.05 | AZ33: =ROUND(SUM(O33:AY33),2) -> 19700.79 | BA33: =ROUND(N33-AZ33,2) -> 25314.21 | BB33: =ROUND(BA33/2,2) -> 12657.11 | BC33: =BA33-BB33 -> 12657.1 | BI33: 555.55556
A34: =A33+1 -> 27 | B34: de la Cruz | C34: Roy Son | D34: R. | E34: PLO III | F34: PPD | G34: OSEC-DAB-PLO3-3-1998 | H34: 42348 | I34: 46027 | J34: 18 | K34: 1 | L34: =IFERROR(VLOOKUP(J34, DATA!$A$4:$I$36, MATCH(K34, DATA!$B$3:$I$3, 0)+1, FALSE), "") -> 53818 | M34: 2000 | N34: =L34+M34 -> 55818 | O34: =ROUND(L34*9%,2) -> 4843.62 | V34: 1101.28 | W34: 1400 | Y34: 9634.44 | AA34: 6974.58 | AB34: =ROUND(IF(L34>79999.99,900,IF(L34<10000.01,137.5,IF(10000<L34>80000,L34*2.5%))),2) -> 1345.45 | AD34: 0 | AE34: 500 | AF34: 0 | AG34: 100 | AH34: 1336 | AS34: 910.34 | AW34: 0 | AY34: 2124.3 | AZ34: =ROUND(SUM(O34:AY34),2) -> 30270.01 | BA34: =ROUND(N34-AZ34,2) -> 25547.99 | BB34: =ROUND(BA34/2,2) -> 12774 | BC34: =BA34-BB34 -> 12773.99 | BI34: 465.88021
A35: =A34+1 -> 28 | B35: de Mesa | C35: Maria Carmina | D35: M. | E35: Agric. I | F35: PAD | G35: OSEC-DAB-AG1-162-1998 | H35: 42998 | I35: 42998 | J35: 11 | K35: 3 | L35: =IFERROR(VLOOKUP(J35, DATA!$A$4:$I$36, MATCH(K35, DATA!$B$3:$I$3, 0)+1, FALSE), "") -> 32109 | M35: 2000 | N35: =L35+M35 -> 34109 | O35: =ROUND(L35*9%,2) -> 2889.81 | V35: 4126.25 | Y35: 9634.44 | AA35: 1537.23 | AB35: =ROUND(IF(L35>79999.99,900,IF(L35<10000.01,137.5,IF(10000<L35>80000,L35*2.5%))),2)-0.01 -> 802.72 | AE35: 200 | AF35: 0 | AG35: 100 | AS35: 0 | AW35: 0 | AZ35: =ROUND(SUM(O35:AY35),2) -> 19290.45 | BA35: =ROUND(N35-AZ35,2) -> 14818.55 | BB35: =ROUND(BA35/2,2) -> 7409.28 | BC35: =BA35-BB35 -> 7409.27 | BI35: 0
A36: =A35+1 -> 29 | B36: dela Cuadra | C36: Jovanee | D36: S. | E36: Agric. II | F36: PAD | G36: OSEC-DAB-AG2-1328-1998 | H36: 42278 | I36: 42278 | J36: 15 | K36: 4 | L36: =IFERROR(VLOOKUP(J36, DATA!$A$4:$I$36, MATCH(K36, DATA!$B$3:$I$3, 0)+1, FALSE), "") -> 43442 | M36: 2000 | N36: =L36+M36 -> 45442 | O36: =ROUND(L36*9%,2) -> 3909.78 | P36: 500 | Q36: 655.56 | V36: 5041 | X36: 1966.67 | AA36: 3998.79 | AB36: =ROUND(IF(L36>79999.99,900,IF(L36<10000.01,137.5,IF(10000<L36>80000,L36*2.5%))),2) -> 1086.05 | AC36: 667.35 | AD36: 1000 | AE36: 200 | AF36: 0 | AG36: 100 | AH36: 1336 | AS36: 1000 | AT36: 4735.13 | AW36: 0 | AY36: 3034.72 | AZ36: =ROUND(SUM(O36:AY36),2) -> 29231.05 | BA36: =ROUND(N36-AZ36,2) -> 16210.95 | BB36: =ROUND(BA36/2,2) -> 8105.48 | BC36: =BA36-BB36 -> 8105.47 | BI36: 462.33333
A37: =A36+1 -> 30 | B37: dela Torre | C37: Julrose | D37: H. | E37: IO II | F37: ISD | G37: OSEC-DAB-INFO2-25-1998 | H37: 43468 | I37: 45670 | J37: 15 | K37: 1 | L37: =IFERROR(VLOOKUP(J37, DATA!$A$4:$I$36, MATCH(K37, DATA!$B$3:$I$3, 0)+1, FALSE), "") -> 42178 | M37: 2000 | N37: =L37+M37 -> 44178 | O37: =ROUND(L37*9%,2) -> 3796.02 | P37: 500 | Q37: 1311.12 | V37: 5422.38 | W37: 1400 | X37: 1966.67 | AA37: 3695.42 | AB37: =ROUND(IF(L37>79999.99,900,IF(L37<10000.01,137.5,IF(10000<L37>80000,L37*2.5%))),2) -> 1054.45 | AE37: 200 | AF37: 0 | AG37: 100 | AS37: 0 | AT37: 7180.79 | AW37: 0 | AY37: 4552.08 | AZ37: =ROUND(SUM(O37:AY37),2) -> 31178.93 | BA37: =ROUND(N37-AZ37,2) -> 12999.07 | BB37: =ROUND(BA37/2,2) -> 6499.54 | BC37: =BA37-BB37 -> 6499.53 | BI37: 0
A38: =A37+1 -> 31 | B38: Dellava | C38: Robert | D38: D. | E38: SG I | F38: AFU-OD | G38: OSEC-DAB-SECG1-258-1998 | H38: 37712 | I38: 37712 | J38: 3 | K38: 8 | L38: =IFERROR(VLOOKUP(J38, DATA!$A$4:$I$36, MATCH(K38, DATA!$B$3:$I$3, 0)+1, FALSE), "") -> 17360 | M38: 2000 | N38: =L38+M38 -> 19360 | O38: =ROUND(L38*9%,2) -> 1562.4 | P38: 200 | V38: 2600.69 | AA38: 0 | AB38: =ROUND(IF(L38>79999.99,900,IF(L38<10000.01,137.5,IF(10000<L38>80000,L38*2.5%))),2) -> 434 | AC38: 3737.95 | AD38: 500 | AE38: 200 | AF38: 0 | AG38: 100 | AL38: 100 | AM38: 500 | AS38: 400 | AW38: 0 | AY38: 3034.72 | AZ38: =ROUND(SUM(O38:AY38),2) -> 13369.76 | BA38: =ROUND(N38-AZ38,2) -> 5990.24 | BB38: =ROUND(BA38/2,2) -> 2995.12 | BC38: =BA38-BB38 -> 2995.12 | BI38: 452.04167
A39: =A38+1 -> 32 | B39: delos Santos | C39: Josefina | D39: M. | E39: AO I | F39: AFU-OD | G39: OSEC-DAB-ADOF1-75-2004 | H39: 35786 | I39: 45737 | J39: 10 | K39: 1 | L39: =IFERROR(VLOOKUP(J39, DATA!$A$4:$I$36, MATCH(K39, DATA!$B$3:$I$3, 0)+1, FALSE), "") -> 26917 | M39: 2000 | N39: =L39+M39 -> 28917 | O39: =ROUND(L39*9%,2) -> 2422.53 | P39: 400 | Q39: 1191.88 | V39: 3986.18 | X39: 1966.67 | Y39: 2505.4 | AA39: 447.46 | AB39: =ROUND(IF(L39>79999.99,900,IF(L39<10000.01,137.5,IF(10000<L39>80000,L39*2.5%))),2)-0.01 -> 672.92 | AD39: 0 | AE39: 300 | AF39: 0 | AG39: 100 | AL39: 100 | AS39: 0 | AT39: 3156.75 | AW39: 0 | AY39: 3034.72 | AZ39: =ROUND(SUM(O39:AY39),2) -> 20284.51 | BA39: =ROUND(N39-AZ39,2) -> 8632.49 | BB39: =ROUND(BA39/2,2) -> 4316.25 | BC39: =BA39-BB39 -> 4316.24 | BI39: 635.66667
A40: =A39+1 -> 33 | B40: Deñado | C40: Emerson | D40: R. | E40: Agric. II | F40: ISD | G40: OSEC-DAB-AG2-968-1998 | H40: 42451 | I40: 42998 | J40: 15 | K40: 3 | L40: =IFERROR(VLOOKUP(J40, DATA!$A$4:$I$36, MATCH(K40, DATA!$B$3:$I$3, 0)+1, FALSE), "") -> 43015 | M40: 2000 | N40: =L40+M40 -> 45015 | O40: =ROUND(L40*9%,2) -> 3871.35 | AA40: 3889.58 | AB40: =ROUND(IF(L40>79999.99,900,IF(L40<10000.01,137.5,IF(10000<L40>80000,L40*2.5%))),2)-0.01 -> 1075.37 | AD40: 1000 | AE40: 200 | AF40: 0 | AG40: 100 | AL40: 100 | AM40: 7500 | AN40: 2000 | AO40: 527.3 | AP40: 272.21 | AS40: 0 | AU40: 14749.76 | AY40: 3034.72 | AZ40: =ROUND(SUM(O40:AY40),2) -> 38320.29 | BA40: =ROUND(N40-AZ40,2) -> 6694.71 | BB40: =ROUND(BA40/2,2) -> 3347.36 | BC40: =BA40-BB40 -> 3347.35 | BI40: 489.58333
A41: =A40+1 -> 34 | B41: Dreje | C41: Sherrie | D41: C. | E41: Sr. Agric. | F41: PAD | G41: OSEC-DAB-SRAG-162-1998 | H41: 42278 | I41: 44929 | J41: 18 | K41: 2 | L41: =IFERROR(VLOOKUP(J41, DATA!$A$4:$I$36, MATCH(K41, DATA!$B$3:$I$3, 0)+1, FALSE), "") -> 54371 | M41: 2000 | N41: =L41+M41 -> 56371 | O41: =ROUND(L41*9%,2) -> 4893.39 | Y41: 8646.86 | AA41: 6395.7 | AB41: =ROUND(IF(L41>79999.99,900,IF(L41<10000.01,137.5,IF(10000<L41>80000,L41*2.5%))),2) -> 1359.28 | AE41: 500 | AF41: 0 | AG41: 100 | AK41: 1000 | AN41: 2000 | AO41: 461.39 | AP41: 704.35 | AS41: 0 | AW41: 0 | AY41: 5826.67 | AZ41: =ROUND(SUM(O41:AY41),2) -> 31887.64 | BA41: =ROUND(N41-AZ41,2) -> 24483.36 | BB41: =ROUND(BA41/2,2) -> 12241.68 | BC41: =BA41-BB41 -> 12241.68 | BI41: 1630.3889
A42: =A41+1 -> 35 | B42: Drueco | C42: Janina | D42: G. | E42: DMO II | F42: CDMD | G42: OSEC-DAB-DMO2-60-2014 | H42: 42293 | I42: 42293 | J42: 15 | K42: 4 | L42: =IFERROR(VLOOKUP(J42, DATA!$A$4:$I$36, MATCH(K42, DATA!$B$3:$I$3, 0)+1, FALSE), "") -> 43442 | M42: 2000 | N42: =L42+M42 -> 45442 | O42: =ROUND(L42*9%,2) -> 3909.78 | AA42: 3998.79 | AB42: =ROUND(IF(L42>79999.99,900,IF(L42<10000.01,137.5,IF(10000<L42>80000,L42*2.5%))),2) -> 1086.05 | AD42: 0 | AE42: 200 | AF42: 0 | AG42: 100 | AS42: 1420.64 | AW42: 0 | AX42: 1476.39 | AZ42: =ROUND(SUM(O42:AY42),2) -> 12191.65 | BA42: =ROUND(N42-AZ42,2) -> 33250.35 | BB42: =ROUND(BA42/2,2) -> 16625.18 | BC42: =BA42-BB42 -> 16625.17 | BI42: 620.20681
A43: =A42+1 -> 36 | B43: Espeña | C43: God Rick | D43: M. | E43: PDO I | F43: PPD | G43: OSEC-DAB-PDO1-60-2014 | H43: 44228 | I43: 44228 | J43: 11 | K43: 2 | L43: =IFERROR(VLOOKUP(J43, DATA!$A$4:$I$36, MATCH(K43, DATA!$B$3:$I$3, 0)+1, FALSE), "") -> 31820 | M43: 2000 | N43: =L43+M43 -> 33820 | O43: =ROUND(L43*9%,2) -> 2863.8 | AA43: 1481.83 | AB43: =ROUND(IF(L43>79999.99,900,IF(L43<10000.01,137.5,IF(10000<L43>80000,L43*2.5%))),2) -> 795.5 | AE43: 200 | AF43: 0 | AG43: 100 | AS43: 0 | AZ43: =ROUND(SUM(O43:AY43),2) -> 5441.13 | BA43: =ROUND(N43-AZ43,2) -> 28378.87 | BB43: =ROUND(BA43/2,2) -> 14189.44 | BC43: =BA43-BB43 -> 14189.43
A44: =A43+1 -> 37 | B44: Estoesta | C44: Dominador | D44: N. | E44: Adm. Aide IV | F44: AFU-OD | G44: OSEC-DAB-ADA4-412-2004 | H44: 34704 | I44: 34704 | J44: 4 | K44: 8 | L44: =IFERROR(VLOOKUP(J44, DATA!$A$4:$I$36, MATCH(K44, DATA!$B$3:$I$3, 0)+1, FALSE), "") -> 18433 | M44: 2000 | N44: =L44+M44 -> 20433 | O44: =ROUND(L44*9%,2) -> 1658.97 | P44: 200 | Q44: 655.56 | V44: 2561.74 | Y44: 3797.05 | AA44: 0 | AB44: =ROUND(IF(L44>79999.99,900,IF(L44<10000.01,137.5,IF(10000<L44>80000,L44*2.5%))),2)-0.01 -> 460.82 | AC44: 1295.63 | AD44: 0 | AE44: 200 | AF44: 0 | AG44: 100 | AH44: 1336 | AS44: 0 | AW44: 0 | AY44: 2124.3 | AZ44: =ROUND(SUM(O44:AY44),2) -> 14390.07 | BA44: =ROUND(N44-AZ44,2) -> 6042.93 | BB44: =ROUND(BA44/2,2) -> 3021.47 | BC44: =BA44-BB44 -> 3021.46 | BI44: 580.16667
...
