Workbook

Sheet MASTER DATA
A2: JOB ORDER GENERAL PAYROLL
A3: For The Period of
A4: 02-16-28-2026
A6: No. | B6: ORS Number | C6: ORS Date | E6: Name | F6: Office | G6: Position | H6: Salary Grade | I6: FUND SOURCE | J6: W/ ANNEX B2 | K6: 4th QTR. Work Schedule - | M6: Monthly Rate | N6: Quincena | O6: Daily Rate | P6: Per Hour | Q6: Per Minute | R6: Working Days | S6: Basic Salary | T6: 02-01-15-2026 | W6: =T6 -> 02-01-15-2026 | Z6: 02-16-28-2026 | AC6: =Z6 -> 02-16-28-2026 | AO6: Total | AP6: Other Deduction | AR6: Gross Amount | AS6: Withholding Tax | AU6: Deductions | AY6: Net Pay | AZ6: Remarks
T7: IN PESO | U7: Late / Under Time | W7: IN PESO | X7: Late / Under Time | Z7: IN PESO | AA7: Late / Under Time | AC7: IN PESO | AD7: Late / Under Time | AG7: Late / Under Time | AI7: IN PESO | AJ7: Late / Under Time | AM7: Late / Under Time | AP7: Clothing and Others | AQ7: Remarks | AS7: EXPANDED | AT7: PERCENTAGE | AU7: Accommodation (Staff house) | AV7: Water (Staff house) | AW7: Electricity (Staff house) | AX7: Repairs
K8: Time In | L8: Time Out | T8: Absent | U8: Hour | V8: Minute | W8: Absent | X8: Hour | Y8: Minute | Z8: Absent | AA8: Hour | AB8: Minute | AC8: Absent | AD8: Hour | AE8: Minute | AF8: Absent | AG8: Hour | AH8: Minute | AI8: Absent | AJ8: Hour | AK8: Minute | AL8: Absent | AM8: Hour | AN8: Minute | AS8: 0.02 | AT8: 0.1
A9: 1 | B9: 2 | C9: 3 | D9: 4 | E9: 5 | F9: 6 | G9: 7 | H9: 8 | L9: 10 | M9: 11 | N9: 12 | O9: 13 | P9: 14 | Q9: 15 | R9: 16 | S9: 17 | T9: 18 | U9: 19 | V9: 20 | W9: 21 | X9: 22 | Y9: 23 | Z9: 24 | AA9: 25 | AB9: 26 | AC9: 27 | AD9: 28 | AE9: 29 | AF9: 24 | AG9: 25 | AH9: 26 | AJ9: 28 | AK9: 29 | AM9: 31 | AN9: 32 | AO9: 33 | AP9: 34 | AQ9: 35 | AR9: 36 | AS9: 37 | AT9: 38 | AU9: 39 | AV9: 40 | AX9: 41 | AY9: 42 | AZ9: 43
A10: =IF(B10="","",COUNTA($B$10:B10)) -> 1 | B10: 2026-01-0016 | C10: 46036 | E10: AUSTRIA, CHRISTIAN JOCEF B. | F10: CDMD | G10: Administrative Asst. II | H10: =IF(AZ10="Payroll",VLOOKUP(E10,'[2]CODE 2'!$R:$S,2,FALSE),"0") -> 8 | I10: O. ESETS | J10: OK | M10: =IFERROR(VLOOKUP($H10,'[2]CODE 2'!$J:$K,2,FALSE)," ") -> 19744 | N10: =IFERROR(ROUND((M10/2),2),"") -> 9872 | O10: =IFERROR((M10/22)," ") -> 897.45455 | P10: =IFERROR((O10/8),"") -> 112.18182 | Q10: =IFERROR((P10/60),"") -> 1.869697 | R10: =IF(AZ10="Payroll","11","") -> 11 | S10: =IFERROR(ROUND((O10*R10),2)," ") -> 9872 | T10: 0 | U10: 0 | V10: 0 | W10: =IFERROR(ROUND(($O10*$T10),2)," ") -> 0 | X10: =IFERROR(ROUND(($P10*$U10),2),"") -> 0 | Y10: =IFERROR(ROUND(($Q10*$V10),2),"") -> 0 | AC10: =IFERROR(ROUND(($O10*$Z10),2)," ") -> 0 | AD10: =IFERROR(ROUND(($P10*$AA10),2),"") -> 0 | AE10: =IFERROR(ROUND(($Q10*$AB10),2),"") -> 0 | AI10: =IFERROR(ROUND(($O10*$AF10),2)," ") -> 0 | AJ10: =IFERROR(ROUND(($P10*$AG10),2),"") -> 0 | AK10: =IFERROR(ROUND(($Q10*$AH10),2),"") -> 0 | AL10: =IFERROR(ROUND(($W10+$AC10+$AI10),2),"") -> 0 | AM10: =IFERROR(ROUND(($X10+$AD10+$AJ10),2),"") -> 0 | AN10: =IFERROR(ROUND(($Y10+$AE10+$AK10),2),"") -> 0 | AO10: =SUM(AL10:AN10) -> 0 | AR10: =IFERROR(ROUND((S10-AO10-AP10),2),"") -> 9872 | AY10: =IFERROR(ROUND((AR10-AS10-AT10-AU10-AV10-AW10-AX10),2),"") -> 9872 | AZ10: Payroll | BA10: AGUAS, DERICKE DUANE C.
A11: =IF(B11="","",COUNTA($B$10:B11)) -> 2 | B11: 2026-01-0014 | C11: 46036 | E11: PASTOR, JANELLE E. | F11: CDMD | G11: Development Management Officer I | H11: =IF(AZ11="Payroll",VLOOKUP(E11,'[2]CODE 2'!$R:$S,2,FALSE),"0") -> 11 | I11: O. ESETS | J11: OK | M11: =IFERROR(VLOOKUP($H11,'[2]CODE 2'!$J:$K,2,FALSE)," ") -> 27000 | N11: =IFERROR(ROUND((M11/2),2),"") -> 13500 | O11: =IFERROR((M11/22)," ") -> 1227.2727 | P11: =IFERROR((O11/8),"") -> 153.40909 | Q11: =IFERROR((P11/60),"") -> 2.5568182 | R11: 11 | S11: =IFERROR(ROUND((O11*R11),2)," ") -> 13500 | T11: 0 | U11: 0 | V11: 0 | W11: =IFERROR(ROUND(($O11*$T11),2)," ") -> 0 | X11: =IFERROR(ROUND(($P11*$U11),2),"") -> 0 | Y11: =IFERROR(ROUND(($Q11*$V11),2),"") -> 0 | AC11: =IFERROR(ROUND(($O11*$Z11),2)," ") -> 0 | AD11: =IFERROR(ROUND(($P11*$AA11),2),"") -> 0 | AE11: =IFERROR(ROUND(($Q11*$AB11),2),"") -> 0 | AI11: =IFERROR(ROUND(($O11*$AF11),2)," ") -> 0 | AJ11: =IFERROR(ROUND(($P11*$AG11),2),"") -> 0 | AK11: =IFERROR(ROUND(($Q11*$AH11),2),"") -> 0 | AL11: =IFERROR(ROUND(($W11+$AC11+$AI11),2),"") -> 0 | AM11: =IFERROR(ROUND(($X11+$AD11+$AJ11),2),"") -> 0 | AN11: =IFERROR(ROUND(($Y11+$AE11+$AK11),2),"") -> 0 | AO11: =SUM(AL11:AN11) -> 0 | AR11: =IFERROR(ROUND((S11-AO11-AP11),2),"") -> 13500 | AY11: =IFERROR(ROUND((AR11-AS11-AT11-AU11-AV11-AW11-AX11),2),"") -> 13500 | AZ11: Payroll | BA11: AGUSTIN, PAULYN B.
A12: =IF(B12="","",COUNTA($B$10:B12)) -> 3 | B12: 2026-01-0015 | C12: 46036 | E12: RODRIGUEZ, MA. RUFFA A. | F12: CDMD | G12: Development Management Officer II | H12: 15 | I12: O. ESETS | J12: OK | M12: =IFERROR(VLOOKUP($H12,'[2]CODE 2'!$J:$K,2,FALSE)," ") -> 36619 | N12: =IFERROR(ROUND((M12/2),2),"") -> 18309.5 | O12: =IFERROR((M12/22)," ") -> 1664.5 | P12: =IFERROR((O12/8),"") -> 208.0625 | Q12: =IFERROR((P12/60),"") -> 3.4677083 | R12: 11 | S12: =IFERROR(ROUND((O12*R12),2)," ") -> 18309.5 | T12: 0 | U12: 0 | V12: 0 | W12: =IFERROR(ROUND(($O12*$T12),2)," ") -> 0 | X12: =IFERROR(ROUND(($P12*$U12),2),"") -> 0 | Y12: =IFERROR(ROUND(($Q12*$V12),2),"") -> 0 | AC12: =IFERROR(ROUND(($O12*$Z12),2)," ") -> 0 | AD12: =IFERROR(ROUND(($P12*$AA12),2),"") -> 0 | AE12: =IFERROR(ROUND(($Q12*$AB12),2),"") -> 0 | AI12: =IFERROR(ROUND(($O12*$AF12),2)," ") -> 0 | AJ12: =IFERROR(ROUND(($P12*$AG12),2),"") -> 0 | AK12: =IFERROR(ROUND(($Q12*$AH12),2),"") -> 0 | AL12: =IFERROR(ROUND(($W12+$AC12+$AI12),2),"") -> 0 | AM12: =IFERROR(ROUND(($X12+$AD12+$AJ12),2),"") -> 0 | AN12: =IFERROR(ROUND(($Y12+$AE12+$AK12),2),"") -> 0 | AO12: =SUM(AL12:AN12) -> 0 | AR12: =IFERROR(ROUND((S12-AO12-AP12),2),"") -> 18309.5 | AY12: =IFERROR(ROUND((AR12-AS12-AT12-AU12-AV12-AW12-AX12),2),"") -> 18309.5 | AZ12: Payroll | BA12: AKUT, FILSAN G.
A13: =IF(B13="","",COUNTA($B$10:B13)) -> 4 | B13: 2026-01-0002 | C13: 46035 | E13: OQUINDO, SHEILA JANE G. | F13: CDMD | G13: Development Management Officer I | H13: =IF(AZ13="Payroll",VLOOKUP(E13,'[2]CODE 2'!$R:$S,2,FALSE),"0") -> 0 | I13: CFIDP | J13: OK | M13: =IFERROR(VLOOKUP($H13,'[2]CODE 2'!$J:$K,2,FALSE)," ") | N13: =IFERROR(ROUND((M13/2),2),"") | O13: =IFERROR((M13/22)," ") | P13: =IFERROR((O13/8),"") | Q13: =IFERROR((P13/60),"") | R13: 11 | S13: =IFERROR(ROUND((O13*R13),2)," ") | T13: 0 | U13: 0 | V13: 0 | W13: =IFERROR(ROUND(($O13*$T13),2)," ") | X13: =IFERROR(ROUND(($P13*$U13),2),"") | Y13: =IFERROR(ROUND(($Q13*$V13),2),"") | AC13: =IFERROR(ROUND(($O13*$Z13),2)," ") | AD13: =IFERROR(ROUND(($P13*$AA13),2),"") | AE13: =IFERROR(ROUND(($Q13*$AB13),2),"") | AI13: =IFERROR(ROUND(($O13*$AF13),2)," ") | AJ13: =IFERROR(ROUND(($P13*$AG13),2),"") | AK13: =IFERROR(ROUND(($Q13*$AH13),2),"") | AL13: =IFERROR(ROUND(($W13+$AC13+$AI13),2),"") | AM13: =IFERROR(ROUND(($X13+$AD13+$AJ13),2),"") | AN13: =IFERROR(ROUND(($Y13+$AE13+$AK13),2),"") | AO13: =SUM(AL13:AN13) -> 0 | AR13: =IFERROR(ROUND((S13-AO13-AP13),2),"") | AY13: =IFERROR(ROUND((AR13-AS13-AT13-AU13-AV13-AW13-AX13),2),"") | AZ13: Voucher | BA13: AMBROSIO, JOHN HAROLD F.
A14: =IF(B14="","",COUNTA($B$10:B14)) -> 5 | B14: 2026-01-0017 | C14: 46036 | E14: ESMER, GLECY R. | F14: PPD | G14: Administrative Asst. II | H14: =IF(AZ14="Payroll",VLOOKUP(E14,'[2]CODE 2'!$R:$S,2,FALSE),"0") -> 8 | I14: O. ESETS | J14: OK | M14: =IFERROR(VLOOKUP($H14,'[2]CODE 2'!$J:$K,2,FALSE)," ") -> 19744 | N14: =IFERROR(ROUND((M14/2),2),"") -> 9872 | O14: =IFERROR((M14/22)," ") -> 897.45455 | P14: =IFERROR((O14/8),"") -> 112.18182 | Q14: =IFERROR((P14/60),"") -> 1.869697 | R14: =IF(AZ14="Payroll","11","") -> 11 | S14: =IFERROR(ROUND((O14*R14),2)," ") -> 9872 | T14: 0 | U14: 0 | V14: 0 | W14: =IFERROR(ROUND(($O14*$T14),2)," ") -> 0 | X14: =IFERROR(ROUND(($P14*$U14),2),"") -> 0 | Y14: =IFERROR(ROUND(($Q14*$V14),2),"") -> 0 | AC14: =IFERROR(ROUND(($O14*$Z14),2)," ") -> 0 | AD14: =IFERROR(ROUND(($P14*$AA14),2),"") -> 0 | AE14: =IFERROR(ROUND(($Q14*$AB14),2),"") -> 0 | AI14: =IFERROR(ROUND(($O14*$AF14),2)," ") -> 0 | AJ14: =IFERROR(ROUND(($P14*$AG14),2),"") -> 0 | AK14: =IFERROR(ROUND(($Q14*$AH14),2),"") -> 0 | AL14: =IFERROR(ROUND(($W14+$AC14+$AI14),2),"") -> 0 | AM14: =IFERROR(ROUND(($X14+$AD14+$AJ14),2),"") -> 0 | AN14: =IFERROR(ROUND(($Y14+$AE14+$AK14),2),"") -> 0 | AO14: =SUM(AL14:AN14) -> 0 | AR14: =IFERROR(ROUND((S14-AO14-AP14),2),"") -> 9872 | AU14: 2000 | AV14: 395.48 | AY14: =IFERROR(ROUND((AR14-AS14-AT14-AU14-AV14-AW14-AX14),2),"") -> 7476.52 | AZ14: Payroll | BA14: ANDAYA, APRIL JANE G.
A15: =IF(B15="","",COUNTA($B$10:B15)) -> 6 | B15: 2026-01-0001 | C15: 46035 | E15: GALABAY, CHRISTIANEL B. | F15: PPD | G15: Planning Officer II | H15: =IF(AZ15="Payroll",VLOOKUP(E15,'[2]CODE 2'!$R:$S,2,FALSE),"0") -> 0 | I15: CFIDP | J15: OK | M15: =IFERROR(VLOOKUP($H15,'[2]CODE 2'!$J:$K,2,FALSE)," ") | N15: =IFERROR(ROUND((M15/2),2),"") | O15: =IFERROR((M15/22)," ") | P15: =IFERROR((O15/8),"") | Q15: =IFERROR((P15/60),"") | R15: =IF(AZ15="Payroll","11","") | S15: =IFERROR(ROUND((O15*R15),2)," ") | T15: 0 | U15: 0 | V15: 0 | W15: =IFERROR(ROUND(($O15*$T15),2)," ") | X15: =IFERROR(ROUND(($P15*$U15),2),"") | Y15: =IFERROR(ROUND(($Q15*$V15),2),"") | AC15: =IFERROR(ROUND(($O15*$Z15),2)," ") | AD15: =IFERROR(ROUND(($P15*$AA15),2),"") | AE15: =IFERROR(ROUND(($Q15*$AB15),2),"") | AI15: =IFERROR(ROUND(($O15*$AF15),2)," ") | AJ15: =IFERROR(ROUND(($P15*$AG15),2),"") | AK15: =IFERROR(ROUND(($Q15*$AH15),2),"") | AL15: =IFERROR(ROUND(($W15+$AC15+$AI15),2),"") | AM15: =IFERROR(ROUND(($X15+$AD15+$AJ15),2),"") | AN15: =IFERROR(ROUND(($Y15+$AE15+$AK15),2),"") | AO15: =SUM(AL15:AN15) -> 0 | AR15: =IFERROR(ROUND((S15-AO15-AP15),2),"") | AY15: =IFERROR(ROUND((AR15-AS15-AT15-AU15-AV15-AW15-AX15),2),"") | AZ15: Voucher | BA15: ARANAZ, CZAREE JOSIAH A.
A16: =IF(B16="","",COUNTA($B$10:B16)) -> 7 | B16: 2026-01-0018 | C16: 46036 | E16: NILO, FAITH PERL A. | F16: PPD | G16: Planning Officer I | H16: =IF(AZ16="Payroll",VLOOKUP(E16,'[2]CODE 2'!$R:$S,2,FALSE),"0") -> 11 | I16: O. ESETS | J16: OK | M16: =IFERROR(VLOOKUP($H16,'[2]CODE 2'!$J:$K,2,FALSE)," ") -> 27000 | N16: =IFERROR(ROUND((M16/2),2),"") -> 13500 | O16: =IFERROR((M16/22)," ") -> 1227.2727 | P16: =IFERROR((O16/8),"") -> 153.40909 | Q16: =IFERROR((P16/60),"") -> 2.5568182 | R16: =IF(AZ16="Payroll","11","") -> 11 | S16: =IFERROR(ROUND((O16*R16),2)," ") -> 13500 | T16: 0 | U16: 0 | V16: 4 | W16: =IFERROR(ROUND(($O16*$T16),2)," ") -> 0 | X16: =IFERROR(ROUND(($P16*$U16),2),"") -> 0 | Y16: =IFERROR(ROUND(($Q16*$V16),2),"") -> 10.23 | AC16: =IFERROR(ROUND(($O16*$Z16),2)," ") -> 0 | AD16: =IFERROR(ROUND(($P16*$AA16),2),"") -> 0 | AE16: =IFERROR(ROUND(($Q16*$AB16),2),"") -> 0 | AI16: =IFERROR(ROUND(($O16*$AF16),2)," ") -> 0 | AJ16: =IFERROR(ROUND(($P16*$AG16),2),"") -> 0 | AK16: =IFERROR(ROUND(($Q16*$AH16),2),"") -> 0 | AL16: =IFERROR(ROUND(($W16+$AC16+$AI16),2),"") -> 0 | AM16: =IFERROR(ROUND(($X16+$AD16+$AJ16),2),"") -> 0 | AN16: =IFERROR(ROUND(($Y16+$AE16+$AK16),2),"") -> 10.23 | AO16: =SUM(AL16:AN16) -> 10.23 | AR16: =IFERROR(ROUND((S16-AO16-AP16),2),"") -> 13489.77 | AY16: =IFERROR(ROUND((AR16-AS16-AT16-AU16-AV16-AW16-AX16),2),"") -> 13489.77 | AZ16: Payroll | BA16: AUSTRIA, CHRISTIAN JOCEF B.
A17: =IF(B17="","",COUNTA($B$10:B17)) -> 8 | B17: 2026-01-0019 | C17: 46036 | E17: VERINO, ALLYSON RYAN T. | F17: PPD | G17: Planning Development Officer I | H17: =IF(AZ17="Payroll",VLOOKUP(E17,'[2]CODE 2'!$R:$S,2,FALSE),"0") -> 11 | I17: O. ESETS | J17: OK | M17: =IFERROR(VLOOKUP($H17,'[2]CODE 2'!$J:$K,2,FALSE)," ") -> 27000 | N17: =IFERROR(ROUND((M17/2),2),"") -> 13500 | O17: =IFERROR((M17/22)," ") -> 1227.2727 | P17: =IFERROR((O17/8),"") -> 153.40909 | Q17: =IFERROR((P17/60),"") -> 2.5568182 | R17: =IF(AZ17="Payroll","11","") -> 11 | S17: =IFERROR(ROUND((O17*R17),2)," ") -> 13500 | T17: 0 | U17: 0 | V17: 0 | W17: =IFERROR(ROUND(($O17*$T17),2)," ") -> 0 | X17: =IFERROR(ROUND(($P17*$U17),2),"") -> 0 | Y17: =IFERROR(ROUND(($Q17*$V17),2),"") -> 0 | AC17: =IFERROR(ROUND(($O17*$Z17),2)," ") -> 0 | AD17: =IFERROR(ROUND(($P17*$AA17),2),"") -> 0 | AE17: =IFERROR(ROUND(($Q17*$AB17),2),"") -> 0 | AI17: =IFERROR(ROUND(($O17*$AF17),2)," ") -> 0 | AJ17: =IFERROR(ROUND(($P17*$AG17),2),"") -> 0 | AK17: =IFERROR(ROUND(($Q17*$AH17),2),"") -> 0 | AL17: =IFERROR(ROUND(($W17+$AC17+$AI17),2),"") -> 0 | AM17: =IFERROR(ROUND(($X17+$AD17+$AJ17),2),"") -> 0 | AN17: =IFERROR(ROUND(($Y17+$AE17+$AK17),2),"") -> 0 | AO17: =SUM(AL17:AN17) -> 0 | AR17: =IFERROR(ROUND((S17-AO17-AP17),2),"") -> 13500 | AY17: =IFERROR(ROUND((AR17-AS17-AT17-AU17-AV17-AW17-AX17),2),"") -> 13500 | AZ17: Payroll | BA17: BADILLO, ALBINO M.
A18: =IF(B18="","",COUNTA($B$10:B18)) -> 9 | B18: 2026-01-0025 | C18: 46036 | E18: LAMPAS, CHRISTIAN JOSEPH P | F18: ISD | G18: Computer Maintenance Technologist I | H18: =IF(AZ18="Payroll",VLOOKUP(E18,'[2]CODE 2'!$R:$S,2,FALSE),"0") -> 11 | I18: FPMA/RICE | J18: OK | M18: =IFERROR(VLOOKUP($H18,'[2]CODE 2'!$J:$K,2,FALSE)," ") -> 27000 | N18: =IFERROR(ROUND((M18/2),2),"") -> 13500 | O18: =IFERROR((M18/22)," ") -> 1227.2727 | P18: =IFERROR((O18/8),"") -> 153.40909 | Q18: =IFERROR((P18/60),"") -> 2.5568182 | R18: =IF(AZ18="Payroll","11","") -> 11 | S18: =IFERROR(ROUND((O18*R18),2)," ") -> 13500 | T18: 1 | U18: 0 | V18: 0 | W18: =IFERROR(ROUND(($O18*$T18),2)," ") -> 1227.27 | X18: =IFERROR(ROUND(($P18*$U18),2),"") -> 0 | Y18: =IFERROR(ROUND(($Q18*$V18),2),"") -> 0 | AC18: =IFERROR(ROUND(($O18*$Z18),2)," ") -> 0 | AD18: =IFERROR(ROUND(($P18*$AA18),2),"") -> 0 | AE18: =IFERROR(ROUND(($Q18*$AB18),2),"") -> 0 | AI18: =IFERROR(ROUND(($O18*$AF18),2)," ") -> 0 | AJ18: =IFERROR(ROUND(($P18*$AG18),2),"") -> 0 | AK18: =IFERROR(ROUND(($Q18*$AH18),2),"") -> 0 | AL18: =IFERROR(ROUND(($W18+$AC18+$AI18),2),"") -> 1227.27 | AM18: =IFERROR(ROUND(($X18+$AD18+$AJ18),2),"") -> 0 | AN18: =IFERROR(ROUND(($Y18+$AE18+$AK18),2),"") -> 0 | AO18: =SUM(AL18:AN18) -> 1227.27 | AR18: =IFERROR(ROUND((S18-AO18-AP18),2),"") -> 12272.73 | AY18: =IFERROR(ROUND((AR18-AS18-AT18-AU18-AV18-AW18-AX18),2),"") -> 12272.73 | AZ18: Payroll | BA18: BALA, ANGEL D.
A19: =IF(B19="","",COUNTA($B$10:B19)) -> 10 | B19: 2026-01-0022 | C19: 46036 | E19: MANDANI, AVE M. | F19: ISD | G19: Bookbinder III | H19: =IF(AZ19="Payroll",VLOOKUP(E19,'[2]CODE 2'!$R:$S,2,FALSE),"0") -> 7 | I19: O. ESETS | J19: OK | M19: =IFERROR(VLOOKUP($H19,'[2]CODE 2'!$J:$K,2,FALSE)," ") -> 18620 | N19: =IFERROR(ROUND((M19/2),2),"") -> 9310 | O19: =IFERROR((M19/22)," ") -> 846.36364 | P19: =IFERROR((O19/8),"") -> 105.79545 | Q19: =IFERROR((P19/60),"") -> 1.7632576 | R19: =IF(AZ19="Payroll","11","") -> 11 | S19: =IFERROR(ROUND((O19*R19),2)," ") -> 9310 | T19: 0 | U19: 0 | V19: 0 | W19: =IFERROR(ROUND(($O19*$T19),2)," ") -> 0 | X19: =IFERROR(ROUND(($P19*$U19),2),"") -> 0 | Y19: =IFERROR(ROUND(($Q19*$V19),2),"") -> 0 | AC19: =IFERROR(ROUND(($O19*$Z19),2)," ") -> 0 | AD19: =IFERROR(ROUND(($P19*$AA19),2),"") -> 0 | AE19: =IFERROR(ROUND(($Q19*$AB19),2),"") -> 0 | AI19: =IFERROR(ROUND(($O19*$AF19),2)," ") -> 0 | AJ19: =IFERROR(ROUND(($P19*$AG19),2),"") -> 0 | AK19: =IFERROR(ROUND(($Q19*$AH19),2),"") -> 0 | AL19: =IFERROR(ROUND(($W19+$AC19+$AI19),2),"") -> 0 | AM19: =IFERROR(ROUND(($X19+$AD19+$AJ19),2),"") -> 0 | AN19: =IFERROR(ROUND(($Y19+$AE19+$AK19),2),"") -> 0 | AO19: =SUM(AL19:AN19) -> 0 | AR19: =IFERROR(ROUND((S19-AO19-AP19),2),"") -> 9310 | AY19: =IFERROR(ROUND((AR19-AS19-AT19-AU19-AV19-AW19-AX19),2),"") -> 9310 | AZ19: Payroll | BA19: BALANGATAN, JUN CHRISTOPHER C.
A20: =IF(B20="","",COUNTA($B$10:B20)) -> 11 | B20: 2026-01-0021 | C20: 46036 | E20: PERNIA, JONAS S. | F20: ISD | G20: Administrative Asst. II | H20: =IF(AZ20="Payroll",VLOOKUP(E20,'[2]CODE 2'!$R:$S,2,FALSE),"0") -> 8 | I20: O. ESETS | J20: OK | M20: =IFERROR(VLOOKUP($H20,'[2]CODE 2'!$J:$K,2,FALSE)," ") -> 19744 | N20: =IFERROR(ROUND((M20/2),2),"") -> 9872 | O20: =IFERROR((M20/22)," ") -> 897.45455 | P20: =IFERROR((O20/8),"") -> 112.18182 | Q20: =IFERROR((P20/60),"") -> 1.869697 | R20: =IF(AZ20="Payroll","11","") -> 11 | S20: =IFERROR(ROUND((O20*R20),2)," ") -> 9872 | T20: 0 | U20: 0 | V20: 0 | W20: =IFERROR(ROUND(($O20*$T20),2)," ") -> 0 | X20: =IFERROR(ROUND(($P20*$U20),2),"") -> 0 | Y20: =IFERROR(ROUND(($Q20*$V20),2),"") -> 0 | AC20: =IFERROR(ROUND(($O20*$Z20),2)," ") -> 0 | AD20: =IFERROR(ROUND(($P20*$AA20),2),"") -> 0 | AE20: =IFERROR(ROUND(($Q20*$AB20),2),"") -> 0 | AI20: =IFERROR(ROUND(($O20*$AF20),2)," ") -> 0 | AJ20: =IFERROR(ROUND(($P20*$AG20),2),"") -> 0 | AK20: =IFERROR(ROUND(($Q20*$AH20),2),"") -> 0 | AL20: =IFERROR(ROUND(($W20+$AC20+$AI20),2),"") -> 0 | AM20: =IFERROR(ROUND(($X20+$AD20+$AJ20),2),"") -> 0 | AN20: =IFERROR(ROUND(($Y20+$AE20+$AK20),2),"") -> 0 | AO20: =SUM(AL20:AN20) -> 0 | AR20: =IFERROR(ROUND((S20-AO20-AP20),2),"") -> 9872 | AY20: =IFERROR(ROUND((AR20-AS20-AT20-AU20-AV20-AW20-AX20),2),"") -> 9872 | AZ20: Payroll | BA20: BELO, JOSHUA G.
A21: =IF(B21="","",COUNTA($B$10:B21)) -> 12 | B21: 2026-01-0023 | C21: 46036 | E21: BALANGATAN, JUN CHRISTOPHER C. | F21: ISD | G21: Media Production Specialist I | H21: =IF(AZ21="Payroll",VLOOKUP(E21,'[2]CODE 2'!$R:$S,2,FALSE),"0") -> 11 | I21: O. ESETS | J21: OK | M21: =IFERROR(VLOOKUP($H21,'[2]CODE 2'!$J:$K,2,FALSE)," ") -> 27000 | N21: =IFERROR(ROUND((M21/2),2),"") -> 13500 | O21: =IFERROR((M21/22)," ") -> 1227.2727 | P21: =IFERROR((O21/8),"") -> 153.40909 | Q21: =IFERROR((P21/60),"") -> 2.5568182 | R21: =IF(AZ21="Payroll","11","") -> 11 | S21: =IFERROR(ROUND((O21*R21),2)," ") -> 13500 | T21: 0 | U21: 0 | V21: 0 | W21: =IFERROR(ROUND(($O21*$T21),2)," ") -> 0 | X21: =IFERROR(ROUND(($P21*$U21),2),"") -> 0 | Y21: =IFERROR(ROUND(($Q21*$V21),2),"") -> 0 | AC21: =IFERROR(ROUND(($O21*$Z21),2)," ") -> 0 | AD21: =IFERROR(ROUND(($P21*$AA21),2),"") -> 0 | AE21: =IFERROR(ROUND(($Q21*$AB21),2),"") -> 0 | AI21: =IFERROR(ROUND(($O21*$AF21),2)," ") -> 0 | AJ21: =IFERROR(ROUND(($P21*$AG21),2),"") -> 0 | AK21: =IFERROR(ROUND(($Q21*$AH21),2),"") -> 0 | AL21: =IFERROR(ROUND(($W21+$AC21+$AI21),2),"") -> 0 | AM21: =IFERROR(ROUND(($X21+$AD21+$AJ21),2),"") -> 0 | AN21: =IFERROR(ROUND(($Y21+$AE21+$AK21),2),"") -> 0 | AO21: =SUM(AL21:AN21) -> 0 | AR21: =IFERROR(ROUND((S21-AO21-AP21),2),"") -> 13500 | AY21: =IFERROR(ROUND((AR21-AS21-AT21-AU21-AV21-AW21-AX21),2),"") -> 13500 | AZ21: Payroll | BA21: BRUZON, ANGENNITTE F.
A22: =IF(B22="","",COUNTA($B$10:B22)) -> 13 | B22: 2026-01-0024 | C22: 46036 | E22: LIM, KLEIN ANSON G. | F22: ISD | G22: Agriculturist I | H22: =IF(AZ22="Payroll",VLOOKUP(E22,'[2]CODE 2'!$R:$S,2,FALSE),"0") -> 11 | I22: FPMA/RICE | J22: OK | M22: =IFERROR(VLOOKUP($H22,'[2]CODE 2'!$J:$K,2,FALSE)," ") -> 27000 | N22: =IFERROR(ROUND((M22/2),2),"") -> 13500 | O22: =IFERROR((M22/22)," ") -> 1227.2727 | P22: =IFERROR((O22/8),"") -> 153.40909 | Q22: =IFERROR((P22/60),"") -> 2.5568182 | R22: =IF(AZ22="Payroll","11","") -> 11 | S22: =IFERROR(ROUND((O22*R22),2)," ") -> 13500 | T22: 0 | U22: 0 | V22: 9 | W22: =IFERROR(ROUND(($O22*$T22),2)," ") -> 0 | X22: =IFERROR(ROUND(($P22*$U22),2),"") -> 0 | Y22: =IFERROR(ROUND(($Q22*$V22),2),"") -> 23.01 | AC22: =IFERROR(ROUND(($O22*$Z22),2)," ") -> 0 | AD22: =IFERROR(ROUND(($P22*$AA22),2),"") -> 0 | AE22: =IFERROR(ROUND(($Q22*$AB22),2),"") -> 0 | AI22: =IFERROR(ROUND(($O22*$AF22),2)," ") -> 0 | AJ22: =IFERROR(ROUND(($P22*$AG22),2),"") -> 0 | AK22: =IFERROR(ROUND(($Q22*$AH22),2),"") -> 0 | AL22: =IFERROR(ROUND(($W22+$AC22+$AI22),2),"") -> 0 | AM22: =IFERROR(ROUND(($X22+$AD22+$AJ22),2),"") -> 0 | AN22: =IFERROR(ROUND(($Y22+$AE22+$AK22),2),"") -> 23.01 | AO22: =SUM(AL22:AN22) -> 23.01 | AR22: =IFERROR(ROUND((S22-AO22-AP22),2),"") -> 13476.99 | AY22: =IFERROR(ROUND((AR22-AS22-AT22-AU22-AV22-AW22-AX22),2),"") -> 13476.99 | AZ22: Payroll | BA22: CAGUMBAY, LIYANNE M.
A23: =IF(B23="","",COUNTA($B$10:B23)) -> 14 | B23: 2026-01-0020 | C23: 46036 | E23: AGUAS, DERICKE DUANE C. | F23: ISD | G23: Information Officer I | H23: 11 | I23: O. ESETS | J23: OK | M23: =IFERROR(VLOOKUP($H23,'[2]CODE 2'!$J:$K,2,FALSE)," ") -> 27000 | N23: =IFERROR(ROUND((M23/2),2),"") -> 13500 | O23: =IFERROR((M23/22)," ") -> 1227.2727 | P23: =IFERROR((O23/8),"") -> 153.40909 | Q23: =IFERROR((P23/60),"") -> 2.5568182 | R23: =IF(AZ23="Payroll","11","") -> 11 | S23: =IFERROR(ROUND((O23*R23),2)," ") -> 13500 | T23: 0 | U23: 0 | V23: 0 | W23: =IFERROR(ROUND(($O23*$T23),2)," ") -> 0 | X23: =IFERROR(ROUND(($P23*$U23),2),"") -> 0 | Y23: =IFERROR(ROUND(($Q23*$V23),2),"") -> 0 | AC23: =IFERROR(ROUND(($O23*$Z23),2)," ") -> 0 | AD23: =IFERROR(ROUND(($P23*$AA23),2),"") -> 0 | AE23: =IFERROR(ROUND(($Q23*$AB23),2),"") -> 0 | AI23: =IFERROR(ROUND(($O23*$AF23),2)," ") -> 0 | AJ23: =IFERROR(ROUND(($P23*$AG23),2),"") -> 0 | AK23: =IFERROR(ROUND(($Q23*$AH23),2),"") -> 0 | AL23: =IFERROR(ROUND(($W23+$AC23+$AI23),2),"") -> 0 | AM23: =IFERROR(ROUND(($X23+$AD23+$AJ23),2),"") -> 0 | AN23: =IFERROR(ROUND(($Y23+$AE23+$AK23),2),"") -> 0 | AO23: =SUM(AL23:AN23) -> 0 | AR23: =IFERROR(ROUND((S23-AO23-AP23),2),"") -> 13500 | AY23: =IFERROR(ROUND((AR23-AS23-AT23-AU23-AV23-AW23-AX23),2),"") -> 13500 | AZ23: Payroll | BA23: CAIZ, LEONILA D.
A24: =IF(B24="","",COUNTA($B$10:B24)) -> 15 | B24: 2026-01-0026 | C24: 46036 | E24: BALA, ANGEL D. | F24: ISD | G24: Information Officer I | H24: 11 | I24: O. ESETS | J24: OK | M24: =IFERROR(VLOOKUP($H24,'[2]CODE 2'!$J:$K,2,FALSE)," ") -> 27000 | N24: =IFERROR(ROUND((M24/2),2),"") -> 13500 | O24: =IFERROR((M24/22)," ") -> 1227.2727 | P24: =IFERROR((O24/8),"") -> 153.40909 | Q24: =IFERROR((P24/60),"") -> 2.5568182 | R24: =IF(AZ24="Payroll","11","") -> 11 | S24: =IFERROR(ROUND((O24*R24),2)," ") -> 13500 | T24: 0 | U24: 0 | V24: 0 | W24: =IFERROR(ROUND(($O24*$T24),2)," ") -> 0 | X24: =IFERROR(ROUND(($P24*$U24),2),"") -> 0 | Y24: =IFERROR(ROUND(($Q24*$V24),2),"") -> 0 | AC24: =IFERROR(ROUND(($O24*$Z24),2)," ") -> 0 | AD24: =IFERROR(ROUND(($P24*$AA24),2),"") -> 0 | AE24: =IFERROR(ROUND(($Q24*$AB24),2),"") -> 0 | AI24: =IFERROR(ROUND(($O24*$AF24),2)," ") -> 0 | AJ24: =IFERROR(ROUND(($P24*$AG24),2),"") -> 0 | AK24: =IFERROR(ROUND(($Q24*$AH24),2),"") -> 0 | AL24: =IFERROR(ROUND(($W24+$AC24+$AI24),2),"") -> 0 | AM24: =IFERROR(ROUND(($X24+$AD24+$AJ24),2),"") -> 0 | AN24: =IFERROR(ROUND(($Y24+$AE24+$AK24),2),"") -> 0 | AO24: =SUM(AL24:AN24) -> 0 | AR24: =IFERROR(ROUND((S24-AO24-AP24),2),"") -> 13500 | AU24: 2000 | AY24: =IFERROR(ROUND((AR24-AS24-AT24-AU24-AV24-AW24-AX24),2),"") -> 11500 | AZ24: Payroll | BA24: CALDITO, CHARISSE D.
A25: =IF(B25="","",COUNTA($B$10:B25)) -> 16 | B25: 2026-01-0047 | C25: 46036 | E25: CAGUMBAY, LIYANNE M. | F25: ADO | G25: Administrative Asst. II | H25: =IF(AZ25="Payroll",VLOOKUP(E25,'[2]CODE 2'!$R:$S,2,FALSE),"0") -> 8 | I25: GASS | J25: OK | M25: =IFERROR(VLOOKUP($H25,'[2]CODE 2'!$J:$K,2,FALSE)," ") -> 19744 | N25: =IFERROR(ROUND((M25/2),2),"") -> 9872 | O25: =IFERROR((M25/22)," ") -> 897.45455 | P25: =IFERROR((O25/8),"") -> 112.18182 | Q25: =IFERROR((P25/60),"") -> 1.869697 | R25: =IF(AZ25="Payroll","11","") -> 11 | S25: =IFERROR(ROUND((O25*R25),2)," ") -> 9872 | T25: 0 | U25: 0 | V25: 0 | W25: =IFERROR(ROUND(($O25*$T25),2)," ") -> 0 | X25: =IFERROR(ROUND(($P25*$U25),2),"") -> 0 | Y25: =IFERROR(ROUND(($Q25*$V25),2),"") -> 0 | AC25: =IFERROR(ROUND(($O25*$Z25),2)," ") -> 0 | AD25: =IFERROR(ROUND(($P25*$AA25),2),"") -> 0 | AE25: =IFERROR(ROUND(($Q25*$AB25),2),"") -> 0 | AI25: =IFERROR(ROUND(($O25*$AF25),2)," ") -> 0 | AJ25: =IFERROR(ROUND(($P25*$AG25),2),"") -> 0 | AK25: =IFERROR(ROUND(($Q25*$AH25),2),"") -> 0 | AL25: =IFERROR(ROUND(($W25+$AC25+$AI25),2),"") -> 0 | AM25: =IFERROR(ROUND(($X25+$AD25+$AJ25),2),"") -> 0 | AN25: =IFERROR(ROUND(($Y25+$AE25+$AK25),2),"") -> 0 | AO25: =SUM(AL25:AN25) -> 0 | AR25: =IFERROR(ROUND((S25-AO25-AP25),2),"") -> 9872 | AY25: =IFERROR(ROUND((AR25-AS25-AT25-AU25-AV25-AW25-AX25),2),"") -> 9872 | AZ25: Payroll | BA25: CAPONGCOL, MARY JANE
A26: =IF(B26="","",COUNTA($B$10:B26)) -> 17 | B26: 2026-01-48 | C26: 46036 | E26: DE GUZMAN, SWEET JESSABEL M. | F26: ADO | G26: Executive Assistant II | H26: =IF(AZ26="Payroll",VLOOKUP(E26,'[2]CODE 2'!$R:$S,2,FALSE),"0") -> 17 | I26: O. ESETS | J26: OK | M26: =IFERROR(VLOOKUP($H26,'[2]CODE 2'!$J:$K,2,FALSE)," ") -> 43030 | N26: =IFERROR(ROUND((M26/2),2),"") -> 21515 | O26: =IFERROR((M26/22)," ") -> 1955.9091 | P26: =IFERROR((O26/8),"") -> 244.48864 | Q26: =IFERROR((P26/60),"") -> 4.0748106 | R26: =IF(AZ26="Payroll","11","") -> 11 | S26: =IFERROR(ROUND((O26*R26),2)," ") -> 21515 | T26: 0 | U26: 0 | V26: 0 | W26: =IFERROR(ROUND(($O26*$T26),2)," ") -> 0 | X26: =IFERROR(ROUND(($P26*$U26),2),"") -> 0 | Y26: =IFERROR(ROUND(($Q26*$V26),2),"") -> 0 | AC26: =IFERROR(ROUND(($O26*$Z26),2)," ") -> 0 | AD26: =IFERROR(ROUND(($P26*$AA26),2),"") -> 0 | AE26: =IFERROR(ROUND(($Q26*$AB26),2),"") -> 0 | AI26: =IFERROR(ROUND(($O26*$AF26),2)," ") -> 0 | AJ26: =IFERROR(ROUND(($P26*$AG26),2),"") -> 0 | AK26: =IFERROR(ROUND(($Q26*$AH26),2),"") -> 0 | AL26: =IFERROR(ROUND(($W26+$AC26+$AI26),2),"") -> 0 | AM26: =IFERROR(ROUND(($X26+$AD26+$AJ26),2),"") -> 0 | AN26: =IFERROR(ROUND(($Y26+$AE26+$AK26),2),"") -> 0 | AO26: =SUM(AL26:AN26) -> 0 | AR26: =IFERROR(ROUND((S26-AO26-AP26),2),"") -> 21515 | AY26: =IFERROR(ROUND((AR26-AS26-AT26-AU26-AV26-AW26-AX26),2),"") -> 21515 | AZ26: Payroll | BA26: CATIMBANG, SHANDEE FAY O.
A27: =IF(B27="","",COUNTA($B$10:B27)) -> 18 | B27: 2026-01-0037 | C27: 46036 | E27: SALVA, IRENE U | F27: BGT. | G27: Administrative Asst. II | H27: =IF(AZ27="Payroll",VLOOKUP(E27,'[2]CODE 2'!$R:$S,2,FALSE),"0") -> 8 | I27: O. ESETS | J27: OK | M27: =IFERROR(VLOOKUP($H27,'[2]CODE 2'!$J:$K,2,FALSE)," ") -> 19744 | N27: =IFERROR(ROUND((M27/2),2),"") -> 9872 | O27: =IFERROR((M27/22)," ") -> 897.45455 | P27: =IFERROR((O27/8),"") -> 112.18182 | Q27: =IFERROR((P27/60),"") -> 1.869697 | R27: =IF(AZ27="Payroll","11","") -> 11 | S27: =IFERROR(ROUND((O27*R27),2)," ") -> 9872 | T27: 0 | U27: 0 | V27: 0 | W27: =IFERROR(ROUND(($O27*$T27),2)," ") -> 0 | X27: =IFERROR(ROUND(($P27*$U27),2),"") -> 0 | Y27: =IFERROR(ROUND(($Q27*$V27),2),"") -> 0 | AC27: =IFERROR(ROUND(($O27*$Z27),2)," ") -> 0 | AD27: =IFERROR(ROUND(($P27*$AA27),2),"") -> 0 | AE27: =IFERROR(ROUND(($Q27*$AB27),2),"") -> 0 | AI27: =IFERROR(ROUND(($O27*$AF27),2)," ") -> 0 | AJ27: =IFERROR(ROUND(($P27*$AG27),2),"") -> 0 | AK27: =IFERROR(ROUND(($Q27*$AH27),2),"") -> 0 | AL27: =IFERROR(ROUND(($W27+$AC27+$AI27),2),"") -> 0 | AM27: =IFERROR(ROUND(($X27+$AD27+$AJ27),2),"") -> 0 | AN27: =IFERROR(ROUND(($Y27+$AE27+$AK27),2),"") -> 0 | AO27: =SUM(AL27:AN27) -> 0 | AR27: =IFERROR(ROUND((S27-AO27-AP27),2),"") -> 9872 | AY27: =IFERROR(ROUND((AR27-AS27-AT27-AU27-AV27-AW27-AX27),2),"") -> 9872 | AZ27: Payroll | BA27: CATUBAY, ELVIS JOHN L.
A28: =IF(B28="","",COUNTA($B$10:B28)) -> 19 | B28: 2026-01-0007 | C28: 46035 | E28: SASIS, BRINGKLY B. | F28: BGT. | G28: Administrative Asst. II | H28: =IF(AZ28="Payroll",VLOOKUP(E28,'[2]CODE 2'!$R:$S,2,FALSE),"0") -> 0 | I28: CFIDP | J28: OK | M28: =IFERROR(VLOOKUP($H28,'[2]CODE 2'!$J:$K,2,FALSE)," ") | N28: =IFERROR(ROUND((M28/2),2),"") | O28: =IFERROR((M28/22)," ") | P28: =IFERROR((O28/8),"") | Q28: =IFERROR((P28/60),"") | R28: =IF(AZ28="Payroll","11","") | S28: =IFERROR(ROUND((O28*R28),2)," ") | T28: 0 | U28: 0 | V28: 0 | W28: =IFERROR(ROUND(($O28*#REF!),2)," ") | X28: =IFERROR(ROUND(($P28*$U28),2),"") | Y28: =IFERROR(ROUND(($Q28*$V28),2),"") | AC28: =IFERROR(ROUND(($O28*$Z28),2)," ") | AD28: =IFERROR(ROUND(($P28*$AA28),2),"") | AE28: =IFERROR(ROUND(($Q28*$AB28),2),"") | AI28: =IFERROR(ROUND(($O28*$AF28),2)," ") | AJ28: =IFERROR(ROUND(($P28*$AG28),2),"") | AK28: =IFERROR(ROUND(($Q28*$AH28),2),"") | AL28: =IFERROR(ROUND(($W28+$AC28+$AI28),2),"") | AM28: =IFERROR(ROUND(($X28+$AD28+$AJ28),2),"") | AN28: =IFERROR(ROUND(($Y28+$AE28+$AK28),2),"") | AO28: =SUM(AL28:AN28) -> 0 | AR28: =IFERROR(ROUND((S28-AO28-AP28),2),"") | AY28: =IFERROR(ROUND((AR28-AS28-AT28-AU28-AV28-AW28-AX28),2),"") | AZ28: Voucher | BA28: CELOCIA, ROSELY-ANN G.
A29: =IF(B29="","",COUNTA($B$10:B29)) -> 20 | B29: 2026-01-0038 | C29: 46036 | E29: CAIZ, LEONILA D. | F29: BGT. | G29: Financial Analyst | I29: O. ESETS | M29: =IFERROR(VLOOKUP($H29,'[2]CODE 2'!$J:$K,2,FALSE)," ") -> 50617 | N29: =IFERROR(ROUND((M29/2),2),"") -> 25308.5 | O29: =IFERROR((M29/22)," ") -> 2300.7727 | P29: =IFERROR((O29/8),"") -> 287.59659 | Q29: =IFERROR((P29/60),"") -> 4.7932765 | R29: =IF(AZ29="Payroll","11","") -> 11 | S29: =IFERROR(ROUND((O29*R29),2)," ") -> 25308.5 | T29: 5 | U29: 1 | V29: 43 | W29: =IFERROR(ROUND(($O29*$T29),2)," ") -> 11503.86 | X29: =IFERROR(ROUND(($P29*$U29),2),"") -> 287.6 | Y29: =IFERROR(ROUND(($Q29*$V29),2),"") -> 206.11 | AC29: =IFERROR(ROUND(($O29*$Z29),2)," ") -> 0 | AD29: =IFERROR(ROUND(($P29*$AA29),2),"") -> 0 | AE29: =IFERROR(ROUND(($Q29*$AB29),2),"") -> 0 | AI29: =IFERROR(ROUND(($O29*$AF29),2)," ") -> 0 | AJ29: =IFERROR(ROUND(($P29*$AG29),2),"") -> 0 | AK29: =IFERROR(ROUND(($Q29*$AH29),2),"") -> 0 | AL29: =IFERROR(ROUND(($W29+$AC29+$AI29),2),"") -> 11503.86 | AM29: =IFERROR(ROUND(($X29+$AD29+$AJ29),2),"") -> 287.6 | AN29: =IFERROR(ROUND(($Y29+$AE29+$AK29),2),"") -> 206.11 | AO29: =SUM(AL29:AN29) -> 11997.57 | AR29: =IFERROR(ROUND((S29-AO29-AP29),2),"") -> 13310.93 | AY29: =IFERROR(ROUND((AR29-AS29-AT29-AU29-AV29-AW29-AX29),2),"") -> 13310.93 | AZ29: Payroll | BA29: COMPLETO, CRIZANTO E.
A30: =IF(B30="","",COUNTA($B$10:B30)) -> 21 | B30: 2026-01-0039 | C30: 46036 | E30: SALVANIA, JEFFREY | F30: ACCTG. | G30: Administrative Asst. II | H30: =IF(AZ30="Payroll",VLOOKUP(E30,'[2]CODE 2'!$R:$S,2,FALSE),"0") -> 8 | I30: O. ESETS | J30: OK | M30: =IFERROR(VLOOKUP($H30,'[2]CODE 2'!$J:$K,2,FALSE)," ") -> 19744 | N30: =IFERROR(ROUND((M30/2),2),"") -> 9872 | O30: =IFERROR((M30/22)," ") -> 897.45455 | P30: =IFERROR((O30/8),"") -> 112.18182 | Q30: =IFERROR((P30/60),"") -> 1.869697 | R30: =IF(AZ30="Payroll","11","") -> 11 | S30: =IFERROR(ROUND((O30*R30),2)," ") -> 9872 | T30: 0 | U30: 0 | V30: 0 | W30: =IFERROR(ROUND(($O30*$T28),2)," ") -> 0 | X30: =IFERROR(ROUND(($P30*$U30),2),"") -> 0 | Y30: =IFERROR(ROUND(($Q30*$V30),2),"") -> 0 | AC30: =IFERROR(ROUND(($O30*$Z30),2)," ") -> 0 | AD30: =IFERROR(ROUND(($P30*$AA30),2),"") -> 0 | AE30: =IFERROR(ROUND(($Q30*$AB30),2),"") -> 0 | AI30: =IFERROR(ROUND(($O30*$AF30),2)," ") -> 0 | AJ30: =IFERROR(ROUND(($P30*$AG30),2),"") -> 0 | AK30: =IFERROR(ROUND(($Q30*$AH30),2),"") -> 0 | AL30: =IFERROR(ROUND(($W30+$AC30+$AI30),2),"") -> 0 | AM30: =IFERROR(ROUND(($X30+$AD30+$AJ30),2),"") -> 0 | AN30: =IFERROR(ROUND(($Y30+$AE30+$AK30),2),"") -> 0 | AO30: =SUM(AL30:AN30) -> 0 | AR30: =IFERROR(ROUND((S30-AO30-AP30),2),"") -> 9872 | AY30: =IFERROR(ROUND((AR30-AS30-AT30-AU30-AV30-AW30-AX30),2),"") -> 9872 | AZ30: Payroll | BA30: CORDOVA, JOEL M.
A31: =IF(B31="","",COUNTA($B$10:B31)) -> 22 | B31: 2026-01-0012 | C31: 46036 | E31: ESTAPON, LESLIE DC. | F31: ACCTG. | G31: Administrative Asst. II | H31: =IF(AZ31="Payroll",VLOOKUP(E31,'[2]CODE 2'!$R:$S,2,FALSE),"0") -> 0 | I31: REVOLVING FUND | J31: OK | M31: =IFERROR(VLOOKUP($H31,'[2]CODE 2'!$J:$K,2,FALSE)," ") | N31: =IFERROR(ROUND((M31/2),2),"") | O31: =IFERROR((M31/22)," ") | P31: =IFERROR((O31/8),"") | Q31: =IFERROR((P31/60),"") | R31: 11 | S31: =IFERROR(ROUND((O31*R31),2)," ") | T31: 0 | U31: 0 | V31: 18 | W31: =IFERROR(ROUND(($O31*$T31),2)," ") | X31: =IFERROR(ROUND(($P31*$U31),2),"") | Y31: =IFERROR(ROUND(($Q31*$V31),2),"") | AC31: =IFERROR(ROUND(($O31*$Z31),2)," ") | AD31: =IFERROR(ROUND(($P31*$AA31),2),"") | AE31: =IFERROR(ROUND(($Q31*$AB31),2),"") | AI31: =IFERROR(ROUND(($O31*$AF31),2)," ") | AJ31: =IFERROR(ROUND(($P31*$AG31),2),"") | AK31: =IFERROR(ROUND(($Q31*$AH31),2),"") | AL31: =IFERROR(ROUND(($W31+$AC31+$AI31),2),"") | AM31: =IFERROR(ROUND(($X31+$AD31+$AJ31),2),"") | AN31: =IFERROR(ROUND(($Y31+$AE31+$AK31),2),"") | AO31: =SUM(AL31:AN31) -> 0 | AR31: =IFERROR(ROUND((S31-AO31-AP31),2),"") | AY31: =IFERROR(ROUND((AR31-AS31-AT31-AU31-AV31-AW31-AX31),2),"") | AZ31: Voucher | BA31: CRUZ, CLAIRE JOYCE B.
A32: =IF(B32="","",COUNTA($B$10:B32)) -> 23 | B32: 2026-01-0040 | C32: 46036 | E32: MARTIN, ORLAN LEONARD E. | F32: ACCTG. | G32: Administrative Asst. II | H32: =IF(AZ32="Payroll",VLOOKUP(E32,'[2]CODE 2'!$R:$S,2,FALSE),"0") -> 8 | I32: O. ESETS | J32: OK | M32: =IFERROR(VLOOKUP($H32,'[2]CODE 2'!$J:$K,2,FALSE)," ") -> 19744 | N32: =IFERROR(ROUND((M32/2),2),"") -> 9872 | O32: =IFERROR((M32/22)," ") -> 897.45455 | P32: =IFERROR((O32/8),"") -> 112.18182 | Q32: =IFERROR((P32/60),"") -> 1.869697 | R32: 11 | S32: =IFERROR(ROUND((O32*R32),2)," ") -> 9872 | T32: 0 | U32: 0 | V32: 32 | W32: =IFERROR(ROUND(($O32*$T32),2)," ") -> 0 | X32: =IFERROR(ROUND(($P32*$U32),2),"") -> 0 | Y32: =IFERROR(ROUND(($Q32*$V32),2),"") -> 59.83 | AC32: =IFERROR(ROUND(($O32*$Z32),2)," ") -> 0 | AD32: =IFERROR(ROUND(($P32*$AA32),2),"") -> 0 | AE32: =IFERROR(ROUND(($Q32*$AB32),2),"") -> 0 | AI32: =IFERROR(ROUND(($O32*$AF32),2)," ") -> 0 | AJ32: =IFERROR(ROUND(($P32*$AG32),2),"") -> 0 | AK32: =IFERROR(ROUND(($Q32*$AH32),2),"") -> 0 | AL32: =IFERROR(ROUND(($W32+$AC32+$AI32),2),"") -> 0 | AM32: =IFERROR(ROUND(($X32+$AD32+$AJ32),2),"") -> 0 | AN32: =IFERROR(ROUND(($Y32+$AE32+$AK32),2),"") -> 59.83 | AO32: =SUM(AL32:AN32) -> 59.83 | AR32: =IFERROR(ROUND((S32-AO32-AP32),2),"") -> 9812.17 | AY32: =IFERROR(ROUND((AR32-AS32-AT32-AU32-AV32-AW32-AX32),2),"") -> 9812.17 | AZ32: Payroll | BA32: CUARTERON, JOSEN L.
A33: =IF(B33="","",COUNTA($B$10:B33)) -> 24 | B33: 2026-01-0004 | C33: 46035 | E33: MAGDARAOG, CHRISTINE NAZEL C. | F33: ACCTG. | G33: Administrative Asst. II | H33: =IF(AZ33="Payroll",VLOOKUP(E33,'[2]CODE 2'!$R:$S,2,FALSE),"0") -> 0 | I33: CFIDP | J33: OK | M33: =IFERROR(VLOOKUP($H33,'[2]CODE 2'!$J:$K,2,FALSE)," ") | N33: =IFERROR(ROUND((M33/2),2),"") | O33: =IFERROR((M33/22)," ") | P33: =IFERROR((O33/8),"") | Q33: =IFERROR((P33/60),"") | R33: 11 | S33: =IFERROR(ROUND((O33*R33),2)," ") | T33: 0 | U33: 0 | V33: 0 | W33: =IFERROR(ROUND(($O33*$T33),2)," ") | X33: =IFERROR(ROUND(($P33*$U33),2),"") | Y33: =IFERROR(ROUND(($Q33*$V33),2),"") | AC33: =IFERROR(ROUND(($O33*$Z33),2)," ") | AD33: =IFERROR(ROUND(($P33*$AA33),2),"") | AE33: =IFERROR(ROUND(($Q33*$AB33),2),"") | AI33: =IFERROR(ROUND(($O33*$AF33),2)," ") | AJ33: =IFERROR(ROUND(($P33*$AG33),2),"") | AK33: =IFERROR(ROUND(($Q33*$AH33),2),"") | AL33: =IFERROR(ROUND(($W33+$AC33+$AI33),2),"") | AM33: =IFERROR(ROUND(($X33+$AD33+$AJ33),2),"") | AN33: =IFERROR(ROUND(($Y33+$AE33+$AK33),2),"") | AO33: =SUM(AL33:AN33) -> 0 | AR33: =IFERROR(ROUND((S33-AO33-AP33),2),"") | AY33: =IFERROR(ROUND((AR33-AS33-AT33-AU33-AV33-AW33-AX33),2),"") | AZ33: Voucher | BA33: DE GUZMAN, SWEET JESSABEL M.
A34: =IF(B34="","",COUNTA($B$10:B34)) -> 25 | B34: 2026-01-0013 | C34: 46036 | E34: LOZANO, ADRIAN D. | F34: ACCTG. | G34: Administrative Asst. II | H34: =IF(AZ34="Payroll",VLOOKUP(E34,'[2]CODE 2'!$R:$S,2,FALSE),"0") -> 0 | I34: REVOLVING FUND | J34: OK | M34: =IFERROR(VLOOKUP($H34,'[2]CODE 2'!$J:$K,2,FALSE)," ") | N34: =IFERROR(ROUND((M34/2),2),"") | O34: =IFERROR((M34/22)," ") | P34: =IFERROR((O34/8),"") | Q34: =IFERROR((P34/60),"") | R34: 11 | S34: =IFERROR(ROUND((O34*R34),2)," ") | T34: 0 | U34: 0 | V34: 5 | W34: =IFERROR(ROUND(($O34*$T34),2)," ") | X34: =IFERROR(ROUND(($P34*$U34),2),"") | Y34: =IFERROR(ROUND(($Q34*$V34),2),"") | AC34: =IFERROR(ROUND(($O34*$Z34),2)," ") | AD34: =IFERROR(ROUND(($P34*$AA34),2),"") | AE34: =IFERROR(ROUND(($Q34*$AB34),2),"") | AI34: =IFERROR(ROUND(($O34*$AF34),2)," ") | AJ34: =IFERROR(ROUND(($P34*$AG34),2),"") | AK34: =IFERROR(ROUND(($Q34*$AH34),2),"") | AL34: =IFERROR(ROUND(($W34+$AC34+$AI34),2),"") | AM34: =IFERROR(ROUND(($X34+$AD34+$AJ34),2),"") | AN34: =IFERROR(ROUND(($Y34+$AE34+$AK34),2),"") | AO34: =SUM(AL34:AN34) -> 0 | AR34: =IFERROR(ROUND((S34-AO34-AP34),2),"") | AY34: =IFERROR(ROUND((AR34-AS34-AT34-AU34-AV34-AW34-AX34),2),"") | AZ34: Voucher | BA34: DITCHE, ALLIAH LYN P.
A35: =IF(B35="","",COUNTA($B$10:B35)) -> 26 | B35: 2026-01-0006 | C35: 46035 | E35: OLIVO, JENNA P. | F35: ACCTG. | G35: Technical Support Staff IV | H35: =IF(AZ35="Payroll",VLOOKUP(E35,'[2]CODE 2'!$R:$S,2,FALSE),"0") -> 0 | I35: CFIDP | J35: OK | M35: =IFERROR(VLOOKUP($H35,'[2]CODE 2'!$J:$K,2,FALSE)," ") | N35: =IFERROR(ROUND((M35/2),2),"") | O35: =IFERROR((M35/22)," ") | P35: =IFERROR((O35/8),"") | Q35: =IFERROR((P35/60),"") | R35: 11 | S35: =IFERROR(ROUND((O35*R35),2)," ") | T35: 0 | U35: 0 | V35: 0 | W35: =IFERROR(ROUND(($O35*$T35),2)," ") | X35: =IFERROR(ROUND(($P35*$U35),2),"") | Y35: =IFERROR(ROUND(($Q35*$V35),2),"") | AC35: =IFERROR(ROUND(($O35*$Z35),2)," ") | AD35: =IFERROR(ROUND(($P35*$AA35),2),"") | AE35: =IFERROR(ROUND(($Q35*$AB35),2),"") | AI35: =IFERROR(ROUND(($O35*$AF35),2)," ") | AJ35: =IFERROR(ROUND(($P35*$AG35),2),"") | AK35: =IFERROR(ROUND(($Q35*$AH35),2),"") | AL35: =IFERROR(ROUND(($W35+$AC35+$AI35),2),"") | AM35: =IFERROR(ROUND(($X35+$AD35+$AJ35),2),"") | AN35: =IFERROR(ROUND(($Y35+$AE35+$AK35),2),"") | AO35: =SUM(AL35:AN35) -> 0 | AR35: =IFERROR(ROUND((S35-AO35-AP35),2),"") | AY35: =IFERROR(ROUND((AR35-AS35-AT35-AU35-AV35-AW35-AX35),2),"") | AZ35: Voucher | BA35: EMBALZADO, SHERYL P.
A36: =IF(B36="","",COUNTA($B$10:B36)) -> 27 | B36: 2026-01-0005 | C36: 46035 | E36: CALDITO, CHARISSE D. | F36: ACCTG. | G36: Administrative Asst. II | H36: =IF(AZ36="Payroll",VLOOKUP(E36,'[2]CODE 2'!$R:$S,2,FALSE),"0") -> 0 | I36: CFIDP | J36: OK | M36: =IFERROR(VLOOKUP($H36,'[2]CODE 2'!$J:$K,2,FALSE)," ") | N36: =IFERROR(ROUND((M36/2),2),"") | O36: =IFERROR((M36/22)," ") | P36: =IFERROR((O36/8),"") | Q36: =IFERROR((P36/60),"") | R36: 11 | S36: =IFERROR(ROUND((O36*R36),2)," ") | T36: 0 | U36: 0 | V36: 29 | W36: =IFERROR(ROUND(($O36*$T36),2)," ") | X36: =IFERROR(ROUND(($P36*$U36),2),"") | Y36: =IFERROR(ROUND(($Q36*$V36),2),"") | AC36: =IFERROR(ROUND(($O36*$Z36),2)," ") | AD36: =IFERROR(ROUND(($P36*$AA36),2),"") | AE36: =IFERROR(ROUND(($Q36*$AB36),2),"") | AI36: =IFERROR(ROUND(($O36*$AF36),2)," ") | AJ36: =IFERROR(ROUND(($P36*$AG36),2),"") | AK36: =IFERROR(ROUND(($Q36*$AH36),2),"") | AL36: =IFERROR(ROUND(($W36+$AC36+$AI36),2),"") | AM36: =IFERROR(ROUND(($X36+$AD36+$AJ36),2),"") | AN36: =IFERROR(ROUND(($Y36+$AE36+$AK36),2),"") | AO36: =SUM(AL36:AN36) -> 0 | AR36: =IFERROR(ROUND((S36-AO36-AP36),2),"") | AY36: =IFERROR(ROUND((AR36-AS36-AT36-AU36-AV36-AW36-AX36),2),"") | AZ36: Voucher | BA36: ESMER, GLECY R.
A37: =IF(B37="","",COUNTA($B$10:B37)) -> 28 | B37: 2026-01-0041 | C37: 46036 | E37: YUGA, MYKA ALEXZA B. | F37: ACCTG. | G37: Administrative Asst. II | H37: =IF(AZ37="Payroll",VLOOKUP(E37,'[2]CODE 2'!$R:$S,2,FALSE),"0") -> 8 | I37: O. ESETS | J37: OK | M37: =IFERROR(VLOOKUP($H37,'[2]CODE 2'!$J:$K,2,FALSE)," ") -> 19744 | N37: =IFERROR(ROUND((M37/2),2),"") -> 9872 | O37: =IFERROR((M37/22)," ") -> 897.45455 | P37: =IFERROR((O37/8),"") -> 112.18182 | Q37: =IFERROR((P37/60),"") -> 1.869697 | R37: 11 | S37: =IFERROR(ROUND((O37*R37),2)," ") -> 9872 | T37: 0 | U37: 0 | V37: 0 | W37: =IFERROR(ROUND(($O37*$T37),2)," ") -> 0 | X37: =IFERROR(ROUND(($P37*$U37),2),"") -> 0 | Y37: =IFERROR(ROUND(($Q37*$V37),2),"") -> 0 | AC37: =IFERROR(ROUND(($O37*$Z37),2)," ") -> 0 | AD37: =IFERROR(ROUND(($P37*$AA37),2),"") -> 0 | AE37: =IFERROR(ROUND(($Q37*$AB37),2),"") -> 0 | AI37: =IFERROR(ROUND(($O37*$AF37),2)," ") -> 0 | AJ37: =IFERROR(ROUND(($P37*$AG37),2),"") -> 0 | AK37: =IFERROR(ROUND(($Q37*$AH37),2),"") -> 0 | AL37: =IFERROR(ROUND(($W37+$AC37+$AI37),2),"") -> 0 | AM37: =IFERROR(ROUND(($X37+$AD37+$AJ37),2),"") -> 0 | AN37: =IFERROR(ROUND(($Y37+$AE37+$AK37),2),"") -> 0 | AO37: =SUM(AL37:AN37) -> 0 | AR37: =IFERROR(ROUND((S37-AO37-AP37),2),"") -> 9872 | AY37: =IFERROR(ROUND((AR37-AS37-AT37-AU37-AV37-AW37-AX37),2),"") -> 9872 | AZ37: Payroll | BA37: ESTAPON, LESLIE DC.
A38: =IF(B38="","",COUNTA($B$10:B38)) -> 29 | B38: 2026-01-0003 | C38: 46035 | E38: EMBALZADO, SHERYL P. | F38: CASHIER | G38: Administrative Asst. II | H38: =IF(AZ38="Payroll",VLOOKUP(E38,'[2]CODE 2'!$R:$S,2,FALSE),"0") -> 0 | I38: CFIDP | J38: OK | M38: =IFERROR(VLOOKUP($H38,'[2]CODE 2'!$J:$K,2,FALSE)," ") | N38: =IFERROR(ROUND((M38/2),2),"") | O38: =IFERROR((M38/22)," ") | P38: =IFERROR((O38/8),"") | Q38: =IFERROR((P38/60),"") | R38: 11 | S38: =IFERROR(ROUND((O38*R38),2)," ") | T38: 0 | U38: 0 | V38: 0 | W38: =IFERROR(ROUND(($O38*$T38),2)," ") | X38: =IFERROR(ROUND(($P38*$U38),2),"") | Y38: =IFERROR(ROUND(($Q38*$V38),2),"") | AC38: =IFERROR(ROUND(($O38*$Z38),2)," ") | AD38: =IFERROR(ROUND(($P38*$AA38),2),"") | AE38: =IFERROR(ROUND(($Q38*$AB38),2),"") | AI38: =IFERROR(ROUND(($O38*$AF38),2)," ") | AJ38: =IFERROR(ROUND(($P38*$AG38),2),"") | AK38: =IFERROR(ROUND(($Q38*$AH38),2),"") | AL38: =IFERROR(ROUND(($W38+$AC38+$AI38),2),"") | AM38: =IFERROR(ROUND(($X38+$AD38+$AJ38),2),"") | AN38: =IFERROR(ROUND(($Y38+$AE38+$AK38),2),"") | AO38: =SUM(AL38:AN38) -> 0 | AR38: =IFERROR(ROUND((S38-AO38+AP38),2),"") | AY38: =IFERROR(ROUND((AR38-AS38-AT38-AU38-AV38-AW38-AX38),2),"") | AZ38: Voucher | BA38: FERNANDEZ, YARI E.
A39: =IF(B39="","",COUNTA($B$10:B39)) -> 30 | B39: 2026-01-0049 | C39: 46036 | E39: CRUZ, CLAIRE JOYCE B. | F39: IAU | G39: Administrative Asst. II | H39: =IF(AZ39="Payroll",VLOOKUP(E39,'[2]CODE 2'!$R:$S,2,FALSE),"0") -> 8 | I39: O. ESETS | J39: OK | M39: =IFERROR(VLOOKUP($H39,'[2]CODE 2'!$J:$K,2,FALSE)," ") -> 19744 | N39: =IFERROR(ROUND((M39/2),2),"") -> 9872 | O39: =IFERROR((M39/22)," ") -> 897.45455 | P39: =IFERROR((O39/8),"") -> 112.18182 | Q39: =IFERROR((P39/60),"") -> 1.869697 | R39: =IF(AZ39="Payroll","11","") -> 11 | S39: =IFERROR(ROUND((O39*R39),2)," ") -> 9872 | T39: 0 | U39: 0 | V39: 0 | W39: =IFERROR(ROUND(($O39*$T39),2)," ") -> 0 | X39: =IFERROR(ROUND(($P39*$U39),2),"") -> 0 | Y39: =IFERROR(ROUND(($Q39*$V39),2),"") -> 0 | AC39: =IFERROR(ROUND(($O39*$Z39),2)," ") -> 0 | AD39: =IFERROR(ROUND(($P39*$AA39),2),"") -> 0 | AE39: =IFERROR(ROUND(($Q39*$AB39),2),"") -> 0 | AI39: =IFERROR(ROUND(($O39*$AF39),2)," ") -> 0 | AJ39: =IFERROR(ROUND(($P39*$AG39),2),"") -> 0 | AK39: =IFERROR(ROUND(($Q39*$AH39),2),"") -> 0 | AL39: =IFERROR(ROUND(($W39+$AC39+$AI39),2),"") -> 0 | AM39: =IFERROR(ROUND(($X39+$AD39+$AJ39),2),"") -> 0 | AN39: =IFERROR(ROUND(($Y39+$AE39+$AK39),2),"") -> 0 | AO39: =SUM(AL39:AN39) -> 0 | AR39: =IFERROR(ROUND((S39-AO39-AP39),2),"") -> 9872 | AY39: =IFERROR(ROUND((AR39-AS39-AT39-AU39-AV39-AW39-AX39),2),"") -> 9872 | AZ39: Payroll | BA39: FRANCISCO, ULYSSES H.
A40: =IF(B40="","",COUNTA($B$10:B40)) -> 31 | B40: 2026-01-0050 | C40: 46036 | E40: MARTIN, SHAIRA LEA E. | F40: IAU | G40: Administrative Asst. II | H40: =IF(AZ40="Payroll",VLOOKUP(E40,'[2]CODE 2'!$R:$S,2,FALSE),"0") -> 8 | I40: O. ESETS | J40: OK | M40: =IFERROR(VLOOKUP($H40,'[2]CODE 2'!$J:$K,2,FALSE)," ") -> 19744 | N40: =IFERROR(ROUND((M40/2),2),"") -> 9872 | O40: =IFERROR((M40/22)," ") -> 897.45455 | P40: =IFERROR((O40/8),"") -> 112.18182 | Q40: =IFERROR((P40/60),"") -> 1.869697 | R40: 11 | S40: =IFERROR(ROUND((O40*R40),2)," ") -> 9872 | T40: 0 | U40: 0 | V40: 0 | W40: =IFERROR(ROUND(($O40*$T40),2)," ") -> 0 | X40: =IFERROR(ROUND(($P40*$U40),2),"") -> 0 | Y40: =IFERROR(ROUND(($Q40*$V40),2),"") -> 0 | AC40: =IFERROR(ROUND(($O40*$Z40),2)," ") -> 0 | AD40: =IFERROR(ROUND(($P40*$AA40),2),"") -> 0 | AE40: =IFERROR(ROUND(($Q40*$AB40),2),"") -> 0 | AI40: =IFERROR(ROUND(($O40*$AF40),2)," ") -> 0 | AJ40: =IFERROR(ROUND(($P40*$AG40),2),"") -> 0 | AK40: =IFERROR(ROUND(($Q40*$AH40),2),"") -> 0 | AL40: =IFERROR(ROUND(($W40+$AC40+$AI40),2),"") -> 0 | AM40: =IFERROR(ROUND(($X40+$AD40+$AJ40),2),"") -> 0 | AN40: =IFERROR(ROUND(($Y40+$AE40+$AK40),2),"") -> 0 | AO40: =SUM(AL40:AN40) -> 0 | AR40: =IFERROR(ROUND((S40-AO40+AP40),2),"") -> 9872 | AY40: =IFERROR(ROUND((AR40-AS40-AT40-AU40-AV40-AW40-AX40),2),"") -> 9872 | AZ40: Payroll | BA40: GAGUCAS, MICHAEL B.
A41: =IF(B41="","",COUNTA($B$10:B41)) -> 32 | B41: 2026-01-0059 | C41: 46036 | E41: CAPONGCOL, MARY JANE | F41: RCRDS | G41: Administrative Asst. II | H41: =IF(AZ41="Payroll",VLOOKUP(E41,'[2]CODE 2'!$R:$S,2,FALSE),"0") -> 8 | I41: O. ESETS | J41: OK | M41: =IFERROR(VLOOKUP($H41,'[2]CODE 2'!$J:$K,2,FALSE)," ") -> 19744 | N41: =IFERROR(ROUND((M41/2),2),"") -> 9872 | O41: =IFERROR((M41/22)," ") -> 897.45455 | P41: =IFERROR((O41/8),"") -> 112.18182 | Q41: =IFERROR((P41/60),"") -> 1.869697 | R41: =IF(AZ41="Payroll","11","") -> 11 | S41: =IFERROR(ROUND((O41*R41),2)," ") -> 9872 | T41: 0 | U41: 0 | V41: 0 | W41: =IFERROR(ROUND(($O41*$T41),2)," ") -> 0 | X41: =IFERROR(ROUND(($P41*$U41),2),"") -> 0 | Y41: =IFERROR(ROUND(($Q41*$V41),2),"") -> 0 | AC41: =IFERROR(ROUND(($O41*$Z41),2)," ") -> 0 | AD41: =IFERROR(ROUND(($P41*$AA41),2),"") -> 0 | AE41: =IFERROR(ROUND(($Q41*$AB41),2),"") -> 0 | AI41: =IFERROR(ROUND(($O41*$AF41),2)," ") -> 0 | AJ41: =IFERROR(ROUND(($P41*$AG41),2),"") -> 0 | AK41: =IFERROR(ROUND(($Q41*$AH41),2),"") -> 0 | AL41: =IFERROR(ROUND(($W41+$AC41+$AI41),2),"") -> 0 | AM41: =IFERROR(ROUND(($X41+$AD41+$AJ41),2),"") -> 0 | AN41: =IFERROR(ROUND(($Y41+$AE41+$AK41),2),"") -> 0 | AO41: =SUM(AL41:AN41) -> 0 | AR41: =IFERROR(ROUND((S41-AO41+AP41),2),"") -> 9872 | AU41: 2000 | AV41: 461.39 | AY41: =IFERROR(ROUND((AR41-AS41-AT41-AU41-AV41-AW41-AX41),2),"") -> 7410.61 | AZ41: Payroll | BA41: GALABAY, CHRISTIANEL B.
A42: =IF(B42="","",COUNTA($B$10:B42)) -> 33 | B42: 2026-01-0058 | C42: 46036 | E42: FERNANDEZ, YARI E. | F42: RCRDS | G42: Administrative Asst. II | H42: =IF(AZ42="Payroll",VLOOKUP(E42,'[2]CODE 2'!$R:$S,2,FALSE),"0") -> 8 | I42: O. ESETS | J42: OK | M42: =IFERROR(VLOOKUP($H42,'[2]CODE 2'!$J:$K,2,FALSE)," ") -> 19744 | N42: =IFERROR(ROUND((M42/2),2),"") -> 9872 | O42: =IFERROR((M42/22)," ") -> 897.45455 | P42: =IFERROR((O42/8),"") -> 112.18182 | Q42: =IFERROR((P42/60),"") -> 1.869697 | R42: =IF(AZ42="Payroll","11","") -> 11 | S42: =IFERROR(ROUND((O42*R42),2)," ") -> 9872 | T42: 0 | U42: 4 | V42: 58 | W42: =IFERROR(ROUND(($O42*$T42),2)," ") -> 0 | X42: =IFERROR(ROUND(($P42*$U42),2),"") -> 448.73 | Y42: =IFERROR(ROUND(($Q42*$V42),2),"") -> 108.44 | AC42: =IFERROR(ROUND(($O42*$Z42),2)," ") -> 0 | AD42: =IFERROR(ROUND(($P42*$AA42),2),"") -> 0 | AE42: =IFERROR(ROUND(($Q42*$AB42),2),"") -> 0 | AI42: =IFERROR(ROUND(($O42*$AF42),2)," ") -> 0 | AJ42: =IFERROR(ROUND(($P42*$AG42),2),"") -> 0 | AK42: =IFERROR(ROUND(($Q42*$AH42),2),"") -> 0 | AL42: =IFERROR(ROUND(($W42+$AC42+$AI42),2),"") -> 0 | AM42: =IFERROR(ROUND(($X42+$AD42+$AJ42),2),"") -> 448.73 | AN42: =IFERROR(ROUND(($Y42+$AE42+$AK42),2),"") -> 108.44 | AO42: =SUM(AL42:AN42) -> 557.17 | AR42: =IFERROR(ROUND((S42-AO42-AP42),2),"") -> 9314.83 | AY42: =IFERROR(ROUND((AR42-AS42-AT42-AU42-AV42-AW42-AX42),2),"") -> 9314.83 | AZ42: Payroll | BA42: GAMBOA, ELGIE F.
...

Sheet MASTER DATA (2)
A2: JOB ORDER GENERAL PAYROLL
A3: For The Period of
A4: 02-16-28-2026
A6: No. | B6: ORS Number | C6: ORS Date | E6: Name | F6: Office | G6: Position | H6: Salary Grade | I6: FUND SOURCE | K6: 1st QTR. Work Schedule - | M6: Monthly Rate | N6: Quincena | O6: Daily Rate | P6: Per Hour | Q6: Per Minute | R6: Working Days | S6: Basic Salary | T6: 02-01-15-2026 | W6: =T6 -> 02-01-15-2026 | Z6: 02-16-28-2026 | AC6: =Z6 -> 02-16-28-2026 | AI6: =AF6 -> 0 | AL6: TOTAL | AO6: Total | AP6: Other Deduction | AR6: Gross Amount | AS6: Withholding Tax | AU6: Deductions | AY6: Net Pay
T7: IN PESO | U7: Late / Under Time | W7: IN PESO | X7: Late / Under Time | Z7: IN PESO | AA7: Late / Under Time | AC7: IN PESO | AD7: Late / Under Time | AG7: Late / Under Time | AI7: IN PESO | AJ7: Late / Under Time | AL7: IN PESO | AM7: Late / Under Time | AP7: Clothing and Others | AQ7: Remarks | AS7: EXPANDED | AT7: PERCENTAGE | AU7: Accommodation (Staff house) | AV7: Water (Staff house) | AW7: Electricity (Staff house) | AX7: Repairs
K8: Time In | L8: Time Out | T8: Absent | U8: Hour | V8: Minute | W8: Absent | X8: Hour | Y8: Minute | Z8: Absent | AA8: Hour | AB8: Minute | AC8: Absent | AD8: Hour | AE8: Minute | AF8: Absent | AG8: Hour | AH8: Minute | AI8: Absent | AJ8: Hour | AK8: Minute | AL8: Absent | AM8: Hour | AN8: Minute | AS8: 0.02 | AT8: 0
A9: 1 | B9: 2 | C9: 3 | D9: 4 | E9: 5 | F9: 6 | G9: 7 | H9: 8 | L9: 10 | M9: 11 | N9: 12 | O9: 13 | P9: 14 | Q9: 15 | R9: 16 | S9: 17 | T9: 18 | U9: 19 | V9: 20 | W9: 21 | X9: 22 | Y9: 23 | Z9: 24 | AA9: 25 | AB9: 26 | AC9: 27 | AD9: 28 | AE9: 29 | AF9: 24 | AG9: 25 | AH9: 26 | AI9: 27 | AJ9: 28 | AK9: 29 | AL9: 30 | AM9: 31 | AN9: 32 | AO9: 33 | AR9: 36 | AS9: 37 | AT9: 38 | AU9: 39 | AV9: 40 | AW9: 41 | AX9: 41 | AY9: 42
A10: 1 | B10: 2026-01-0009 | C10: 46036 | E10: ALBOROTO, JANET P. | F10: GH | G10: Administrative Asst. III | H10: 9 | I10: REVOLVING FUND | J10: ok | M10: =IFERROR(VLOOKUP($H10,'[3]CODE 2'!$J:$K,2,FALSE)," ") -> 21211 | N10: =ROUND((M10/2),2) -> 10605.5 | O10: =M10/22 -> 964.13636 | P10: =O10/8 -> 120.51705 | Q10: =P10/60 -> 2.0086174 | R10: 11 | S10: =ROUND((O10*R10),2) -> 10605.5 | T10: 0 | U10: 0 | V10: 0 | W10: 0 | X10: =ROUND(($P10*$U10),2) -> 0 | Y10: =ROUND(($Q10*$V10),2) -> 0 | AC10: =ROUND(($O10*$Z10),2) -> 0 | AD10: =ROUND(($P10*$AA10),2) -> 0 | AE10: =ROUND(($Q10*$AB10),2) -> 0 | AI10: =IFERROR(ROUND(($O10*$AF10),2)," ") -> 0 | AJ10: =IFERROR(ROUND(($P10*$AG10),2),"") -> 0 | AK10: =IFERROR(ROUND(($Q10*$AH10),2),"") -> 0 | AL10: =ROUND(($W10+$AC10+$AI10),2) -> 0 | AM10: =ROUND(($X10+$AD10+$AJ10),2) -> 0 | AN10: =ROUND(($Y10+$AE10+$AK10),2) -> 0 | AO10: =SUM(AL10:AN10) -> 0 | AR10: =ROUND((S10-AO10-AP10),2) -> 10605.5 | AT10: =ROUND((AR10*$AT$8),2) -> 0 | AY10: =ROUND((AR10-AS10-AT10-AU10-AV10-AW10-AX10),2) -> 10605.5 | AZ10: #REF!
A11: 2 | B11: 2026-01-0010 | C11: 46036 | E11: ARENAS, DIANA ROSE A. | F11: GH | G11: Administrative Asst. IV (Dormitory Assistant) | H11: 10 | I11: REVOLVING FUND | J11: ok | M11: =IFERROR(VLOOKUP($H11,'[3]CODE 2'!$J:$K,2,FALSE)," ") -> 23176 | N11: =ROUND((M11/2),2) -> 11588 | O11: =M11/22 -> 1053.4545 | P11: =O11/8 -> 131.68182 | Q11: =P11/60 -> 2.194697 | R11: 11 | S11: =ROUND((O11*R11),2) -> 11588 | T11: 0 | U11: 0 | V11: 4 | W11: 0 | X11: =ROUND(($P11*$U11),2) -> 0 | Y11: =ROUND(($Q11*$V11),2) -> 8.78 | AC11: =ROUND(($O11*$Z11),2) -> 0 | AD11: =ROUND(($P11*$AA11),2) -> 0 | AE11: =ROUND(($Q11*$AB11),2) -> 0 | AI11: =IFERROR(ROUND(($O11*$AF11),2)," ") -> 0 | AJ11: =IFERROR(ROUND(($P11*$AG11),2),"") -> 0 | AK11: =IFERROR(ROUND(($Q11*$AH11),2),"") -> 0 | AL11: =ROUND(($W11+$AC11+$AI11),2) -> 0 | AM11: =ROUND(($X11+$AD11+$AJ11),2) -> 0 | AN11: =ROUND(($Y11+$AE11+$AK11),2) -> 8.78 | AO11: =SUM(AL11:AN11) -> 8.78 | AR11: =ROUND((S11-AO11-AP11),2) -> 11579.22 | AT11: =ROUND((AR11*$AT$8),2) -> 0 | AY11: =ROUND((AR11-AS11-AT11-AU11-AV11-AW11-AX11),2) -> 11579.22 | AZ11: #REF!
A12: 3 | E12: BERNABE, JOHN MICHAEL A. | F12: GH | G12: Administrative Asst. III | H12: 9 | I12: REVOLVING FUND | J12: ok | M12: =IFERROR(VLOOKUP($H12,'[3]CODE 2'!$J:$K,2,FALSE)," ") -> 21211 | N12: =ROUND((M12/2),2) -> 10605.5 | O12: =M12/22 -> 964.13636 | P12: =O12/8 -> 120.51705 | Q12: =P12/60 -> 2.0086174 | R12: 11 | S12: =ROUND((O12*R12),2) -> 10605.5
A13: 4 | B13: 2026-01-0002 | C13: 46036 | E13: CANNU JR, ALFREDO O. | F13: GH | G13: Administrative Asst. III (Housekeeping Attendant) | H13: 9 | I13: REVOLVING FUND | J13: ok | M13: =IFERROR(VLOOKUP($H13,'[3]CODE 2'!$J:$K,2,FALSE)," ") -> 21211 | N13: =ROUND((M13/2),2) -> 10605.5 | O13: =M13/22 -> 964.13636 | P13: =O13/8 -> 120.51705 | Q13: =P13/60 -> 2.0086174 | R13: 11 | S13: =ROUND((O13*R13),2) -> 10605.5 | T13: 0 | U13: 0 | V13: 14 | W13: =ROUND(($O13*$T13),2) -> 0 | X13: =ROUND(($P13*$U13),2) -> 0 | Y13: =ROUND(($Q13*$V13),2) -> 28.12 | AC13: =ROUND(($O13*$Z13),2) -> 0 | AD13: =ROUND(($P13*$AA13),2) -> 0 | AE13: =ROUND(($Q13*$AB13),2) -> 0 | AI13: =IFERROR(ROUND(($O13*$AF13),2)," ") -> 0 | AJ13: =IFERROR(ROUND(($P13*$AG13),2),"") -> 0 | AK13: =IFERROR(ROUND(($Q13*$AH13),2),"") -> 0 | AL13: =ROUND(($W13+$AC13+$AI13),2) -> 0 | AM13: =ROUND(($X13+$AD13+$AJ13),2) -> 0 | AN13: =ROUND(($Y13+$AE13+$AK13),2) -> 28.12 | AO13: =SUM(AL13:AN13) -> 28.12 | AR13: =ROUND((S13-AO13-AP13),2) -> 10577.38 | AT13: =ROUND((AR13*$AT$8),2) -> 0 | AY13: =ROUND((AR13-AS13-AT13-AU13-AV13-AW13-AX13),2) -> 10577.38 | AZ13: #REF!
A14: 5 | B14: 2026-01-0001 | C14: 46036 | E14: CELOCIA, MERLITA O. | F14: GH | G14: Administrative Asst. III | H14: 9 | I14: REVOLVING FUND | J14: ok | M14: =IFERROR(VLOOKUP($H14,'[3]CODE 2'!$J:$K,2,FALSE)," ") -> 21211 | N14: =ROUND((M14/2),2) -> 10605.5 | O14: =M14/22 -> 964.13636 | P14: =O14/8 -> 120.51705 | Q14: =P14/60 -> 2.0086174 | R14: 11 | S14: =ROUND((O14*R14),2) -> 10605.5 | T14: 0 | U14: 0 | V14: 0 | W14: =ROUND(($O14*$T14),2) -> 0 | X14: =ROUND(($P14*$U14),2) -> 0 | Y14: =ROUND(($Q14*$V14),2) -> 0 | AC14: =ROUND(($O14*$Z14),2) -> 0 | AD14: =ROUND(($P14*$AA14),2) -> 0 | AE14: =ROUND(($Q14*$AB14),2) -> 0 | AI14: =IFERROR(ROUND(($O14*$AF14),2)," ") -> 0 | AJ14: =IFERROR(ROUND(($P14*$AG14),2),"") -> 0 | AK14: =IFERROR(ROUND(($Q14*$AH14),2),"") -> 0 | AL14: =ROUND(($W14+$AC14+$AI14),2) -> 0 | AM14: =ROUND(($X14+$AD14+$AJ14),2) -> 0 | AN14: =ROUND(($Y14+$AE14+$AK14),2) -> 0 | AO14: =SUM(AL14:AN14) -> 0 | AR14: =ROUND((S14-AO14-AP14),2) -> 10605.5 | AT14: =ROUND((AR14*$AT$8),2) -> 0 | AY14: =ROUND((AR14-AS14-AT14-AU14-AV14-AW14-AX14),2) -> 10605.5 | AZ14: #REF!
A15: 6 | E15: CUBIL, JOCELYN R. | F15: GH | G15: Administrative Asst. III | H15: 9 | I15: REVOLVING FUND | J15: ok | M15: =IFERROR(VLOOKUP($H15,'[3]CODE 2'!$J:$K,2,FALSE)," ") -> 21211 | N15: =ROUND((M15/2),2) -> 10605.5 | O15: =M15/22 -> 964.13636 | P15: =O15/8 -> 120.51705 | Q15: =P15/60 -> 2.0086174 | R15: 11 | S15: =ROUND((O15*R15),2) -> 10605.5 | W15: =ROUND(($O15*$T15),2) -> 0 | X15: =ROUND(($P15*$U15),2) -> 0 | Y15: =ROUND(($Q15*$V15),2) -> 0 | AC15: =ROUND(($O15*$Z15),2) -> 0 | AD15: =ROUND(($P15*$AA15),2) -> 0 | AE15: =ROUND(($Q15*$AB15),2) -> 0 | AI15: =IFERROR(ROUND(($O15*$AF15),2)," ") -> 0 | AJ15: =IFERROR(ROUND(($P15*$AG15),2),"") -> 0 | AK15: =IFERROR(ROUND(($Q15*$AH15),2),"") -> 0 | AL15: =ROUND(($W15+$AC15+$AI15),2) -> 0 | AM15: =ROUND(($X15+$AD15+$AJ15),2) -> 0 | AN15: =ROUND(($Y15+$AE15+$AK15),2) -> 0 | AO15: =SUM(AL15:AN15) -> 0 | AT15: =ROUND((AR15*$AT$8),2) -> 0 | AZ15: #REF!
A16: 7 | B16: 2026-01-0006 | C16: 46036 | E16: GULTIANO, HELEN D. | F16: GH | G16: Administrative Asst. III | H16: 9 | I16: REVOLVING FUND | J16: ok | M16: =IFERROR(VLOOKUP($H16,'[3]CODE 2'!$J:$K,2,FALSE)," ") -> 21211 | N16: =ROUND((M16/2),2) -> 10605.5 | O16: =M16/22 -> 964.13636 | P16: =O16/8 -> 120.51705 | Q16: =P16/60 -> 2.0086174 | R16: 11 | S16: =ROUND((O16*R16),2) -> 10605.5 | T16: 0 | U16: 0 | V16: 0 | W16: =ROUND(($O16*$T16),2) -> 0 | X16: =ROUND(($P16*$U16),2) -> 0 | Y16: =ROUND(($Q16*$V16),2) -> 0 | AC16: =ROUND(($O16*$Z16),2) -> 0 | AD16: =ROUND(($P16*$AA16),2) -> 0 | AE16: =ROUND(($Q16*$AB16),2) -> 0 | AI16: =IFERROR(ROUND(($O16*$AF16),2)," ") -> 0 | AJ16: =IFERROR(ROUND(($P16*$AG16),2),"") -> 0 | AK16: =IFERROR(ROUND(($Q16*$AH16),2),"") -> 0 | AL16: =ROUND(($W16+$AC16+$AI16),2) -> 0 | AM16: =ROUND(($X16+$AD16+$AJ16),2) -> 0 | AN16: =ROUND(($Y16+$AE16+$AK16),2) -> 0 | AO16: =SUM(AL16:AN16) -> 0 | AR16: =ROUND((S16-AO16-AP16),2) -> 10605.5 | AT16: =ROUND((AR16*$AT$8),2) -> 0 | AY16: =ROUND((AR16-AS16-AT16-AU16-AV16-AW16-AX16),2) -> 10605.5 | AZ16: #REF!
A17: 8 | B17: 2026-01-0007 | C17: 46036 | E17: TORIO, CECIL P. | F17: GH | G17: Administrative Asst. III | H17: 9 | I17: REVOLVING FUND | J17: ok | M17: =IFERROR(VLOOKUP($H17,'[3]CODE 2'!$J:$K,2,FALSE)," ") -> 21211 | N17: =ROUND((M17/2),2) -> 10605.5 | O17: =M17/22 -> 964.13636 | P17: =O17/8 -> 120.51705 | Q17: =P17/60 -> 2.0086174 | R17: 11 | S17: =ROUND((O17*R17),2) -> 10605.5 | T17: 0 | U17: 0 | V17: 45 | W17: =ROUND(($O17*$T17),2) -> 0 | X17: =ROUND(($P17*$U17),2) -> 0 | Y17: =ROUND(($Q17*$V17),2) -> 90.39 | AC17: =ROUND(($O17*$Z17),2) -> 0 | AD17: =ROUND(($P17*$AA17),2) -> 0 | AE17: =ROUND(($Q17*$AB17),2) -> 0 | AI17: =IFERROR(ROUND(($O17*$AF17),2)," ") -> 0 | AJ17: =IFERROR(ROUND(($P17*$AG17),2),"") -> 0 | AK17: =IFERROR(ROUND(($Q17*$AH17),2),"") -> 0 | AL17: =ROUND(($W17+$AC17+$AI17),2) -> 0 | AM17: =ROUND(($X17+$AD17+$AJ17),2) -> 0 | AN17: =ROUND(($Y17+$AE17+$AK17),2) -> 90.39 | AO17: =SUM(AL17:AN17) -> 90.39 | AR17: =ROUND((S17-AO17-AP17),2) -> 10515.11 | AT17: =ROUND((AR17*$AT$8),2) -> 0 | AY17: =ROUND((AR17-AS17-AT17-AU17-AV17-AW17-AX17),2) -> 10515.11 | AZ17: #REF!
A18: 9 | B18: 2026-01-0008 | C18: 46036 | E18: GASATAN, ENRICO JAN S. | F18: GH | G18: Administrative Asst. III (Housekeeping Attendant) | H18: 9 | I18: REVOLVING FUND | J18: ok | M18: =IFERROR(VLOOKUP($H18,'[3]CODE 2'!$J:$K,2,FALSE)," ") -> 21211 | N18: =ROUND((M18/2),2) -> 10605.5 | O18: =M18/22 -> 964.13636 | P18: =O18/8 -> 120.51705 | Q18: =P18/60 -> 2.0086174 | R18: 11 | S18: =ROUND((O18*R18),2) -> 10605.5 | T18: 0 | U18: 0 | V18: 0 | W18: =ROUND(($O18*$T18),2) -> 0 | X18: =ROUND(($P18*$U18),2) -> 0 | Y18: =ROUND(($Q18*$V18),2) -> 0 | AC18: =ROUND(($O18*$Z18),2) -> 0 | AD18: =ROUND(($P18*$AA18),2) -> 0 | AE18: =ROUND(($Q18*$AB18),2) -> 0 | AI18: =IFERROR(ROUND(($O18*$AF18),2)," ") -> 0 | AJ18: =IFERROR(ROUND(($P18*$AG18),2),"") -> 0 | AK18: =IFERROR(ROUND(($Q18*$AH18),2),"") -> 0 | AL18: =ROUND(($W18+$AC18+$AI18),2) -> 0 | AM18: =ROUND(($X18+$AD18+$AJ18),2) -> 0 | AN18: =ROUND(($Y18+$AE18+$AK18),2) -> 0 | AO18: =SUM(AL18:AN18) -> 0 | AR18: =ROUND((S18-AO18-AP18),2) -> 10605.5 | AT18: =ROUND((AR18*$AT$8),2) -> 0 | AY18: =ROUND((AR18-AS18-AT18-AU18-AV18-AW18-AX18),2) -> 10605.5 | AZ18: #REF!
A19: 10 | B19: 2026-01-0004 | C19: 46036 | E19: JARABESE, LUIS E. | F19: GH | G19: Administrative Asst. III | H19: 9 | I19: REVOLVING FUND | J19: ok | M19: =IFERROR(VLOOKUP($H19,'[3]CODE 2'!$J:$K,2,FALSE)," ") -> 21211 | N19: =ROUND((M19/2),2) -> 10605.5 | O19: =M19/22 -> 964.13636 | P19: =O19/8 -> 120.51705 | Q19: =P19/60 -> 2.0086174 | R19: 11 | S19: =ROUND((O19*R19),2) -> 10605.5 | T19: 0 | U19: 0 | V19: 0 | W19: =ROUND(($O19*$T19),2) -> 0 | X19: =ROUND(($P19*$U19),2) -> 0 | Y19: =ROUND(($Q19*$V19),2) -> 0 | AC19: =ROUND(($O19*$Z19),2) -> 0 | AD19: =ROUND(($P19*$AA19),2) -> 0 | AE19: =ROUND(($Q19*$AB19),2) -> 0 | AI19: =IFERROR(ROUND(($O19*$AF19),2)," ") -> 0 | AJ19: =IFERROR(ROUND(($P19*$AG19),2),"") -> 0 | AK19: =IFERROR(ROUND(($Q19*$AH19),2),"") -> 0 | AL19: =ROUND(($W19+$AC19+$AI19),2) -> 0 | AM19: =ROUND(($X19+$AD19+$AJ19),2) -> 0 | AN19: =ROUND(($Y19+$AE19+$AK19),2) -> 0 | AO19: =SUM(AL19:AN19) -> 0 | AR19: =ROUND((S19-AO19-AP19),2) -> 10605.5 | AT19: =ROUND((AR19*$AT$8),2) -> 0 | AY19: =ROUND((AR19-AS19-AT19-AU19-AV19-AW19-AX19),2) -> 10605.5 | AZ19: #REF!
A20: 11 | B20: 2026-01-0011 | C20: 46036 | E20: ACENO, ALYANNA MARIE | F20: GH | G20: Dormitory Manager I | H20: 9 | I20: REVOLVING FUND | J20: ok | M20: =IFERROR(VLOOKUP($H20,'[3]CODE 2'!$J:$K,2,FALSE)," ") -> 21211 | N20: =ROUND((M20/2),2) -> 10605.5 | O20: =M20/22 -> 964.13636 | P20: =O20/8 -> 120.51705 | Q20: =P20/60 -> 2.0086174 | R20: 11 | S20: =ROUND((O20*R20),2) -> 10605.5 | T20: 0 | U20: 0 | V20: 0 | W20: =ROUND(($O20*$T20),2) -> 0 | X20: =ROUND(($P20*$U20),2) -> 0 | Y20: =ROUND(($Q20*$V20),2) -> 0 | AC20: =ROUND(($O20*$Z20),2) -> 0 | AD20: =ROUND(($P20*$AA20),2) -> 0 | AE20: =ROUND(($Q20*$AB20),2) -> 0 | AI20: =IFERROR(ROUND(($O20*$AF20),2)," ") -> 0 | AJ20: =IFERROR(ROUND(($P20*$AG20),2),"") -> 0 | AK20: =IFERROR(ROUND(($Q20*$AH20),2),"") -> 0 | AL20: =ROUND(($W20+$AC20+$AI20),2) -> 0 | AM20: =ROUND(($X20+$AD20+$AJ20),2) -> 0 | AN20: =ROUND(($Y20+$AE20+$AK20),2) -> 0 | AO20: =SUM(AL20:AN20) -> 0 | AR20: =ROUND((S20-AO20-AP20),2) -> 10605.5 | AT20: =ROUND((AR20*$AT$8),2) -> 0 | AY20: =ROUND((AR20-AS20-AT20-AU20-AV20-AW20-AX20),2) -> 10605.5 | AZ20: #REF!
